Workbook

Sheet 说明首页
B1: 金条坐席SABC评级 · 数据口径与评级标准
B3: 数据截止日期 | C3: 2026-04-12 | D3: ← 更新数据时同步修改此单元格
B5: 一、数据口径
B6: 数据范围 | C6: 近30个自然日，截止日期见C3参数单元格
B7: 数据来源 | C7: CRM系统导出，每日T-1更新
B8: 底表结构 | C8: A-U列(21列)为原始数据，V列起为辅助公式列
B9: 更新方式 | C9: 粘贴新A-U列数据覆盖明细表，所有公式和汇总表自动重算
B10: 首贷/复贷 | C10: 由坐席类型字段(A列)直接判定，首贷和复贷分池独立评级
B11: 有效通话阈值 | C11: 单通通话时长≥30秒计为有效接通
B12: 转化率分母 | C12: 首贷暂用接通用户数(J列)，后续名单下发数到位后替换K列
B14: 二、参评条件
B15: 条件① 活跃度 | C15: 最近一次有效外呼距截止日不超过7天
B16: 条件② 出勤量 | C16: 近30天有效外呼天数(通话时长>30分钟)≥22天
B17: 参评判定 | C17: 同时满足①②标记为"是"，参与评级；否则标记"非参评"，不参与排名
B19: 三、评级权重
B20: 维度 | C20: 首贷权重 | D20: 复贷权重 | E20: 类型
B21: 个人转化率 / GMV | C21: 55% | D21: 40% | E21: 结果指标（核心）
B22: 件均金额 | C22: — | D22: 15% | E22: 结果指标
B23: 个人ATT | C23: 30% | D23: 30% | E23: 过程指标
B24: 日均有效拨打量 | C24: 15% | D24: 15% | E24: 过程指标
B25: 结果:过程 | C25: 55 : 45 | D25: 55 : 45
B27: 四、分级标准（百分位排名制+底线门槛）
B28: 等级 | C28: 排名范围 | D28: 底线门槛 | E28: 管理动作
B29: S | C29: 综合得分Top 20% | D29: 且结果指标>参评池中位值 | E29: 名单优先+话术萃取；不达底线降A，名额不递补
B30: A | C30: Top 20%-50% | D30: 无 | E30: 正常管理+常规培训
B31: B | C31: Top 50%-80% | D31: 无 | E31: 组长定向辅导+通关考核
B32: C | C32: Bottom 20% | D32: 无 | E32: 暂停优质名单+14天改善期
B34: 五、流失与预警定义
B35: 指标 | C35: 定义 | D35: 分母 | E35: 用途
B36: 有效在岗 | C36: 近30天外呼天数≥20天 | D36: — | E36: 司龄统计分母
B37: 流失（确认） | C37: 最近有效外呼距截止日>7天 | D37: 有效在岗人数 | E37: 已确认流失
B38: 预警（早期） | C38: 最近有效外呼距截止日≥3天 | D38: 有效在岗人数 | E38: 早期预警
B39: 司龄分段 | C39: MOB1-(<30天) | MOB1-3(30-89) | MOB3-6(90-179) | MOB6-12(180-364) | MOB12+(≥365) | D39: 基于210客户池在职天数
B41: 六、汇总表口径
B42: SABC占比 | C42: 各职场该等级人数 ÷ 全大盘参评总人数（非职场内部占比）
B43: 均值指标 | C43: ATT/转化率/GMV/件均/日均拨打量均仅统计参评坐席
B44: 得分计算 | C44: 百分位排名仅在参评人中做排名，非参评不进入排名池
B45: 职场范围 | C45: 剔除赛维斯机器人、零犀伽玛机器人（纯机器人职场）
B47: ⚠️ 待补充
B48: 名单下发数 | C48: 首贷转化率分母暂用接通用户数，后续名单数据到位后替换
...

Sheet 首贷评级明细
A1: 坐席类型 | B1: 职场名称 | C1: 坐席id | D1: 坐席名称 | E1: 210客户池首次外呼日期 | F1: 金条业务首次外呼日期 | G1: 210客户池在职天数 | H1: 金条业务线在职日期 | I1: 最近一次有效外呼时间 | J1: 接通用户数 | K1: 接通话单数 | L1: 有效接通数话单数 | M1: 近30天累计通时（秒） | N1: 近30天累计有效通时 | O1: 近30天外呼天数（通话时长>30分钟天数） | P1: 近30日累计转化首贷用户数 | Q1: 近30日累计转化首贷GMV | R1: 近30日累计转化复贷用户数 | S1: 近30日累计转化复贷订单数 | T1: 近30日累计转化复贷GMV | U1: 近30日累计转化GMV | V1: 超7天未上线 | W1: 外呼天数不足22天 | X1: 是否参评 | Y1: 连续3天未上线预警 | Z1: 个人ATT(秒) | AA1: 转化率% | AB1: 首贷件均(元) | AC1: 日均拨打量 | AD1: ATT得分 | AE1: 转化率得分 | AF1: 拨打量得分 | AG1: 综合得分 | AH1: 参评排名 | AI1: 等级 | AJ1: 司龄分段
A2: 首贷 | B2: 管户金条-赛维斯职场 | C2: 801583 | D2: 赛维斯小白账号36 | E2: 2026-02-10 11:31:08 | F2: 2026-02-10 11:31:08 | G2: 61 | H2: 61 | I2: 2026-04-09 12:25:38 | J2: 109 | K2: 110 | L2: 51 | M2: 9592 | N2: 8785 | O2: 3 | V2: =IF(OR(I2="",说明首页!$C$3-INT(I2)>7),"是","否") -> 否 | W2: =IF(OR(O2="",O2<22),"是","否") -> 是 | X2: =IF(AND(V2="否",W2="否"),"是","否") -> 否 | Y2: =IF(OR(I2="",说明首页!$C$3-INT(I2)>=3),"是","否") -> 是 | Z2: =IF(L2>0,N2/L2,0) -> 172.2549 | AA2: =IF(J2>0,P2/J2*100,0) -> 0 | AB2: =IF(AND(P2<>"",P2>0),Q2/P2,0) -> 0 | AC2: =IF(O2>0,L2/O2,0) -> 17 | AD2: =IF(X2="是",COUNTIFS($X$2:$X$5000,"是",$Z$2:$Z$5000,"<"&Z2)/COUNTIF($X$2:$X$5000,"是")*100,"") | AE2: =IF(X2="是",COUNTIFS($X$2:$X$5000,"是",$AA$2:$AA$5000,"<"&AA2)/COUNTIF($X$2:$X$5000,"是")*100,"") | AF2: =IF(X2="是",COUNTIFS($X$2:$X$5000,"是",$AC$2:$AC$5000,"<"&AC2)/COUNTIF($X$2:$X$5000,"是")*100,"") | AG2: =IF(X2="是",ROUND(AD2*0.3+AE2*0.55+AF2*0.15,2),"") | AH2: =IF(X2="是",COUNTIFS($X$2:$X$5000,"是",$AG$2:$AG$5000,">"&AG2)+1,"") | AI2: =IF(X2<>"是","非参评",IF(AND(AH2<=COUNTIF($X$2:$X$5000,"是")*0.2,AA2>MEDIAN(IF($X$2:$X$5000="是",$AA$2:$AA$5000))),"S",IF(AH2<=COUNTIF($X$2:$X$5000,"是")*0.5,"A",IF(AH2<=COUNTIF($X$2:$X$5000,"是")*0.8,"B","C")))) -> 非参评 | AJ2: =IF(G2="","无数据",IF(G2<30,"MOB1-",IF(G2<90,"MOB1-3",IF(G2<180,"MOB3-6",IF(G2<365,"MOB6-12","MOB12+"))))) -> MOB1-3
A3: 首贷 | B3: 管户金条-毅航合肥职场 | C3: 806906 | D3: 王鸳 | E3: 2026-04-03 10:32:29 | F3: 2026-04-03 10:32:29 | G3: 9 | H3: 9 | I3: 2026-04-03 18:15:53 | J3: 175 | K3: 175 | L3: 75 | M3: 7990 | N3: 6640 | O3: 1 | P3: 1 | Q3: 1000 | R3: 0 | S3: 0 | U3: 1000 | V3: =IF(OR(I3="",说明首页!$C$3-INT(I3)>7),"是","否") -> 是 | W3: =IF(OR(O3="",O3<22),"是","否") -> 是 | X3: =IF(AND(V3="否",W3="否"),"是","否") -> 否 | Y3: =IF(OR(I3="",说明首页!$C$3-INT(I3)>=3),"是","否") -> 是 | Z3: =IF(L3>0,N3/L3,0) -> 88.533333 | AA3: =IF(J3>0,P3/J3*100,0) -> 0.57142857 | AB3: =IF(AND(P3<>"",P3>0),Q3/P3,0) -> 1000 | AC3: =IF(O3>0,L3/O3,0) -> 75 | AD3: =IF(X3="是",COUNTIFS($X$2:$X$5000,"是",$Z$2:$Z$5000,"<"&Z3)/COUNTIF($X$2:$X$5000,"是")*100,"") | AE3: =IF(X3="是",COUNTIFS($X$2:$X$5000,"是",$AA$2:$AA$5000,"<"&AA3)/COUNTIF($X$2:$X$5000,"是")*100,"") | AF3: =IF(X3="是",COUNTIFS($X$2:$X$5000,"是",$AC$2:$AC$5000,"<"&AC3)/COUNTIF($X$2:$X$5000,"是")*100,"") | AG3: =IF(X3="是",ROUND(AD3*0.3+AE3*0.55+AF3*0.15,2),"") | AH3: =IF(X3="是",COUNTIFS($X$2:$X$5000,"是",$AG$2:$AG$5000,">"&AG3)+1,"") | AI3: =IF(X3<>"是","非参评",IF(AND(AH3<=COUNTIF($X$2:$X$5000,"是")*0.2,AA3>MEDIAN(IF($X$2:$X$5000="是",$AA$2:$AA$5000))),"S",IF(AH3<=COUNTIF($X$2:$X$5000,"是")*0.5,"A",IF(AH3<=COUNTIF($X$2:$X$5000,"是")*0.8,"B","C")))) -> 非参评 | AJ3: =IF(G3="","无数据",IF(G3<30,"MOB1-",IF(G3<90,"MOB1-3",IF(G3<180,"MOB3-6",IF(G3<365,"MOB6-12","MOB12+"))))) -> MOB1-
A4: 首贷 | B4: 管户金条-毛毛虫职场 | C4: 763245 | D4: 徐超迪 | E4: 2024-05-17 15:13:06 | F4: 2024-05-17 15:13:06 | G4: 695 | H4: 695 | I4: 2026-03-31 12:25:28 | J4: 527 | K4: 538 | L4: 256 | M4: 25065 | N4: 20655 | O4: 10 | P4: 5 | Q4: 14200 | R4: 0 | S4: 0 | U4: 14200 | V4: =IF(OR(I4="",说明首页!$C$3-INT(I4)>7),"是","否") -> 是 | W4: =IF(OR(O4="",O4<22),"是","否") -> 是 | X4: =IF(AND(V4="否",W4="否"),"是","否") -> 否 | Y4: =IF(OR(I4="",说明首页!$C$3-INT(I4)>=3),"是","否") -> 是 | Z4: =IF(L4>0,N4/L4,0) -> 80.683594 | AA4: =IF(J4>0,P4/J4*100,0) -> 0.9487666 | AB4: =IF(AND(P4<>"",P4>0),Q4/P4,0) -> 2840 | AC4: =IF(O4>0,L4/O4,0) -> 25.6 | AD4: =IF(X4="是",COUNTIFS($X$2:$X$5000,"是",$Z$2:$Z$5000,"<"&Z4)/COUNTIF($X$2:$X$5000,"是")*100,"") | AE4: =IF(X4="是",COUNTIFS($X$2:$X$5000,"是",$AA$2:$AA$5000,"<"&AA4)/COUNTIF($X$2:$X$5000,"是")*100,"") | AF4: =IF(X4="是",COUNTIFS($X$2:$X$5000,"是",$AC$2:$AC$5000,"<"&AC4)/COUNTIF($X$2:$X$5000,"是")*100,"") | AG4: =IF(X4="是",ROUND(AD4*0.3+AE4*0.55+AF4*0.15,2),"") | AH4: =IF(X4="是",COUNTIFS($X$2:$X$5000,"是",$AG$2:$AG$5000,">"&AG4)+1,"") | AI4: =IF(X4<>"是","非参评",IF(AND(AH4<=COUNTIF($X$2:$X$5000,"是")*0.2,AA4>MEDIAN(IF($X$2:$X$5000="是",$AA$2:$AA$5000))),"S",IF(AH4<=COUNTIF($X$2:$X$5000,"是")*0.5,"A",IF(AH4<=COUNTIF($X$2:$X$5000,"是")*0.8,"B","C")))) -> 非参评 | AJ4: =IF(G4="","无数据",IF(G4<30,"MOB1-",IF(G4<90,"MOB1-3",IF(G4<180,"MOB3-6",IF(G4<365,"MOB6-12","MOB12+"))))) -> MOB12+
A5: 首贷 | B5: 管户金条-毅航合肥职场 | C5: 804078 | D5: 丁孝帅 | E5: 2026-03-12 17:49:12 | F5: 2026-03-12 17:49:12 | G5: 31 | H5: 31 | I5: 2026-04-12 12:28:37 | J5: 3675 | K5: 4025 | L5: 1994 | M5: 186692 | N5: 154130 | O5: 25 | P5: 38 | Q5: 964000 | R5: 1 | S5: 1 | T5: 1500 | U5: 965500 | V5: =IF(OR(I5="",说明首页!$C$3-INT(I5)>7),"是","否") -> 否 | W5: =IF(OR(O5="",O5<22),"是","否") -> 否 | X5: =IF(AND(V5="否",W5="否"),"是","否") -> 是 | Y5: =IF(OR(I5="",说明首页!$C$3-INT(I5)>=3),"是","否") -> 否 | Z5: =IF(L5>0,N5/L5,0) -> 77.296891 | AA5: =IF(J5>0,P5/J5*100,0) -> 1.0340136 | AB5: =IF(AND(P5<>"",P5>0),Q5/P5,0) -> 25368.421 | AC5: =IF(O5>0,L5/O5,0) -> 79.76 | AD5: =IF(X5="是",COUNTIFS($X$2:$X$5000,"是",$Z$2:$Z$5000,"<"&Z5)/COUNTIF($X$2:$X$5000,"是")*100,"") -> 22.365591 | AE5: =IF(X5="是",COUNTIFS($X$2:$X$5000,"是",$AA$2:$AA$5000,"<"&AA5)/COUNTIF($X$2:$X$5000,"是")*100,"") -> 64.301075 | AF5: =IF(X5="是",COUNTIFS($X$2:$X$5000,"是",$AC$2:$AC$5000,"<"&AC5)/COUNTIF($X$2:$X$5000,"是")*100,"") -> 55.698925 | AG5: =IF(X5="是",ROUND(AD5*0.3+AE5*0.55+AF5*0.15,2),"") -> 50.43 | AH5: =IF(X5="是",COUNTIFS($X$2:$X$5000,"是",$AG$2:$AG$5000,">"&AG5)+1,"") -> 231 | AI5: =IF(X5<>"是","非参评",IF(AND(AH5<=COUNTIF($X$2:$X$5000,"是")*0.2,AA5>MEDIAN(IF($X$2:$X$5000="是",$AA$2:$AA$5000))),"S",IF(AH5<=COUNTIF($X$2:$X$5000,"是")*0.5,"A",IF(AH5<=COUNTIF($X$2:$X$5000,"是")*0.8,"B","C")))) -> A | AJ5: =IF(G5="","无数据",IF(G5<30,"MOB1-",IF(G5<90,"MOB1-3",IF(G5<180,"MOB3-6",IF(G5<365,"MOB6-12","MOB12+"))))) -> MOB1-3
A6: 首贷 | B6: 管户金条-毅航合肥职场 | C6: 803078 | D6: 赵莉 | E6: 2026-03-03 13:41:37 | F6: 2026-03-03 13:41:37 | G6: 40 | H6: 40 | I6: 2026-04-03 18:20:36 | J6: 465 | K6: 466 | L6: 156 | M6: 18042 | N6: 13499 | O6: 6 | P6: 2 | Q6: 2700 | R6: 0 | S6: 0 | U6: 2700 | V6: =IF(OR(I6="",说明首页!$C$3-INT(I6)>7),"是","否") -> 是 | W6: =IF(OR(O6="",O6<22),"是","否") -> 是 | X6: =IF(AND(V6="否",W6="否"),"是","否") -> 否 | Y6: =IF(OR(I6="",说明首页!$C$3-INT(I6)>=3),"是","否") -> 是 | Z6: =IF(L6>0,N6/L6,0) -> 86.532051 | AA6: =IF(J6>0,P6/J6*100,0) -> 0.43010753 | AB6: =IF(AND(P6<>"",P6>0),Q6/P6,0) -> 1350 | AC6: =IF(O6>0,L6/O6,0) -> 26 | AD6: =IF(X6="是",COUNTIFS($X$2:$X$5000,"是",$Z$2:$Z$5000,"<"&Z6)/COUNTIF($X$2:$X$5000,"是")*100,"") | AE6: =IF(X6="是",COUNTIFS($X$2:$X$5000,"是",$AA$2:$AA$5000,"<"&AA6)/COUNTIF($X$2:$X$5000,"是")*100,"") | AF6: =IF(X6="是",COUNTIFS($X$2:$X$5000,"是",$AC$2:$AC$5000,"<"&AC6)/COUNTIF($X$2:$X$5000,"是")*100,"") | AG6: =IF(X6="是",ROUND(AD6*0.3+AE6*0.55+AF6*0.15,2),"") | AH6: =IF(X6="是",COUNTIFS($X$2:$X$5000,"是",$AG$2:$AG$5000,">"&AG6)+1,"") | AI6: =IF(X6<>"是","非参评",IF(AND(AH6<=COUNTIF($X$2:$X$5000,"是")*0.2,AA6>MEDIAN(IF($X$2:$X$5000="是",$AA$2:$AA$5000))),"S",IF(AH6<=COUNTIF($X$2:$X$5000,"是")*0.5,"A",IF(AH6<=COUNTIF($X$2:$X$5000,"是")*0.8,"B","C")))) -> 非参评 | AJ6: =IF(G6="","无数据",IF(G6<30,"MOB1-",IF(G6<90,"MOB1-3",IF(G6<180,"MOB3-6",IF(G6<365,"MOB6-12","MOB12+"))))) -> MOB1-3
A7: 首贷 | B7: 管户金条-毅航合肥职场 | C7: 803624 | D7: 桑嘉文 | E7: 2026-03-07 16:23:50 | F7: 2026-03-07 16:23:50 | G7: 36 | H7: 36 | I7: 2026-04-03 18:14:01 | J7: 223 | K7: 225 | L7: 104 | M7: 10448 | N7: 8864 | O7: 3 | V7: =IF(OR(I7="",说明首页!$C$3-INT(I7)>7),"是","否") -> 是 | W7: =IF(OR(O7="",O7<22),"是","否") -> 是 | X7: =IF(AND(V7="否",W7="否"),"是","否") -> 否 | Y7: =IF(OR(I7="",说明首页!$C$3-INT(I7)>=3),"是","否") -> 是 | Z7: =IF(L7>0,N7/L7,0) -> 85.230769 | AA7: =IF(J7>0,P7/J7*100,0) -> 0 | AB7: =IF(AND(P7<>"",P7>0),Q7/P7,0) -> 0 | AC7: =IF(O7>0,L7/O7,0) -> 34.666667 | AD7: =IF(X7="是",COUNTIFS($X$2:$X$5000,"是",$Z$2:$Z$5000,"<"&Z7)/COUNTIF($X$2:$X$5000,"是")*100,"") | AE7: =IF(X7="是",COUNTIFS($X$2:$X$5000,"是",$AA$2:$AA$5000,"<"&AA7)/COUNTIF($X$2:$X$5000,"是")*100,"") | AF7: =IF(X7="是",COUNTIFS($X$2:$X$5000,"是",$AC$2:$AC$5000,"<"&AC7)/COUNTIF($X$2:$X$5000,"是")*100,"") | AG7: =IF(X7="是",ROUND(AD7*0.3+AE7*0.55+AF7*0.15,2),"") | AH7: =IF(X7="是",COUNTIFS($X$2:$X$5000,"是",$AG$2:$AG$5000,">"&AG7)+1,"") | AI7: =IF(X7<>"是","非参评",IF(AND(AH7<=COUNTIF($X$2:$X$5000,"是")*0.2,AA7>MEDIAN(IF($X$2:$X$5000="是",$AA$2:$AA$5000))),"S",IF(AH7<=COUNTIF($X$2:$X$5000,"是")*0.5,"A",IF(AH7<=COUNTIF($X$2:$X$5000,"是")*0.8,"B","C")))) -> 非参评 | AJ7: =IF(G7="","无数据",IF(G7<30,"MOB1-",IF(G7<90,"MOB1-3",IF(G7<180,"MOB3-6",IF(G7<365,"MOB6-12","MOB12+"))))) -> MOB1-3
A8: 首贷 | B8: 管户金条-博岳石家庄职场 | C8: 805113 | D8: 戴金瑞 | E8: 2026-03-30 09:38:07 | F8: 2026-03-30 09:38:07 | G8: 13 | H8: 13 | I8: 2026-03-31 14:41:10 | J8: 208 | K8: 214 | L8: 80 | M8: 6742 | N8: 4794 | O8: 2 | P8: 1 | Q8: 500 | R8: 0 | S8: 0 | U8: 500 | V8: =IF(OR(I8="",说明首页!$C$3-INT(I8)>7),"是","否") -> 是 | W8: =IF(OR(O8="",O8<22),"是","否") -> 是 | X8: =IF(AND(V8="否",W8="否"),"是","否") -> 否 | Y8: =IF(OR(I8="",说明首页!$C$3-INT(I8)>=3),"是","否") -> 是 | Z8: =IF(L8>0,N8/L8,0) -> 59.925 | AA8: =IF(J8>0,P8/J8*100,0) -> 0.48076923 | AB8: =IF(AND(P8<>"",P8>0),Q8/P8,0) -> 500 | AC8: =IF(O8>0,L8/O8,0) -> 40 | AD8: =IF(X8="是",COUNTIFS($X$2:$X$5000,"是",$Z$2:$Z$5000,"<"&Z8)/COUNTIF($X$2:$X$5000,"是")*100,"") | AE8: =IF(X8="是",COUNTIFS($X$2:$X$5000,"是",$AA$2:$AA$5000,"<"&AA8)/COUNTIF($X$2:$X$5000,"是")*100,"") | AF8: =IF(X8="是",COUNTIFS($X$2:$X$5000,"是",$AC$2:$AC$5000,"<"&AC8)/COUNTIF($X$2:$X$5000,"是")*100,"") | AG8: =IF(X8="是",ROUND(AD8*0.3+AE8*0.55+AF8*0.15,2),"") | AH8: =IF(X8="是",COUNTIFS($X$2:$X$5000,"是",$AG$2:$AG$5000,">"&AG8)+1,"") | AI8: =IF(X8<>"是","非参评",IF(AND(AH8<=COUNTIF($X$2:$X$5000,"是")*0.2,AA8>MEDIAN(IF($X$2:$X$5000="是",$AA$2:$AA$5000))),"S",IF(AH8<=COUNTIF($X$2:$X$5000,"是")*0.5,"A",IF(AH8<=COUNTIF($X$2:$X$5000,"是")*0.8,"B","C")))) -> 非参评 | AJ8: =IF(G8="","无数据",IF(G8<30,"MOB1-",IF(G8<90,"MOB1-3",IF(G8<180,"MOB3-6",IF(G8<365,"MOB6-12","MOB12+"))))) -> MOB1-
A9: 首贷 | B9: 管户金条-毅航合肥职场 | C9: 803615 | D9: 刘梦雪 | E9: 2026-03-09 13:49:19 | F9: 2026-03-09 13:49:19 | G9: 34 | H9: 34 | I9: 2026-04-03 18:26:23 | J9: 288 | K9: 291 | L9: 83 | M9: 9013 | N9: 5727 | O9: 1 | V9: =IF(OR(I9="",说明首页!$C$3-INT(I9)>7),"是","否") -> 是 | W9: =IF(OR(O9="",O9<22),"是","否") -> 是 | X9: =IF(AND(V9="否",W9="否"),"是","否") -> 否 | Y9: =IF(OR(I9="",说明首页!$C$3-INT(I9)>=3),"是","否") -> 是 | Z9: =IF(L9>0,N9/L9,0) -> 69 | AA9: =IF(J9>0,P9/J9*100,0) -> 0 | AB9: =IF(AND(P9<>"",P9>0),Q9/P9,0) -> 0 | AC9: =IF(O9>0,L9/O9,0) -> 83 | AD9: =IF(X9="是",COUNTIFS($X$2:$X$5000,"是",$Z$2:$Z$5000,"<"&Z9)/COUNTIF($X$2:$X$5000,"是")*100,"") | AE9: =IF(X9="是",COUNTIFS($X$2:$X$5000,"是",$AA$2:$AA$5000,"<"&AA9)/COUNTIF($X$2:$X$5000,"是")*100,"") | AF9: =IF(X9="是",COUNTIFS($X$2:$X$5000,"是",$AC$2:$AC$5000,"<"&AC9)/COUNTIF($X$2:$X$5000,"是")*100,"") | AG9: =IF(X9="是",ROUND(AD9*0.3+AE9*0.55+AF9*0.15,2),"") | AH9: =IF(X9="是",COUNTIFS($X$2:$X$5000,"是",$AG$2:$AG$5000,">"&AG9)+1,"") | AI9: =IF(X9<>"是","非参评",IF(AND(AH9<=COUNTIF($X$2:$X$5000,"是")*0.2,AA9>MEDIAN(IF($X$2:$X$5000="是",$AA$2:$AA$5000))),"S",IF(AH9<=COUNTIF($X$2:$X$5000,"是")*0.5,"A",IF(AH9<=COUNTIF($X$2:$X$5000,"是")*0.8,"B","C")))) -> 非参评 | AJ9: =IF(G9="","无数据",IF(G9<30,"MOB1-",IF(G9<90,"MOB1-3",IF(G9<180,"MOB3-6",IF(G9<365,"MOB6-12","MOB12+"))))) -> MOB1-3
A10: 首贷 | B10: 管户金条-伽玛职场 | C10: 731014 | D10: 刘敏 | E10: 2023-01-04 13:32:37 | F10: 2023-01-04 13:32:37 | G10: 1194 | H10: 1194 | I10: 2026-04-11 18:43:14 | J10: 3840 | K10: 5146 | L10: 1635 | M10: 191667 | N10: 142469 | O10: 23 | P10: 47 | Q10: 1934100 | R10: 2 | S10: 2 | T10: 139300 | U10: 2073400 | V10: =IF(OR(I10="",说明首页!$C$3-INT(I10)>7),"是","否") -> 否 | W10: =IF(OR(O10="",O10<22),"是","否") -> 否 | X10: =IF(AND(V10="否",W10="否"),"是","否") -> 是 | Y10: =IF(OR(I10="",说明首页!$C$3-INT(I10)>=3),"是","否") -> 否 | Z10: =IF(L10>0,N10/L10,0) -> 87.137003 | AA10: =IF(J10>0,P10/J10*100,0) -> 1.2239583 | AB10: =IF(AND(P10<>"",P10>0),Q10/P10,0) -> 41151.064 | AC10: =IF(O10>0,L10/O10,0) -> 71.086957 | AD10: =IF(X10="是",COUNTIFS($X$2:$X$5000,"是",$Z$2:$Z$5000,"<"&Z10)/COUNTIF($X$2:$X$5000,"是")*100,"") -> 47.956989 | AE10: =IF(X10="是",COUNTIFS($X$2:$X$5000,"是",$AA$2:$AA$5000,"<"&AA10)/COUNTIF($X$2:$X$5000,"是")*100,"") -> 77.204301 | AF10: =IF(X10="是",COUNTIFS($X$2:$X$5000,"是",$AC$2:$AC$5000,"<"&AC10)/COUNTIF($X$2:$X$5000,"是")*100,"") -> 29.032258 | AG10: =IF(X10="是",ROUND(AD10*0.3+AE10*0.55+AF10*0.15,2),"") -> 61.2 | AH10: =IF(X10="是",COUNTIFS($X$2:$X$5000,"是",$AG$2:$AG$5000,">"&AG10)+1,"") -> 146 | AI10: =IF(X10<>"是","非参评",IF(AND(AH10<=COUNTIF($X$2:$X$5000,"是")*0.2,AA10>MEDIAN(IF($X$2:$X$5000="是",$AA$2:$AA$5000))),"S",IF(AH10<=COUNTIF($X$2:$X$5000,"是")*0.5,"A",IF(AH10<=COUNTIF($X$2:$X$5000,"是")*0.8,"B","C")))) -> A | AJ10: =IF(G10="","无数据",IF(G10<30,"MOB1-",IF(G10<90,"MOB1-3",IF(G10<180,"MOB3-6",IF(G10<365,"MOB6-12","MOB12+"))))) -> MOB12+
A11: 首贷 | B11: 管户金条-博岳石家庄职场 | C11: 799886 | D11: 王昊哲 | E11: 2025-12-17 10:42:10 | F11: 2025-12-17 10:42:10 | G11: 116 | H11: 116 | J11: 1 | K11: 1 | L11: 0 | M11: 11 | V11: =IF(OR(I11="",说明首页!$C$3-INT(I11)>7),"是","否") -> #VALUE! | W11: =IF(OR(O11="",O11<22),"是","否") -> 是 | X11: =IF(AND(V11="否",W11="否"),"是","否") -> #VALUE! | Y11: =IF(OR(I11="",说明首页!$C$3-INT(I11)>=3),"是","否") -> #VALUE! | Z11: =IF(L11>0,N11/L11,0) -> 0 | AA11: =IF(J11>0,P11/J11*100,0) -> 0 | AB11: =IF(AND(P11<>"",P11>0),Q11/P11,0) -> 0 | AC11: =IF(O11>0,L11/O11,0) -> 0 | AD11: =IF(X11="是",COUNTIFS($X$2:$X$5000,"是",$Z$2:$Z$5000,"<"&Z11)/COUNTIF($X$2:$X$5000,"是")*100,"") -> #VALUE! | AE11: =IF(X11="是",COUNTIFS($X$2:$X$5000,"是",$AA$2:$AA$5000,"<"&AA11)/COUNTIF($X$2:$X$5000,"是")*100,"") -> #VALUE! | AF11: =IF(X11="是",COUNTIFS($X$2:$X$5000,"是",$AC$2:$AC$5000,"<"&AC11)/COUNTIF($X$2:$X$5000,"是")*100,"") -> #VALUE! | AG11: =IF(X11="是",ROUND(AD11*0.3+AE11*0.55+AF11*0.15,2),"") -> #VALUE! | AH11: =IF(X11="是",COUNTIFS($X$2:$X$5000,"是",$AG$2:$AG$5000,">"&AG11)+1,"") -> #VALUE! | AI11: =IF(X11<>"是","非参评",IF(AND(AH11<=COUNTIF($X$2:$X$5000,"是")*0.2,AA11>MEDIAN(IF($X$2:$X$5000="是",$AA$2:$AA$5000))),"S",IF(AH11<=COUNTIF($X$2:$X$5000,"是")*0.5,"A",IF(AH11<=COUNTIF($X$2:$X$5000,"是")*0.8,"B","C")))) -> #VALUE! | AJ11: =IF(G11="","无数据",IF(G11<30,"MOB1-",IF(G11<90,"MOB1-3",IF(G11<180,"MOB3-6",IF(G11<365,"MOB6-12","MOB12+"))))) -> MOB3-6
A12: 首贷 | B12: 管户金条-华啸职场 | C12: 804874 | D12: 蒋秀琳 | E12: 2026-03-25 11:36:28 | F12: 2026-03-25 11:36:28 | G12: 18 | H12: 18 | I12: 2026-03-27 14:33:12 | J12: 25 | K12: 28 | L12: 17 | M12: 1135 | N12: 988 | V12: =IF(OR(I12="",说明首页!$C$3-INT(I12)>7),"是","否") -> 是 | W12: =IF(OR(O12="",O12<22),"是","否") -> 是 | X12: =IF(AND(V12="否",W12="否"),"是","否") -> 否 | Y12: =IF(OR(I12="",说明首页!$C$3-INT(I12)>=3),"是","否") -> 是 | Z12: =IF(L12>0,N12/L12,0) -> 58.117647 | AA12: =IF(J12>0,P12/J12*100,0) -> 0 | AB12: =IF(AND(P12<>"",P12>0),Q12/P12,0) -> 0 | AC12: =IF(O12>0,L12/O12,0) -> 0 | AD12: =IF(X12="是",COUNTIFS($X$2:$X$5000,"是",$Z$2:$Z$5000,"<"&Z12)/COUNTIF($X$2:$X$5000,"是")*100,"") | AE12: =IF(X12="是",COUNTIFS($X$2:$X$5000,"是",$AA$2:$AA$5000,"<"&AA12)/COUNTIF($X$2:$X$5000,"是")*100,"") | AF12: =IF(X12="是",COUNTIFS($X$2:$X$5000,"是",$AC$2:$AC$5000,"<"&AC12)/COUNTIF($X$2:$X$5000,"是")*100,"") | AG12: =IF(X12="是",ROUND(AD12*0.3+AE12*0.55+AF12*0.15,2),"") | AH12: =IF(X12="是",COUNTIFS($X$2:$X$5000,"是",$AG$2:$AG$5000,">"&AG12)+1,"") | AI12: =IF(X12<>"是","非参评",IF(AND(AH12<=COUNTIF($X$2:$X$5000,"是")*0.2,AA12>MEDIAN(IF($X$2:$X$5000="是",$AA$2:$AA$5000))),"S",IF(AH12<=COUNTIF($X$2:$X$5000,"是")*0.5,"A",IF(AH12<=COUNTIF($X$2:$X$5000,"是")*0.8,"B","C")))) -> 非参评 | AJ12: =IF(G12="","无数据",IF(G12<30,"MOB1-",IF(G12<90,"MOB1-3",IF(G12<180,"MOB3-6",IF(G12<365,"MOB6-12","MOB12+"))))) -> MOB1-
A13: 首贷 | B13: 管户金条-毅航合肥职场 | C13: 799583 | D13: 张玉慧 | E13: 2025-12-12 10:03:31 | F13: 2025-12-12 10:03:31 | G13: 121 | H13: 121 | I13: 2026-04-12 18:05:52 | J13: 5950 | K13: 7343 | L13: 2332 | M13: 309883 | N13: 233186 | O13: 27 | P13: 40 | Q13: 2563500 | R13: 0 | S13: 0 | U13: 2563500 | V13: =IF(OR(I13="",说明首页!$C$3-INT(I13)>7),"是","否") -> 否 | W13: =IF(OR(O13="",O13<22),"是","否") -> 否 | X13: =IF(AND(V13="否",W13="否"),"是","否") -> 是 | Y13: =IF(OR(I13="",说明首页!$C$3-INT(I13)>=3),"是","否") -> 否 | Z13: =IF(L13>0,N13/L13,0) -> 99.993997 | AA13: =IF(J13>0,P13/J13*100,0) -> 0.67226891 | AB13: =IF(AND(P13<>"",P13>0),Q13/P13,0) -> 64087.5 | AC13: =IF(O13>0,L13/O13,0) -> 86.37037 | AD13: =IF(X13="是",COUNTIFS($X$2:$X$5000,"是",$Z$2:$Z$5000,"<"&Z13)/COUNTIF($X$2:$X$5000,"是")*100,"") -> 79.354839 | AE13: =IF(X13="是",COUNTIFS($X$2:$X$5000,"是",$AA$2:$AA$5000,"<"&AA13)/COUNTIF($X$2:$X$5000,"是")*100,"") -> 19.784946 | AF13: =IF(X13="是",COUNTIFS($X$2:$X$5000,"是",$AC$2:$AC$5000,"<"&AC13)/COUNTIF($X$2:$X$5000,"是")*100,"") -> 73.548387 | AG13: =IF(X13="是",ROUND(AD13*0.3+AE13*0.55+AF13*0.15,2),"") -> 45.72 | AH13: =IF(X13="是",COUNTIFS($X$2:$X$5000,"是",$AG$2:$AG$5000,">"&AG13)+1,"") -> 272 | AI13: =IF(X13<>"是","非参评",IF(AND(AH13<=COUNTIF($X$2:$X$5000,"是")*0.2,AA13>MEDIAN(IF($X$2:$X$5000="是",$AA$2:$AA$5000))),"S",IF(AH13<=COUNTIF($X$2:$X$5000,"是")*0.5,"A",IF(AH13<=COUNTIF($X$2:$X$5000,"是")*0.8,"B","C")))) -> B | AJ13: =IF(G13="","无数据",IF(G13<30,"MOB1-",IF(G13<90,"MOB1-3",IF(G13<180,"MOB3-6",IF(G13<365,"MOB6-12","MOB12+"))))) -> MOB3-6
A14: 首贷 | B14: 管户金条-毛毛虫职场 | C14: 785218 | D14: 姚永生 | E14: 2025-05-26 11:10:46 | F14: 2025-05-26 11:10:46 | G14: 321 | H14: 321 | I14: 2026-04-12 18:21:05 | J14: 4546 | K14: 4604 | L14: 1833 | M14: 213598 | N14: 171346 | O14: 24 | P14: 40 | Q14: 1129900 | R14: 1 | S14: 2 | T14: 1300 | U14: 1131200 | V14: =IF(OR(I14="",说明首页!$C$3-INT(I14)>7),"是","否") -> 否 | W14: =IF(OR(O14="",O14<22),"是","否") -> 否 | X14: =IF(AND(V14="否",W14="否"),"是","否") -> 是 | Y14: =IF(OR(I14="",说明首页!$C$3-INT(I14)>=3),"是","否") -> 否 | Z14: =IF(L14>0,N14/L14,0) -> 93.478451 | AA14: =IF(J14>0,P14/J14*100,0) -> 0.87989441 | AB14: =IF(AND(P14<>"",P14>0),Q14/P14,0) -> 28247.5 | AC14: =IF(O14>0,L14/O14,0) -> 76.375 | AD14: =IF(X14="是",COUNTIFS($X$2:$X$5000,"是",$Z$2:$Z$5000,"<"&Z14)/COUNTIF($X$2:$X$5000,"是")*100,"") -> 66.021505 | AE14: =IF(X14="是",COUNTIFS($X$2:$X$5000,"是",$AA$2:$AA$5000,"<"&AA14)/COUNTIF($X$2:$X$5000,"是")*100,"") -> 44.731183 | AF14: =IF(X14="是",COUNTIFS($X$2:$X$5000,"是",$AC$2:$AC$5000,"<"&AC14)/COUNTIF($X$2:$X$5000,"是")*100,"") -> 43.44086 | AG14: =IF(X14="是",ROUND(AD14*0.3+AE14*0.55+AF14*0.15,2),"") -> 50.92 | AH14: =IF(X14="是",COUNTIFS($X$2:$X$5000,"是",$AG$2:$AG$5000,">"&AG14)+1,"") -> 226 | AI14: =IF(X14<>"是","非参评",IF(AND(AH14<=COUNTIF($X$2:$X$5000,"是")*0.2,AA14>MEDIAN(IF($X$2:$X$5000="是",$AA$2:$AA$5000))),"S",IF(AH14<=COUNTIF($X$2:$X$5000,"是")*0.5,"A",IF(AH14<=COUNTIF($X$2:$X$5000,"是")*0.8,"B","C")))) -> A | AJ14: =IF(G14="","无数据",IF(G14<30,"MOB1-",IF(G14<90,"MOB1-3",IF(G14<180,"MOB3-6",IF(G14<365,"MOB6-12","MOB12+"))))) -> MOB6-12
A15: 首贷 | B15: 管户金条-毛毛虫职场 | C15: 804168 | D15: 方乔慧 | E15: 2026-03-12 18:27:13 | F15: 2026-03-12 18:27:13 | G15: 31 | H15: 31 | I15: 2026-04-11 17:00:02 | J15: 4605 | K15: 5785 | L15: 2054 | M15: 193354 | N15: 143864 | O15: 24 | P15: 40 | Q15: 1303600 | R15: 2 | S15: 2 | T15: 1700 | U15: 1305300 | V15: =IF(OR(I15="",说明首页!$C$3-INT(I15)>7),"是","否") -> 否 | W15: =IF(OR(O15="",O15<22),"是","否") -> 否 | X15: =IF(AND(V15="否",W15="否"),"是","否") -> 是 | Y15: =IF(OR(I15="",说明首页!$C$3-INT(I15)>=3),"是","否") -> 否 | Z15: =IF(L15>0,N15/L15,0) -> 70.040896 | AA15: =IF(J15>0,P15/J15*100,0) -> 0.86862106 | AB15: =IF(AND(P15<>"",P15>0),Q15/P15,0) -> 32590 | AC15: =IF(O15>0,L15/O15,0) -> 85.583333 | AD15: =IF(X15="是",COUNTIFS($X$2:$X$5000,"是",$Z$2:$Z$5000,"<"&Z15)/COUNTIF($X$2:$X$5000,"是")*100,"") -> 8.6021505 | AE15: =IF(X15="是",COUNTIFS($X$2:$X$5000,"是",$AA$2:$AA$5000,"<"&AA15)/COUNTIF($X$2:$X$5000,"是")*100,"") -> 43.44086 | AF15: =IF(X15="是",COUNTIFS($X$2:$X$5000,"是",$AC$2:$AC$5000,"<"&AC15)/COUNTIF($X$2:$X$5000,"是")*100,"") -> 71.182796 | AG15: =IF(X15="是",ROUND(AD15*0.3+AE15*0.55+AF15*0.15,2),"") -> 37.15 | AH15: =IF(X15="是",COUNTIFS($X$2:$X$5000,"是",$AG$2:$AG$5000,">"&AG15)+1,"") -> 322 | AI15: =IF(X15<>"是","非参评",IF(AND(AH15<=COUNTIF($X$2:$X$5000,"是")*0.2,AA15>MEDIAN(IF($X$2:$X$5000="是",$AA$2:$AA$5000))),"S",IF(AH15<=COUNTIF($X$2:$X$5000,"是")*0.5,"A",IF(AH15<=COUNTIF($X$2:$X$5000,"是")*0.8,"B","C")))) -> B | AJ15: =IF(G15="","无数据",IF(G15<30,"MOB1-",IF(G15<90,"MOB1-3",IF(G15<180,"MOB3-6",IF(G15<365,"MOB6-12","MOB12+"))))) -> MOB1-3
A16: 首贷 | B16: 管户金条-伽玛职场 | C16: 806835 | D16: 马鑫伟 | E16: 2026-04-02 10:34:16 | F16: 2026-04-02 10:34:16 | G16: 10 | H16: 10 | I16: 2026-04-12 18:27:48 | J16: 776 | K16: 969 | L16: 424 | M16: 50303 | N16: 42456 | O16: 7 | P16: 2 | Q16: 3000 | R16: 0 | S16: 0 | U16: 3000 | V16: =IF(OR(I16="",说明首页!$C$3-INT(I16)>7),"是","否") -> 否 | W16: =IF(OR(O16="",O16<22),"是","否") -> 是 | X16: =IF(AND(V16="否",W16="否"),"是","否") -> 否 | Y16: =IF(OR(I16="",说明首页!$C$3-INT(I16)>=3),"是","否") -> 否 | Z16: =IF(L16>0,N16/L16,0) -> 100.13208 | AA16: =IF(J16>0,P16/J16*100,0) -> 0.25773196 | AB16: =IF(AND(P16<>"",P16>0),Q16/P16,0) -> 1500 | AC16: =IF(O16>0,L16/O16,0) -> 60.571429 | AD16: =IF(X16="是",COUNTIFS($X$2:$X$5000,"是",$Z$2:$Z$5000,"<"&Z16)/COUNTIF($X$2:$X$5000,"是")*100,"") | AE16: =IF(X16="是",COUNTIFS($X$2:$X$5000,"是",$AA$2:$AA$5000,"<"&AA16)/COUNTIF($X$2:$X$5000,"是")*100,"") | AF16: =IF(X16="是",COUNTIFS($X$2:$X$5000,"是",$AC$2:$AC$5000,"<"&AC16)/COUNTIF($X$2:$X$5000,"是")*100,"") | AG16: =IF(X16="是",ROUND(AD16*0.3+AE16*0.55+AF16*0.15,2),"") | AH16: =IF(X16="是",COUNTIFS($X$2:$X$5000,"是",$AG$2:$AG$5000,">"&AG16)+1,"") | AI16: =IF(X16<>"是","非参评",IF(AND(AH16<=COUNTIF($X$2:$X$5000,"是")*0.2,AA16>MEDIAN(IF($X$2:$X$5000="是",$AA$2:$AA$5000))),"S",IF(AH16<=COUNTIF($X$2:$X$5000,"是")*0.5,"A",IF(AH16<=COUNTIF($X$2:$X$5000,"是")*0.8,"B","C")))) -> 非参评 | AJ16: =IF(G16="","无数据",IF(G16<30,"MOB1-",IF(G16<90,"MOB1-3",IF(G16<180,"MOB3-6",IF(G16<365,"MOB6-12","MOB12+"))))) -> MOB1-
A17: 首贷 | B17: 管户金条-人和职场 | C17: 795506 | D17: 代丽萍 | E17: 2025-10-14 12:19:34 | F17: 2025-10-14 12:19:34 | G17: 180 | H17: 180 | I17: 2026-04-11 17:59:06 | J17: 3060 | K17: 5364 | L17: 1296 | M17: 179734 | N17: 125313 | O17: 27 | P17: 31 | Q17: 1333300 | R17: 1 | S17: 1 | T17: 20000 | U17: 1353300 | V17: =IF(OR(I17="",说明首页!$C$3-INT(I17)>7),"是","否") -> 否 | W17: =IF(OR(O17="",O17<22),"是","否") -> 否 | X17: =IF(AND(V17="否",W17="否"),"是","否") -> 是 | Y17: =IF(OR(I17="",说明首页!$C$3-INT(I17)>=3),"是","否") -> 否 | Z17: =IF(L17>0,N17/L17,0) -> 96.69213 | AA17: =IF(J17>0,P17/J17*100,0) -> 1.0130719 | AB17: =IF(AND(P17<>"",P17>0),Q17/P17,0) -> 43009.677 | AC17: =IF(O17>0,L17/O17,0) -> 48 | AD17: =IF(X17="是",COUNTIFS($X$2:$X$5000,"是",$Z$2:$Z$5000,"<"&Z17)/COUNTIF($X$2:$X$5000,"是")*100,"") -> 73.11828 | AE17: =IF(X17="是",COUNTIFS($X$2:$X$5000,"是",$AA$2:$AA$5000,"<"&AA17)/COUNTIF($X$2:$X$5000,"是")*100,"") -> 62.365591 | AF17: =IF(X17="是",COUNTIFS($X$2:$X$5000,"是",$AC$2:$AC$5000,"<"&AC17)/COUNTIF($X$2:$X$5000,"是")*100,"") -> 1.9354839 | AG17: =IF(X17="是",ROUND(AD17*0.3+AE17*0.55+AF17*0.15,2),"") -> 56.53 | AH17: =IF(X17="是",COUNTIFS($X$2:$X$5000,"是",$AG$2:$AG$5000,">"&AG17)+1,"") -> 179 | AI17: =IF(X17<>"是","非参评",IF(AND(AH17<=COUNTIF($X$2:$X$5000,"是")*0.2,AA17>MEDIAN(IF($X$2:$X$5000="是",$AA$2:$AA$5000))),"S",IF(AH17<=COUNTIF($X$2:$X$5000,"是")*0.5,"A",IF(AH17<=COUNTIF($X$2:$X$5000,"是")*0.8,"B","C")))) -> A | AJ17: =IF(G17="","无数据",IF(G17<30,"MOB1-",IF(G17<90,"MOB1-3",IF(G17<180,"MOB3-6",IF(G17<365,"MOB6-12","MOB12+"))))) -> MOB6-12
A18: 首贷 | B18: 管户金条-赛维斯职场 | C18: 804459 | D18: 梁泽鹏 | E18: 2026-03-18 16:32:20 | F18: 2026-03-18 16:32:20 | G18: 25 | H18: 25 | I18: 2026-04-07 09:11:28 | J18: 984 | K18: 996 | L18: 492 | M18: 48358 | N18: 41558 | O18: 7 | P18: 3 | Q18: 4100 | R18: 0 | S18: 0 | U18: 4100 | V18: =IF(OR(I18="",说明首页!$C$3-INT(I18)>7),"是","否") -> 否 | W18: =IF(OR(O18="",O18<22),"是","否") -> 是 | X18: =IF(AND(V18="否",W18="否"),"是","否") -> 否 | Y18: =IF(OR(I18="",说明首页!$C$3-INT(I18)>=3),"是","否") -> 是 | Z18: =IF(L18>0,N18/L18,0) -> 84.46748 | AA18: =IF(J18>0,P18/J18*100,0) -> 0.30487805 | AB18: =IF(AND(P18<>"",P18>0),Q18/P18,0) -> 1366.6667 | AC18: =IF(O18>0,L18/O18,0) -> 70.285714 | AD18: =IF(X18="是",COUNTIFS($X$2:$X$5000,"是",$Z$2:$Z$5000,"<"&Z18)/COUNTIF($X$2:$X$5000,"是")*100,"") | AE18: =IF(X18="是",COUNTIFS($X$2:$X$5000,"是",$AA$2:$AA$5000,"<"&AA18)/COUNTIF($X$2:$X$5000,"是")*100,"") | AF18: =IF(X18="是",COUNTIFS($X$2:$X$5000,"是",$AC$2:$AC$5000,"<"&AC18)/COUNTIF($X$2:$X$5000,"是")*100,"") | AG18: =IF(X18="是",ROUND(AD18*0.3+AE18*0.55+AF18*0.15,2),"") | AH18: =IF(X18="是",COUNTIFS($X$2:$X$5000,"是",$AG$2:$AG$5000,">"&AG18)+1,"") | AI18: =IF(X18<>"是","非参评",IF(AND(AH18<=COUNTIF($X$2:$X$5000,"是")*0.2,AA18>MEDIAN(IF($X$2:$X$5000="是",$AA$2:$AA$5000))),"S",IF(AH18<=COUNTIF($X$2:$X$5000,"是")*0.5,"A",IF(AH18<=COUNTIF($X$2:$X$5000,"是")*0.8,"B","C")))) -> 非参评 | AJ18: =IF(G18="","无数据",IF(G18<30,"MOB1-",IF(G18<90,"MOB1-3",IF(G18<180,"MOB3-6",IF(G18<365,"MOB6-12","MOB12+"))))) -> MOB1-
A19: 首贷 | B19: 管户金条-翰锐曲靖职场 | C19: 804003 | D19: 孙叶琪 | E19: 2026-03-11 14:29:55 | F19: 2026-03-11 14:29:55 | G19: 32 | H19: 32 | I19: 2026-04-11 18:06:34 | J19: 4947 | K19: 5352 | L19: 2121 | M19: 221655 | N19: 172510 | O19: 26 | P19: 31 | Q19: 265400 | R19: 2 | S19: 2 | T19: 68800 | U19: 334200 | V19: =IF(OR(I19="",说明首页!$C$3-INT(I19)>7),"是","否") -> 否 | W19: =IF(OR(O19="",O19<22),"是","否") -> 否 | X19: =IF(AND(V19="否",W19="否"),"是","否") -> 是 | Y19: =IF(OR(I19="",说明首页!$C$3-INT(I19)>=3),"是","否") -> 否 | Z19: =IF(L19>0,N19/L19,0) -> 81.334276 | AA19: =IF(J19>0,P19/J19*100,0) -> 0.62664241 | AB19: =IF(AND(P19<>"",P19>0),Q19/P19,0) -> 8561.2903 | AC19: =IF(O19>0,L19/O19,0) -> 81.576923 | AD19: =IF(X19="是",COUNTIFS($X$2:$X$5000,"是",$Z$2:$Z$5000,"<"&Z19)/COUNTIF($X$2:$X$5000,"是")*100,"") -> 30.107527 | AE19: =IF(X19="是",COUNTIFS($X$2:$X$5000,"是",$AA$2:$AA$5000,"<"&AA19)/COUNTIF($X$2:$X$5000,"是")*100,"") -> 13.978495 | AF19: =IF(X19="是",COUNTIFS($X$2:$X$5000,"是",$AC$2:$AC$5000,"<"&AC19)/COUNTIF($X$2:$X$5000,"是")*100,"") -> 61.290323 | AG19: =IF(X19="是",ROUND(AD19*0.3+AE19*0.55+AF19*0.15,2),"") -> 25.91 | AH19: =IF(X19="是",COUNTIFS($X$2:$X$5000,"是",$AG$2:$AG$5000,">"&AG19)+1,"") -> 399 | AI19: =IF(X19<>"是","非参评",IF(AND(AH19<=COUNTIF($X$2:$X$5000,"是")*0.2,AA19>MEDIAN(IF($X$2:$X$5000="是",$AA$2:$AA$5000))),"S",IF(AH19<=COUNTIF($X$2:$X$5000,"是")*0.5,"A",IF(AH19<=COUNTIF($X$2:$X$5000,"是")*0.8,"B","C")))) -> C | AJ19: =IF(G19="","无数据",IF(G19<30,"MOB1-",IF(G19<90,"MOB1-3",IF(G19<180,"MOB3-6",IF(G19<365,"MOB6-12","MOB12+"))))) -> MOB1-3
A20: 首贷 | B20: 管户金条-毅航合肥职场 | C20: 769488 | D20: 刘壮 | E20: 2024-10-30 10:04:01 | F20: 2024-10-30 10:04:01 | G20: 529 | H20: 529 | I20: 2026-04-03 18:09:31 | J20: 292 | K20: 293 | L20: 138 | M20: 16761 | N20: 14435 | O20: 6 | P20: 1 | Q20: 12200 | R20: 0 | S20: 0 | U20: 12200 | V20: =IF(OR(I20="",说明首页!$C$3-INT(I20)>7),"是","否") -> 是 | W20: =IF(OR(O20="",O20<22),"是","否") -> 是 | X20: =IF(AND(V20="否",W20="否"),"是","否") -> 否 | Y20: =IF(OR(I20="",说明首页!$C$3-INT(I20)>=3),"是","否") -> 是 | Z20: =IF(L20>0,N20/L20,0) -> 104.60145 | AA20: =IF(J20>0,P20/J20*100,0) -> 0.34246575 | AB20: =IF(AND(P20<>"",P20>0),Q20/P20,0) -> 12200 | AC20: =IF(O20>0,L20/O20,0) -> 23 | AD20: =IF(X20="是",COUNTIFS($X$2:$X$5000,"是",$Z$2:$Z$5000,"<"&Z20)/COUNTIF($X$2:$X$5000,"是")*100,"") | AE20: =IF(X20="是",COUNTIFS($X$2:$X$5000,"是",$AA$2:$AA$5000,"<"&AA20)/COUNTIF($X$2:$X$5000,"是")*100,"") | AF20: =IF(X20="是",COUNTIFS($X$2:$X$5000,"是",$AC$2:$AC$5000,"<"&AC20)/COUNTIF($X$2:$X$5000,"是")*100,"") | AG20: =IF(X20="是",ROUND(AD20*0.3+AE20*0.55+AF20*0.15,2),"") | AH20: =IF(X20="是",COUNTIFS($X$2:$X$5000,"是",$AG$2:$AG$5000,">"&AG20)+1,"") | AI20: =IF(X20<>"是","非参评",IF(AND(AH20<=COUNTIF($X$2:$X$5000,"是")*0.2,AA20>MEDIAN(IF($X$2:$X$5000="是",$AA$2:$AA$5000))),"S",IF(AH20<=COUNTIF($X$2:$X$5000,"是")*0.5,"A",IF(AH20<=COUNTIF($X$2:$X$5000,"是")*0.8,"B","C")))) -> 非参评 | AJ20: =IF(G20="","无数据",IF(G20<30,"MOB1-",IF(G20<90,"MOB1-3",IF(G20<180,"MOB3-6",IF(G20<365,"MOB6-12","MOB12+"))))) -> MOB12+
A21: 首贷 | B21: 管户金条-毅航合肥职场 | C21: 784858 | D21: 张梦婷 | E21: 2025-05-19 09:55:39 | F21: 2025-05-19 09:55:39 | G21: 328 | H21: 328 | I21: 2026-04-03 19:11:52 | J21: 388 | K21: 391 | L21: 156 | M21: 17069 | N21: 13537 | O21: 5 | P21: 3 | Q21: 14800 | R21: 0 | S21: 0 | U21: 14800 | V21: =IF(OR(I21="",说明首页!$C$3-INT(I21)>7),"是","否") -> 是 | W21: =IF(OR(O21="",O21<22),"是","否") -> 是 | X21: =IF(AND(V21="否",W21="否"),"是","否") -> 否 | Y21: =IF(OR(I21="",说明首页!$C$3-INT(I21)>=3),"是","否") -> 是 | Z21: =IF(L21>0,N21/L21,0) -> 86.775641 | AA21: =IF(J21>0,P21/J21*100,0) -> 0.77319588 | AB21: =IF(AND(P21<>"",P21>0),Q21/P21,0) -> 4933.3333 | AC21: =IF(O21>0,L21/O21,0) -> 31.2 | AD21: =IF(X21="是",COUNTIFS($X$2:$X$5000,"是",$Z$2:$Z$5000,"<"&Z21)/COUNTIF($X$2:$X$5000,"是")*100,"") | AE21: =IF(X21="是",COUNTIFS($X$2:$X$5000,"是",$AA$2:$AA$5000,"<"&AA21)/COUNTIF($X$2:$X$5000,"是")*100,"") | AF21: =IF(X21="是",COUNTIFS($X$2:$X$5000,"是",$AC$2:$AC$5000,"<"&AC21)/COUNTIF($X$2:$X$5000,"是")*100,"") | AG21: =IF(X21="是",ROUND(AD21*0.3+AE21*0.55+AF21*0.15,2),"") | AH21: =IF(X21="是",COUNTIFS($X$2:$X$5000,"是",$AG$2:$AG$5000,">"&AG21)+1,"") | AI21: =IF(X21<>"是","非参评",IF(AND(AH21<=COUNTIF($X$2:$X$5000,"是")*0.2,AA21>MEDIAN(IF($X$2:$X$5000="是",$AA$2:$AA$5000))),"S",IF(AH21<=COUNTIF($X$2:$X$5000,"是")*0.5,"A",IF(AH21<=COUNTIF($X$2:$X$5000,"是")*0.8,"B","C")))) -> 非参评 | AJ21: =IF(G21="","无数据",IF(G21<30,"MOB1-",IF(G21<90,"MOB1-3",IF(G21<180,"MOB3-6",IF(G21<365,"MOB6-12","MOB12+"))))) -> MOB6-12
A22: 首贷 | B22: 管户金条-博岳石家庄职场 | C22: 794909 | D22: 郑文帅 | E22: 2025-09-30 10:11:36 | F22: 2025-09-30 10:11:36 | G22: 194 | H22: 194 | I22: 2026-04-11 19:30:25 | J22: 4880 | K22: 5950 | L22: 1588 | M22: 231534 | N22: 168835 | O22: 28 | P22: 85 | Q22: 904800 | R22: 7 | S22: 8 | T22: 38500 | U22: 943300 | V22: =IF(OR(I22="",说明首页!$C$3-INT(I22)>7),"是","否") -> 否 | W22: =IF(OR(O22="",O22<22),"是","否") -> 否 | X22: =IF(AND(V22="否",W22="否"),"是","否") -> 是 | Y22: =IF(OR(I22="",说明首页!$C$3-INT(I22)>=3),"是","否") -> 否 | Z22: =IF(L22>0,N22/L22,0) -> 106.31927 | AA22: =IF(J22>0,P22/J22*100,0) -> 1.7418033 | AB22: =IF(AND(P22<>"",P22>0),Q22/P22,0) -> 10644.706 | AC22: =IF(O22>0,L22/O22,0) -> 56.714286 | AD22: =IF(X22="是",COUNTIFS($X$2:$X$5000,"是",$Z$2:$Z$5000,"<"&Z22)/COUNTIF($X$2:$X$5000,"是")*100,"") -> 85.591398 | AE22: =IF(X22="是",COUNTIFS($X$2:$X$5000,"是",$AA$2:$AA$5000,"<"&AA22)/COUNTIF($X$2:$X$5000,"是")*100,"") -> 96.344086 | AF22: =IF(X22="是",COUNTIFS($X$2:$X$5000,"是",$AC$2:$AC$5000,"<"&AC22)/COUNTIF($X$2:$X$5000,"是")*100,"") -> 6.6666667 | AG22: =IF(X22="是",ROUND(AD22*0.3+AE22*0.55+AF22*0.15,2),"") -> 79.67 | AH22: =IF(X22="是",COUNTIFS($X$2:$X$5000,"是",$AG$2:$AG$5000,">"&AG22)+1,"") -> 40 | AI22: =IF(X22<>"是","非参评",IF(AND(AH22<=COUNTIF($X$2:$X$5000,"是")*0.2,AA22>MEDIAN(IF($X$2:$X$5000="是",$AA$2:$AA$5000))),"S",IF(AH22<=COUNTIF($X$2:$X$5000,"是")*0.5,"A",IF(AH22<=COUNTIF($X$2:$X$5000,"是")*0.8,"B","C")))) -> S | AJ22: =IF(G22="","无数据",IF(G22<30,"MOB1-",IF(G22<90,"MOB1-3",IF(G22<180,"MOB3-6",IF(G22<365,"MOB6-12","MOB12+"))))) -> MOB6-12
A23: 首贷 | B23: 管户金条-毛毛虫职场 | C23: 626597 | D23: 徐玉婷 | E23: 2025-09-29 10:11:31 | F23: 2025-09-29 10:11:31 | G23: 195 | H23: 195 | I23: 2026-04-11 18:05:13 | J23: 4612 | K23: 4987 | L23: 1825 | M23: 220100 | N23: 173156 | O23: 24 | P23: 43 | Q23: 952000 | R23: 3 | S23: 3 | T23: 6500 | U23: 958500 | V23: =IF(OR(I23="",说明首页!$C$3-INT(I23)>7),"是","否") -> 否 | W23: =IF(OR(O23="",O23<22),"是","否") -> 否 | X23: =IF(AND(V23="否",W23="否"),"是","否") -> 是 | Y23: =IF(OR(I23="",说明首页!$C$3-INT(I23)>=3),"是","否") -> 否 | Z23: =IF(L23>0,N23/L23,0) -> 94.88 | AA23: =IF(J23>0,P23/J23*100,0) -> 0.93235039 | AB23: =IF(AND(P23<>"",P23>0),Q23/P23,0) -> 22139.535 | AC23: =IF(O23>0,L23/O23,0) -> 76.041667 | AD23: =IF(X23="是",COUNTIFS($X$2:$X$5000,"是",$Z$2:$Z$5000,"<"&Z23)/COUNTIF($X$2:$X$5000,"是")*100,"") -> 69.032258 | AE23: =IF(X23="是",COUNTIFS($X$2:$X$5000,"是",$AA$2:$AA$5000,"<"&AA23)/COUNTIF($X$2:$X$5000,"是")*100,"") -> 50.752688 | AF23: =IF(X23="是",COUNTIFS($X$2:$X$5000,"是",$AC$2:$AC$5000,"<"&AC23)/COUNTIF($X$2:$X$5000,"是")*100,"") -> 42.150538 | AG23: =IF(X23="是",ROUND(AD23*0.3+AE23*0.55+AF23*0.15,2),"") -> 54.95 | AH23: =IF(X23="是",COUNTIFS($X$2:$X$5000,"是",$AG$2:$AG$5000,">"&AG23)+1,"") -> 194 | AI23: =IF(X23<>"是","非参评",IF(AND(AH23<=COUNTIF($X$2:$X$5000,"是")*0.2,AA23>MEDIAN(IF($X$2:$X$5000="是",$AA$2:$AA$5000))),"S",IF(AH23<=COUNTIF($X$2:$X$5000,"是")*0.5,"A",IF(AH23<=COUNTIF($X$2:$X$5000,"是")*0.8,"B","C")))) -> A | AJ23: =IF(G23="","无数据",IF(G23<30,"MOB1-",IF(G23<90,"MOB1-3",IF(G23<180,"MOB3-6",IF(G23<365,"MOB6-12","MOB12+"))))) -> MOB6-12
A24: 首贷 | B24: 管户金条-毛毛虫职场 | C24: 744767 | D24: 祝鹏飞 | E24: 2023-08-21 15:55:26 | F24: 2023-08-21 15:55:26 | G24: 965 | H24: 965 | I24: 2026-04-11 11:37:36 | J24: 1000 | K24: 1007 | L24: 443 | M24: 48512 | N24: 40057 | O24: 18 | P24: 10 | Q24: 193900 | R24: 0 | S24: 0 | U24: 193900 | V24: =IF(OR(I24="",说明首页!$C$3-INT(I24)>7),"是","否") -> 否 | W24: =IF(OR(O24="",O24<22),"是","否") -> 是 | X24: =IF(AND(V24="否",W24="否"),"是","否") -> 否 | Y24: =IF(OR(I24="",说明首页!$C$3-INT(I24)>=3),"是","否") -> 否 | Z24: =IF(L24>0,N24/L24,0) -> 90.422122 | AA24: =IF(J24>0,P24/J24*100,0) -> 1 | AB24: =IF(AND(P24<>"",P24>0),Q24/P24,0) -> 19390 | AC24: =IF(O24>0,L24/O24,0) -> 24.611111 | AD24: =IF(X24="是",COUNTIFS($X$2:$X$5000,"是",$Z$2:$Z$5000,"<"&Z24)/COUNTIF($X$2:$X$5000,"是")*100,"") | AE24: =IF(X24="是",COUNTIFS($X$2:$X$5000,"是",$AA$2:$AA$5000,"<"&AA24)/COUNTIF($X$2:$X$5000,"是")*100,"") | AF24: =IF(X24="是",COUNTIFS($X$2:$X$5000,"是",$AC$2:$AC$5000,"<"&AC24)/COUNTIF($X$2:$X$5000,"是")*100,"") | AG24: =IF(X24="是",ROUND(AD24*0.3+AE24*0.55+AF24*0.15,2),"") | AH24: =IF(X24="是",COUNTIFS($X$2:$X$5000,"是",$AG$2:$AG$5000,">"&AG24)+1,"") | AI24: =IF(X24<>"是","非参评",IF(AND(AH24<=COUNTIF($X$2:$X$5000,"是")*0.2,AA24>MEDIAN(IF($X$2:$X$5000="是",$AA$2:$AA$5000))),"S",IF(AH24<=COUNTIF($X$2:$X$5000,"是")*0.5,"A",IF(AH24<=COUNTIF($X$2:$X$5000,"是")*0.8,"B","C")))) -> 非参评 | AJ24: =IF(G24="","无数据",IF(G24<30,"MOB1-",IF(G24<90,"MOB1-3",IF(G24<180,"MOB3-6",IF(G24<365,"MOB6-12","MOB12+"))))) -> MOB12+
A25: 首贷 | B25: 管户金条-广达陕西职场 | C25: 753101 | D25: 高阳 | E25: 2026-03-19 09:33:24 | F25: 2026-03-19 09:33:24 | G25: 24 | H25: 24 | I25: 2026-03-20 10:54:44 | J25: 8 | K25: 12 | L25: 2 | M25: 200 | N25: 87 | V25: =IF(OR(I25="",说明首页!$C$3-INT(I25)>7),"是","否") -> 是 | W25: =IF(OR(O25="",O25<22),"是","否") -> 是 | X25: =IF(AND(V25="否",W25="否"),"是","否") -> 否 | Y25: =IF(OR(I25="",说明首页!$C$3-INT(I25)>=3),"是","否") -> 是 | Z25: =IF(L25>0,N25/L25,0) -> 43.5 | AA25: =IF(J25>0,P25/J25*100,0) -> 0 | AB25: =IF(AND(P25<>"",P25>0),Q25/P25,0) -> 0 | AC25: =IF(O25>0,L25/O25,0) -> 0 | AD25: =IF(X25="是",COUNTIFS($X$2:$X$5000,"是",$Z$2:$Z$5000,"<"&Z25)/COUNTIF($X$2:$X$5000,"是")*100,"") | AE25: =IF(X25="是",COUNTIFS($X$2:$X$5000,"是",$AA$2:$AA$5000,"<"&AA25)/COUNTIF($X$2:$X$5000,"是")*100,"") | AF25: =IF(X25="是",COUNTIFS($X$2:$X$5000,"是",$AC$2:$AC$5000,"<"&AC25)/COUNTIF($X$2:$X$5000,"是")*100,"") | AG25: =IF(X25="是",ROUND(AD25*0.3+AE25*0.55+AF25*0.15,2),"") | AH25: =IF(X25="是",COUNTIFS($X$2:$X$5000,"是",$AG$2:$AG$5000,">"&AG25)+1,"") | AI25: =IF(X25<>"是","非参评",IF(AND(AH25<=COUNTIF($X$2:$X$5000,"是")*0.2,AA25>MEDIAN(IF($X$2:$X$5000="是",$AA$2:$AA$5000))),"S",IF(AH25<=COUNTIF($X$2:$X$5000,"是")*0.5,"A",IF(AH25<=COUNTIF($X$2:$X$5000,"是")*0.8,"B","C")))) -> 非参评 | AJ25: =IF(G25="","无数据",IF(G25<30,"MOB1-",IF(G25<90,"MOB1-3",IF(G25<180,"MOB3-6",IF(G25<365,"MOB6-12","MOB12+"))))) -> MOB1-
A26: 首贷 | B26: 管户金条-博岳石家庄职场 | C26: 756714 | D26: 博岳5号 | E26: 2024-01-12 16:32:53 | F26: 2024-01-12 16:32:53 | G26: 821 | H26: 821 | I26: 2026-03-19 19:20:31 | J26: 71 | K26: 74 | L26: 24 | M26: 3966 | N26: 3298 | O26: 2 | V26: =IF(OR(I26="",说明首页!$C$3-INT(I26)>7),"是","否") -> 是 | W26: =IF(OR(O26="",O26<22),"是","否") -> 是 | X26: =IF(AND(V26="否",W26="否"),"是","否") -> 否 | Y26: =IF(OR(I26="",说明首页!$C$3-INT(I26)>=3),"是","否") -> 是 | Z26: =IF(L26>0,N26/L26,0) -> 137.41667 | AA26: =IF(J26>0,P26/J26*100,0) -> 0 | AB26: =IF(AND(P26<>"",P26>0),Q26/P26,0) -> 0 | AC26: =IF(O26>0,L26/O26,0) -> 12 | AD26: =IF(X26="是",COUNTIFS($X$2:$X$5000,"是",$Z$2:$Z$5000,"<"&Z26)/COUNTIF($X$2:$X$5000,"是")*100,"") | AE26: =IF(X26="是",COUNTIFS($X$2:$X$5000,"是",$AA$2:$AA$5000,"<"&AA26)/COUNTIF($X$2:$X$5000,"是")*100,"") | AF26: =IF(X26="是",COUNTIFS($X$2:$X$5000,"是",$AC$2:$AC$5000,"<"&AC26)/COUNTIF($X$2:$X$5000,"是")*100,"") | AG26: =IF(X26="是",ROUND(AD26*0.3+AE26*0.55+AF26*0.15,2),"") | AH26: =IF(X26="是",COUNTIFS($X$2:$X$5000,"是",$AG$2:$AG$5000,">"&AG26)+1,"") | AI26: =IF(X26<>"是","非参评",IF(AND(AH26<=COUNTIF($X$2:$X$5000,"是")*0.2,AA26>MEDIAN(IF($X$2:$X$5000="是",$AA$2:$AA$5000))),"S",IF(AH26<=COUNTIF($X$2:$X$5000,"是")*0.5,"A",IF(AH26<=COUNTIF($X$2:$X$5000,"是")*0.8,"B","C")))) -> 非参评 | AJ26: =IF(G26="","无数据",IF(G26<30,"MOB1-",IF(G26<90,"MOB1-3",IF(G26<180,"MOB3-6",IF(G26<365,"MOB6-12","MOB12+"))))) -> MOB12+
A27: 首贷 | B27: 管户金条-毅航合肥职场 | C27: 791030 | D27: 伯招财 | E27: 2025-08-25 09:27:55 | F27: 2025-08-25 09:27:55 | G27: 230 | H27: 230 | I27: 2026-03-31 15:23:24 | J27: 336 | K27: 338 | L27: 145 | M27: 17001 | N27: 14065 | O27: 6 | P27: 1 | Q27: 500 | R27: 0 | S27: 0 | U27: 500 | V27: =IF(OR(I27="",说明首页!$C$3-INT(I27)>7),"是","否") -> 是 | W27: =IF(OR(O27="",O27<22),"是","否") -> 是 | X27: =IF(AND(V27="否",W27="否"),"是","否") -> 否 | Y27: =IF(OR(I27="",说明首页!$C$3-INT(I27)>=3),"是","否") -> 是 | Z27: =IF(L27>0,N27/L27,0) -> 97 | AA27: =IF(J27>0,P27/J27*100,0) -> 0.29761905 | AB27: =IF(AND(P27<>"",P27>0),Q27/P27,0) -> 500 | AC27: =IF(O27>0,L27/O27,0) -> 24.166667 | AD27: =IF(X27="是",COUNTIFS($X$2:$X$5000,"是",$Z$2:$Z$5000,"<"&Z27)/COUNTIF($X$2:$X$5000,"是")*100,"") | AE27: =IF(X27="是",COUNTIFS($X$2:$X$5000,"是",$AA$2:$AA$5000,"<"&AA27)/COUNTIF($X$2:$X$5000,"是")*100,"") | AF27: =IF(X27="是",COUNTIFS($X$2:$X$5000,"是",$AC$2:$AC$5000,"<"&AC27)/COUNTIF($X$2:$X$5000,"是")*100,"") | AG27: =IF(X27="是",ROUND(AD27*0.3+AE27*0.55+AF27*0.15,2),"") | AH27: =IF(X27="是",COUNTIFS($X$2:$X$5000,"是",$AG$2:$AG$5000,">"&AG27)+1,"") | AI27: =IF(X27<>"是","非参评",IF(AND(AH27<=COUNTIF($X$2:$X$5000,"是")*0.2,AA27>MEDIAN(IF($X$2:$X$5000="是",$AA$2:$AA$5000))),"S",IF(AH27<=COUNTIF($X$2:$X$5000,"是")*0.5,"A",IF(AH27<=COUNTIF($X$2:$X$5000,"是")*0.8,"B","C")))) -> 非参评 | AJ27: =IF(G27="","无数据",IF(G27<30,"MOB1-",IF(G27<90,"MOB1-3",IF(G27<180,"MOB3-6",IF(G27<365,"MOB6-12","MOB12+"))))) -> MOB6-12
A28: 首贷 | B28: 管户金条-汇讯职场 | C28: 806913 | D28: 周文慧 | E28: 2026-04-03 14:41:22 | F28: 2026-04-03 14:41:22 | G28: 9 | H28: 9 | I28: 2026-04-11 18:57:51 | J28: 960 | K28: 1141 | L28: 447 | M28: 46447 | N28: 36413 | O28: 6 | P28: 2 | Q28: 1000 | R28: 0 | S28: 0 | U28: 1000 | V28: =IF(OR(I28="",说明首页!$C$3-INT(I28)>7),"是","否") -> 否 | W28: =IF(OR(O28="",O28<22),"是","否") -> 是 | X28: =IF(AND(V28="否",W28="否"),"是","否") -> 否 | Y28: =IF(OR(I28="",说明首页!$C$3-INT(I28)>=3),"是","否") -> 否 | Z28: =IF(L28>0,N28/L28,0) -> 81.46085 | AA28: =IF(J28>0,P28/J28*100,0) -> 0.20833333 | AB28: =IF(AND(P28<>"",P28>0),Q28/P28,0) -> 500 | AC28: =IF(O28>0,L28/O28,0) -> 74.5 | AD28: =IF(X28="是",COUNTIFS($X$2:$X$5000,"是",$Z$2:$Z$5000,"<"&Z28)/COUNTIF($X$2:$X$5000,"是")*100,"") | AE28: =IF(X28="是",COUNTIFS($X$2:$X$5000,"是",$AA$2:$AA$5000,"<"&AA28)/COUNTIF($X$2:$X$5000,"是")*100,"") | AF28: =IF(X28="是",COUNTIFS($X$2:$X$5000,"是",$AC$2:$AC$5000,"<"&AC28)/COUNTIF($X$2:$X$5000,"是")*100,"") | AG28: =IF(X28="是",ROUND(AD28*0.3+AE28*0.55+AF28*0.15,2),"") | AH28: =IF(X28="是",COUNTIFS($X$2:$X$5000,"是",$AG$2:$AG$5000,">"&AG28)+1,"") | AI28: =IF(X28<>"是","非参评",IF(AND(AH28<=COUNTIF($X$2:$X$5000,"是")*0.2,AA28>MEDIAN(IF($X$2:$X$5000="是",$AA$2:$AA$5000))),"S",IF(AH28<=COUNTIF($X$2:$X$5000,"是")*0.5,"A",IF(AH28<=COUNTIF($X$2:$X$5000,"是")*0.8,"B","C")))) -> 非参评 | AJ28: =IF(G28="","无数据",IF(G28<30,"MOB1-",IF(G28<90,"MOB1-3",IF(G28<180,"MOB3-6",IF(G28<365,"MOB6-12","MOB12+"))))) -> MOB1-
A29: 首贷 | B29: 管户金条-毛毛虫职场 | C29: 737825 | D29: 赵武 | E29: 2023-05-30 14:39:58 | F29: 2023-05-30 14:39:58 | G29: 1048 | H29: 1048 | I29: 2026-04-11 18:11:48 | J29: 3529 | K29: 4368 | L29: 929 | M29: 156296 | N29: 108385 | O29: 20 | P29: 47 | Q29: 3922000 | R29: 3 | S29: 3 | T29: 87400 | U29: 4009400 | V29: =IF(OR(I29="",说明首页!$C$3-INT(I29)>7),"是","否") -> 否 | W29: =IF(OR(O29="",O29<22),"是","否") -> 是 | X29: =IF(AND(V29="否",W29="否"),"是","否") -> 否 | Y29: =IF(OR(I29="",说明首页!$C$3-INT(I29)>=3),"是","否") -> 否 | Z29: =IF(L29>0,N29/L29,0) -> 116.66846 | AA29: =IF(J29>0,P29/J29*100,0) -> 1.331822 | AB29: =IF(AND(P29<>"",P29>0),Q29/P29,0) -> 83446.809 | AC29: =IF(O29>0,L29/O29,0) -> 46.45 | AD29: =IF(X29="是",COUNTIFS($X$2:$X$5000,"是",$Z$2:$Z$5000,"<"&Z29)/COUNTIF($X$2:$X$5000,"是")*100,"") | AE29: =IF(X29="是",COUNTIFS($X$2:$X$5000,"是",$AA$2:$AA$5000,"<"&AA29)/COUNTIF($X$2:$X$5000,"是")*100,"") | AF29: =IF(X29="是",COUNTIFS($X$2:$X$5000,"是",$AC$2:$AC$5000,"<"&AC29)/COUNTIF($X$2:$X$5000,"是")*100,"") | AG29: =IF(X29="是",ROUND(AD29*0.3+AE29*0.55+AF29*0.15,2),"") | AH29: =IF(X29="是",COUNTIFS($X$2:$X$5000,"是",$AG$2:$AG$5000,">"&AG29)+1,"") | AI29: =IF(X29<>"是","非参评",IF(AND(AH29<=COUNTIF($X$2:$X$5000,"是")*0.2,AA29>MEDIAN(IF($X$2:$X$5000="是",$AA$2:$AA$5000))),"S",IF(AH29<=COUNTIF($X$2:$X$5000,"是")*0.5,"A",IF(AH29<=COUNTIF($X$2:$X$5000,"是")*0.8,"B","C")))) -> 非参评 | AJ29: =IF(G29="","无数据",IF(G29<30,"MOB1-",IF(G29<90,"MOB1-3",IF(G29<180,"MOB3-6",IF(G29<365,"MOB6-12","MOB12+"))))) -> MOB12+
A30: 首贷 | B30: 管户金条-汇讯职场 | C30: 737825 | D30: 赵武 | E30: 2023-05-30 14:39:58 | F30: 2023-05-30 14:39:58 | G30: 1048 | H30: 1048 | I30: 2026-04-11 18:11:48 | J30: 3529 | K30: 4368 | L30: 929 | M30: 156296 | N30: 108385 | O30: 20 | P30: 47 | Q30: 3922000 | R30: 3 | S30: 3 | T30: 87400 | U30: 4009400 | V30: =IF(OR(I30="",说明首页!$C$3-INT(I30)>7),"是","否") -> 否 | W30: =IF(OR(O30="",O30<22),"是","否") -> 是 | X30: =IF(AND(V30="否",W30="否"),"是","否") -> 否 | Y30: =IF(OR(I30="",说明首页!$C$3-INT(I30)>=3),"是","否") -> 否 | Z30: =IF(L30>0,N30/L30,0) -> 116.66846 | AA30: =IF(J30>0,P30/J30*100,0) -> 1.331822 | AB30: =IF(AND(P30<>"",P30>0),Q30/P30,0) -> 83446.809 | AC30: =IF(O30>0,L30/O30,0) -> 46.45 | AD30: =IF(X30="是",COUNTIFS($X$2:$X$5000,"是",$Z$2:$Z$5000,"<"&Z30)/COUNTIF($X$2:$X$5000,"是")*100,"") | AE30: =IF(X30="是",COUNTIFS($X$2:$X$5000,"是",$AA$2:$AA$5000,"<"&AA30)/COUNTIF($X$2:$X$5000,"是")*100,"") | AF30: =IF(X30="是",COUNTIFS($X$2:$X$5000,"是",$AC$2:$AC$5000,"<"&AC30)/COUNTIF($X$2:$X$5000,"是")*100,"") | AG30: =IF(X30="是",ROUND(AD30*0.3+AE30*0.55+AF30*0.15,2),"") | AH30: =IF(X30="是",COUNTIFS($X$2:$X$5000,"是",$AG$2:$AG$5000,">"&AG30)+1,"") | AI30: =IF(X30<>"是","非参评",IF(AND(AH30<=COUNTIF($X$2:$X$5000,"是")*0.2,AA30>MEDIAN(IF($X$2:$X$5000="是",$AA$2:$AA$5000))),"S",IF(AH30<=COUNTIF($X$2:$X$5000,"是")*0.5,"A",IF(AH30<=COUNTIF($X$2:$X$5000,"是")*0.8,"B","C")))) -> 非参评 | AJ30: =IF(G30="","无数据",IF(G30<30,"MOB1-",IF(G30<90,"MOB1-3",IF(G30<180,"MOB3-6",IF(G30<365,"MOB6-12","MOB12+"))))) -> MOB12+
A31: 首贷 | B31: 管户金条-毛毛虫职场 | C31: 802049 | D31: 程明佳 | E31: 2026-01-22 17:24:06 | F31: 2026-01-22 17:24:06 | G31: 80 | H31: 80 | I31: 2026-03-29 14:56:38 | J31: 603 | K31: 697 | L31: 283 | M31: 27948 | N31: 22440 | O31: 9 | P31: 4 | Q31: 6500 | R31: 1 | S31: 1 | T31: 600 | U31: 7100 | V31: =IF(OR(I31="",说明首页!$C$3-INT(I31)>7),"是","否") -> 是 | W31: =IF(OR(O31="",O31<22),"是","否") -> 是 | X31: =IF(AND(V31="否",W31="否"),"是","否") -> 否 | Y31: =IF(OR(I31="",说明首页!$C$3-INT(I31)>=3),"是","否") -> 是 | Z31: =IF(L31>0,N31/L31,0) -> 79.293286 | AA31: =IF(J31>0,P31/J31*100,0) -> 0.66334992 | AB31: =IF(AND(P31<>"",P31>0),Q31/P31,0) -> 1625 | AC31: =IF(O31>0,L31/O31,0) -> 31.444444 | AD31: =IF(X31="是",COUNTIFS($X$2:$X$5000,"是",$Z$2:$Z$5000,"<"&Z31)/COUNTIF($X$2:$X$5000,"是")*100,"") | AE31: =IF(X31="是",COUNTIFS($X$2:$X$5000,"是",$AA$2:$AA$5000,"<"&AA31)/COUNTIF($X$2:$X$5000,"是")*100,"") | AF31: =IF(X31="是",COUNTIFS($X$2:$X$5000,"是",$AC$2:$AC$5000,"<"&AC31)/COUNTIF($X$2:$X$5000,"是")*100,"") | AG31: =IF(X31="是",ROUND(AD31*0.3+AE31*0.55+AF31*0.15,2),"") | AH31: =IF(X31="是",COUNTIFS($X$2:$X$5000,"是",$AG$2:$AG$5000,">"&AG31)+1,"") | AI31: =IF(X31<>"是","非参评",IF(AND(AH31<=COUNTIF($X$2:$X$5000,"是")*0.2,AA31>MEDIAN(IF($X$2:$X$5000="是",$AA$2:$AA$5000))),"S",IF(AH31<=COUNTIF($X$2:$X$5000,"是")*0.5,"A",IF(AH31<=COUNTIF($X$2:$X$5000,"是")*0.8,"B","C")))) -> 非参评 | AJ31: =IF(G31="","无数据",IF(G31<30,"MOB1-",IF(G31<90,"MOB1-3",IF(G31<180,"MOB3-6",IF(G31<365,"MOB6-12","MOB12+"))))) -> MOB1-3
A32: 首贷 | B32: 管户金条-伽玛职场 | C32: 796710 | D32: 闫雅婷 | E32: 2025-10-30 10:20:17 | F32: 2025-10-30 10:20:17 | G32: 164 | H32: 164 | I32: 2026-04-11 17:58:18 | J32: 5192 | K32: 5543 | L32: 1995 | M32: 224044 | N32: 169456 | O32: 26 | P32: 43 | Q32: 1117100 | R32: 3 | S32: 4 | T32: 85100 | U32: 1202200 | V32: =IF(OR(I32="",说明首页!$C$3-INT(I32)>7),"是","否") -> 否 | W32: =IF(OR(O32="",O32<22),"是","否") -> 否 | X32: =IF(AND(V32="否",W32="否"),"是","否") -> 是 | Y32: =IF(OR(I32="",说明首页!$C$3-INT(I32)>=3),"是","否") -> 否 | Z32: =IF(L32>0,N32/L32,0) -> 84.940351 | AA32: =IF(J32>0,P32/J32*100,0) -> 0.82819723 | AB32: =IF(AND(P32<>"",P32>0),Q32/P32,0) -> 25979.07 | AC32: =IF(O32>0,L32/O32,0) -> 76.730769 | AD32: =IF(X32="是",COUNTIFS($X$2:$X$5000,"是",$Z$2:$Z$5000,"<"&Z32)/COUNTIF($X$2:$X$5000,"是")*100,"") -> 40.860215 | AE32: =IF(X32="是",COUNTIFS($X$2:$X$5000,"是",$AA$2:$AA$5000,"<"&AA32)/COUNTIF($X$2:$X$5000,"是")*100,"") -> 38.27957 | AF32: =IF(X32="是",COUNTIFS($X$2:$X$5000,"是",$AC$2:$AC$5000,"<"&AC32)/COUNTIF($X$2:$X$5000,"是")*100,"") -> 44.731183 | AG32: =IF(X32="是",ROUND(AD32*0.3+AE32*0.55+AF32*0.15,2),"") -> 40.02 | AH32: =IF(X32="是",COUNTIFS($X$2:$X$5000,"是",$AG$2:$AG$5000,">"&AG32)+1,"") -> 310 | AI32: =IF(X32<>"是","非参评",IF(AND(AH32<=COUNTIF($X$2:$X$5000,"是")*0.2,AA32>MEDIAN(IF($X$2:$X$5000="是",$AA$2:$AA$5000))),"S",IF(AH32<=COUNTIF($X$2:$X$5000,"是")*0.5,"A",IF(AH32<=COUNTIF($X$2:$X$5000,"是")*0.8,"B","C")))) -> B | AJ32: =IF(G32="","无数据",IF(G32<30,"MOB1-",IF(G32<90,"MOB1-3",IF(G32<180,"MOB3-6",IF(G32<365,"MOB6-12","MOB12+"))))) -> MOB3-6
A33: 首贷 | B33: 管户金条-伽玛职场 | C33: 807027 | D33: 孙治坤 | E33: 2026-04-09 10:09:20 | F33: 2026-04-09 10:09:20 | G33: 3 | H33: 3 | I33: 2026-04-10 18:20:27 | J33: 186 | K33: 205 | L33: 112 | M33: 14312 | N33: 12966 | O33: 2 | P33: 1 | Q33: 7800 | R33: 0 | S33: 0 | U33: 7800 | V33: =IF(OR(I33="",说明首页!$C$3-INT(I33)>7),"是","否") -> 否 | W33: =IF(OR(O33="",O33<22),"是","否") -> 是 | X33: =IF(AND(V33="否",W33="否"),"是","否") -> 否 | Y33: =IF(OR(I33="",说明首页!$C$3-INT(I33)>=3),"是","否") -> 否 | Z33: =IF(L33>0,N33/L33,0) -> 115.76786 | AA33: =IF(J33>0,P33/J33*100,0) -> 0.53763441 | AB33: =IF(AND(P33<>"",P33>0),Q33/P33,0) -> 7800 | AC33: =IF(O33>0,L33/O33,0) -> 56 | AD33: =IF(X33="是",COUNTIFS($X$2:$X$5000,"是",$Z$2:$Z$5000,"<"&Z33)/COUNTIF($X$2:$X$5000,"是")*100,"") | AE33: =IF(X33="是",COUNTIFS($X$2:$X$5000,"是",$AA$2:$AA$5000,"<"&AA33)/COUNTIF($X$2:$X$5000,"是")*100,"") | AF33: =IF(X33="是",COUNTIFS($X$2:$X$5000,"是",$AC$2:$AC$5000,"<"&AC33)/COUNTIF($X$2:$X$5000,"是")*100,"") | AG33: =IF(X33="是",ROUND(AD33*0.3+AE33*0.55+AF33*0.15,2),"") | AH33: =IF(X33="是",COUNTIFS($X$2:$X$5000,"是",$AG$2:$AG$5000,">"&AG33)+1,"") | AI33: =IF(X33<>"是","非参评",IF(AND(AH33<=COUNTIF($X$2:$X$5000,"是")*0.2,AA33>MEDIAN(IF($X$2:$X$5000="是",$AA$2:$AA$5000))),"S",IF(AH33<=COUNTIF($X$2:$X$5000,"是")*0.5,"A",IF(AH33<=COUNTIF($X$2:$X$5000,"是")*0.8,"B","C")))) -> 非参评 | AJ33: =IF(G33="","无数据",IF(G33<30,"MOB1-",IF(G33<90,"MOB1-3",IF(G33<180,"MOB3-6",IF(G33<365,"MOB6-12","MOB12+"))))) -> MOB1-
A34: 首贷 | B34: 管户金条-博岳石家庄职场 | C34: 649680 | D34: 郭芳贤 | E34: 2021-04-22 10:15:19 | F34: 2021-04-22 10:15:19 | G34: 1816 | H34: 1816 | I34: 2026-03-26 16:33:36 | J34: 358 | K34: 395 | L34: 158 | M34: 18854 | N34: 15253 | O34: 8 | V34: =IF(OR(I34="",说明首页!$C$3-INT(I34)>7),"是","否") -> 是 | W34: =IF(OR(O34="",O34<22),"是","否") -> 是 | X34: =IF(AND(V34="否",W34="否"),"是","否") -> 否 | Y34: =IF(OR(I34="",说明首页!$C$3-INT(I34)>=3),"是","否") -> 是 | Z34: =IF(L34>0,N34/L34,0) -> 96.537975 | AA34: =IF(J34>0,P34/J34*100,0) -> 0 | AB34: =IF(AND(P34<>"",P34>0),Q34/P34,0) -> 0 | AC34: =IF(O34>0,L34/O34,0) -> 19.75 | AD34: =IF(X34="是",COUNTIFS($X$2:$X$5000,"是",$Z$2:$Z$5000,"<"&Z34)/COUNTIF($X$2:$X$5000,"是")*100,"") | AE34: =IF(X34="是",COUNTIFS($X$2:$X$5000,"是",$AA$2:$AA$5000,"<"&AA34)/COUNTIF($X$2:$X$5000,"是")*100,"") | AF34: =IF(X34="是",COUNTIFS($X$2:$X$5000,"是",$AC$2:$AC$5000,"<"&AC34)/COUNTIF($X$2:$X$5000,"是")*100,"") | AG34: =IF(X34="是",ROUND(AD34*0.3+AE34*0.55+AF34*0.15,2),"") | AH34: =IF(X34="是",COUNTIFS($X$2:$X$5000,"是",$AG$2:$AG$5000,">"&AG34)+1,"") | AI34: =IF(X34<>"是","非参评",IF(AND(AH34<=COUNTIF($X$2:$X$5000,"是")*0.2,AA34>MEDIAN(IF($X$2:$X$5000="是",$AA$2:$AA$5000))),"S",IF(AH34<=COUNTIF($X$2:$X$5000,"是")*0.5,"A",IF(AH34<=COUNTIF($X$2:$X$5000,"是")*0.8,"B","C")))) -> 非参评 | AJ34: =IF(G34="","无数据",IF(G34<30,"MOB1-",IF(G34<90,"MOB1-3",IF(G34<180,"MOB3-6",IF(G34<365,"MOB6-12","MOB12+"))))) -> MOB12+
A35: 首贷 | B35: 管户金条-毛毛虫职场 | C35: 782855 | D35: 欧阳梦婷 | E35: 2025-04-24 15:09:21 | F35: 2025-04-24 15:09:21 | G35: 353 | H35: 353 | J35: 0 | K35: 0 | L35: 0 | V35: =IF(OR(I35="",说明首页!$C$3-INT(I35)>7),"是","否") -> #VALUE! | W35: =IF(OR(O35="",O35<22),"是","否") -> 是 | X35: =IF(AND(V35="否",W35="否"),"是","否") -> #VALUE! | Y35: =IF(OR(I35="",说明首页!$C$3-INT(I35)>=3),"是","否") -> #VALUE! | Z35: =IF(L35>0,N35/L35,0) -> 0 | AA35: =IF(J35>0,P35/J35*100,0) -> 0 | AB35: =IF(AND(P35<>"",P35>0),Q35/P35,0) -> 0 | AC35: =IF(O35>0,L35/O35,0) -> 0 | AD35: =IF(X35="是",COUNTIFS($X$2:$X$5000,"是",$Z$2:$Z$5000,"<"&Z35)/COUNTIF($X$2:$X$5000,"是")*100,"") -> #VALUE! | AE35: =IF(X35="是",COUNTIFS($X$2:$X$5000,"是",$AA$2:$AA$5000,"<"&AA35)/COUNTIF($X$2:$X$5000,"是")*100,"") -> #VALUE! | AF35: =IF(X35="是",COUNTIFS($X$2:$X$5000,"是",$AC$2:$AC$5000,"<"&AC35)/COUNTIF($X$2:$X$5000,"是")*100,"") -> #VALUE! | AG35: =IF(X35="是",ROUND(AD35*0.3+AE35*0.55+AF35*0.15,2),"") -> #VALUE! | AH35: =IF(X35="是",COUNTIFS($X$2:$X$5000,"是",$AG$2:$AG$5000,">"&AG35)+1,"") -> #VALUE! | AI35: =IF(X35<>"是","非参评",IF(AND(AH35<=COUNTIF($X$2:$X$5000,"是")*0.2,AA35>MEDIAN(IF($X$2:$X$5000="是",$AA$2:$AA$5000))),"S",IF(AH35<=COUNTIF($X$2:$X$5000,"是")*0.5,"A",IF(AH35<=COUNTIF($X$2:$X$5000,"是")*0.8,"B","C")))) -> #VALUE! | AJ35: =IF(G35="","无数据",IF(G35<30,"MOB1-",IF(G35<90,"MOB1-3",IF(G35<180,"MOB3-6",IF(G35<365,"MOB6-12","MOB12+"))))) -> MOB6-12
A36: 首贷 | B36: 管户金条-毅航合肥职场 | C36: 731086 | D36: 马媛媛 | E36: 2023-01-05 09:55:45 | F36: 2023-01-05 09:55:45 | G36: 1193 | H36: 1193 | I36: 2026-04-12 12:19:44 | J36: 7358 | K36: 8270 | L36: 2196 | M36: 367186 | N36: 284110 | O36: 29 | P36: 118 | Q36: 6289400 | R36: 3 | S36: 5 | T36: 42500 | U36: 6331900 | V36: =IF(OR(I36="",说明首页!$C$3-INT(I36)>7),"是","否") -> 否 | W36: =IF(OR(O36="",O36<22),"是","否") -> 否 | X36: =IF(AND(V36="否",W36="否"),"是","否") -> 是 | Y36: =IF(OR(I36="",说明首页!$C$3-INT(I36)>=3),"是","否") -> 否 | Z36: =IF(L36>0,N36/L36,0) -> 129.37614 | AA36: =IF(J36>0,P36/J36*100,0) -> 1.6036967 | AB36: =IF(AND(P36<>"",P36>0),Q36/P36,0) -> 53300 | AC36: =IF(O36>0,L36/O36,0) -> 75.724138 | AD36: =IF(X36="是",COUNTIFS($X$2:$X$5000,"是",$Z$2:$Z$5000,"<"&Z36)/COUNTIF($X$2:$X$5000,"是")*100,"") -> 98.494624 | AE36: =IF(X36="是",COUNTIFS($X$2:$X$5000,"是",$AA$2:$AA$5000,"<"&AA36)/COUNTIF($X$2:$X$5000,"是")*100,"") -> 94.408602 | AF36: =IF(X36="是",COUNTIFS($X$2:$X$5000,"是",$AC$2:$AC$5000,"<"&AC36)/COUNTIF($X$2:$X$5000,"是")*100,"") -> 41.505376 | AG36: =IF(X36="是",ROUND(AD36*0.3+AE36*0.55+AF36*0.15,2),"") -> 87.7 | AH36: =IF(X36="是",COUNTIFS($X$2:$X$5000,"是",$AG$2:$AG$5000,">"&AG36)+1,"") -> 6 | AI36: =IF(X36<>"是","非参评",IF(AND(AH36<=COUNTIF($X$2:$X$5000,"是")*0.2,AA36>MEDIAN(IF($X$2:$X$5000="是",$AA$2:$AA$5000))),"S",IF(AH36<=COUNTIF($X$2:$X$5000,"是")*0.5,"A",IF(AH36<=COUNTIF($X$2:$X$5000,"是")*0.8,"B","C")))) -> S | AJ36: =IF(G36="","无数据",IF(G36<30,"MOB1-",IF(G36<90,"MOB1-3",IF(G36<180,"MOB3-6",IF(G36<365,"MOB6-12","MOB12+"))))) -> MOB12+
A37: 首贷 | B37: 管户金条-毛毛虫职场 | C37: 787604 | D37: 张明舟 | E37: 2025-06-25 09:33:33 | F37: 2025-06-25 09:33:33 | G37: 291 | H37: 291 | I37: 2026-03-31 18:54:07 | J37: 2703 | K37: 2998 | L37: 1453 | M37: 145448 | N37: 125159 | O37: 15 | P37: 29 | Q37: 257700 | R37: 1 | S37: 1 | T37: 500 | U37: 258200 | V37: =IF(OR(I37="",说明首页!$C$3-INT(I37)>7),"是","否") -> 是 | W37: =IF(OR(O37="",O37<22),"是","否") -> 是 | X37: =IF(AND(V37="否",W37="否"),"是","否") -> 否 | Y37: =IF(OR(I37="",说明首页!$C$3-INT(I37)>=3),"是","否") -> 是 | Z37: =IF(L37>0,N37/L37,0) -> 86.138334 | AA37: =IF(J37>0,P37/J37*100,0) -> 1.072882 | AB37: =IF(AND(P37<>"",P37>0),Q37/P37,0) -> 8886.2069 | AC37: =IF(O37>0,L37/O37,0) -> 96.866667 | AD37: =IF(X37="是",COUNTIFS($X$2:$X$5000,"是",$Z$2:$Z$5000,"<"&Z37)/COUNTIF($X$2:$X$5000,"是")*100,"") | AE37: =IF(X37="是",COUNTIFS($X$2:$X$5000,"是",$AA$2:$AA$5000,"<"&AA37)/COUNTIF($X$2:$X$5000,"是")*100,"") | AF37: =IF(X37="是",COUNTIFS($X$2:$X$5000,"是",$AC$2:$AC$5000,"<"&AC37)/COUNTIF($X$2:$X$5000,"是")*100,"") | AG37: =IF(X37="是",ROUND(AD37*0.3+AE37*0.55+AF37*0.15,2),"") | AH37: =IF(X37="是",COUNTIFS($X$2:$X$5000,"是",$AG$2:$AG$5000,">"&AG37)+1,"") | AI37: =IF(X37<>"是","非参评",IF(AND(AH37<=COUNTIF($X$2:$X$5000,"是")*0.2,AA37>MEDIAN(IF($X$2:$X$5000="是",$AA$2:$AA$5000))),"S",IF(AH37<=COUNTIF($X$2:$X$5000,"是")*0.5,"A",IF(AH37<=COUNTIF($X$2:$X$5000,"是")*0.8,"B","C")))) -> 非参评 | AJ37: =IF(G37="","无数据",IF(G37<30,"MOB1-",IF(G37<90,"MOB1-3",IF(G37<180,"MOB3-6",IF(G37<365,"MOB6-12","MOB12+"))))) -> MOB6-12
A38: 首贷 | B38: 管户金条-毛毛虫职场 | C38: 802197 | D38: 谢春霞 | E38: 2026-01-30 09:57:29 | F38: 2026-01-30 09:57:29 | G38: 72 | H38: 72 | I38: 2026-04-11 16:27:33 | J38: 4928 | K38: 5760 | L38: 2283 | M38: 225895 | N38: 176789 | O38: 23 | P38: 41 | Q38: 1069600 | R38: 3 | S38: 3 | T38: 40500 | U38: 1110100 | V38: =IF(OR(I38="",说明首页!$C$3-INT(I38)>7),"是","否") -> 否 | W38: =IF(OR(O38="",O38<22),"是","否") -> 否 | X38: =IF(AND(V38="否",W38="否"),"是","否") -> 是 | Y38: =IF(OR(I38="",说明首页!$C$3-INT(I38)>=3),"是","否") -> 否 | Z38: =IF(L38>0,N38/L38,0) -> 77.437144 | AA38: =IF(J38>0,P38/J38*100,0) -> 0.83198052 | AB38: =IF(AND(P38<>"",P38>0),Q38/P38,0) -> 26087.805 | AC38: =IF(O38>0,L38/O38,0) -> 99.26087 | AD38: =IF(X38="是",COUNTIFS($X$2:$X$5000,"是",$Z$2:$Z$5000,"<"&Z38)/COUNTIF($X$2:$X$5000,"是")*100,"") -> 22.795699 | AE38: =IF(X38="是",COUNTIFS($X$2:$X$5000,"是",$AA$2:$AA$5000,"<"&AA38)/COUNTIF($X$2:$X$5000,"是")*100,"") -> 38.924731 | AF38: =IF(X38="是",COUNTIFS($X$2:$X$5000,"是",$AC$2:$AC$5000,"<"&AC38)/COUNTIF($X$2:$X$5000,"是")*100,"") -> 95.268817 | AG38: =IF(X38="是",ROUND(AD38*0.3+AE38*0.55+AF38*0.15,2),"") -> 42.54 | AH38: =IF(X38="是",COUNTIFS($X$2:$X$5000,"是",$AG$2:$AG$5000,">"&AG38)+1,"") -> 291 | AI38: =IF(X38<>"是","非参评",IF(AND(AH38<=COUNTIF($X$2:$X$5000,"是")*0.2,AA38>MEDIAN(IF($X$2:$X$5000="是",$AA$2:$AA$5000))),"S",IF(AH38<=COUNTIF($X$2:$X$5000,"是")*0.5,"A",IF(AH38<=COUNTIF($X$2:$X$5000,"是")*0.8,"B","C")))) -> B | AJ38: =IF(G38="","无数据",IF(G38<30,"MOB1-",IF(G38<90,"MOB1-3",IF(G38<180,"MOB3-6",IF(G38<365,"MOB6-12","MOB12+"))))) -> MOB1-3
A39: 首贷 | B39: 管户金条-广达陕西职场 | C39: 716962 | D39: 郝千一 | E39: 2024-05-10 10:19:14 | F39: 2024-05-10 10:19:14 | G39: 702 | H39: 702 | I39: 2026-04-07 11:39:11 | J39: 195 | K39: 197 | L39: 77 | M39: 7778 | N39: 6261 | O39: 2 | P39: 1 | Q39: 3000 | R39: 1 | S39: 1 | T39: 33000 | U39: 36000 | V39: =IF(OR(I39="",说明首页!$C$3-INT(I39)>7),"是","否") -> 否 | W39: =IF(OR(O39="",O39<22),"是","否") -> 是 | X39: =IF(AND(V39="否",W39="否"),"是","否") -> 否 | Y39: =IF(OR(I39="",说明首页!$C$3-INT(I39)>=3),"是","否") -> 是 | Z39: =IF(L39>0,N39/L39,0) -> 81.311688 | AA39: =IF(J39>0,P39/J39*100,0) -> 0.51282051 | AB39: =IF(AND(P39<>"",P39>0),Q39/P39,0) -> 3000 | AC39: =IF(O39>0,L39/O39,0) -> 38.5 | AD39: =IF(X39="是",COUNTIFS($X$2:$X$5000,"是",$Z$2:$Z$5000,"<"&Z39)/COUNTIF($X$2:$X$5000,"是")*100,"") | AE39: =IF(X39="是",COUNTIFS($X$2:$X$5000,"是",$AA$2:$AA$5000,"<"&AA39)/COUNTIF($X$2:$X$5000,"是")*100,"") | AF39: =IF(X39="是",COUNTIFS($X$2:$X$5000,"是",$AC$2:$AC$5000,"<"&AC39)/COUNTIF($X$2:$X$5000,"是")*100,"") | AG39: =IF(X39="是",ROUND(AD39*0.3+AE39*0.55+AF39*0.15,2),"") | AH39: =IF(X39="是",COUNTIFS($X$2:$X$5000,"是",$AG$2:$AG$5000,">"&AG39)+1,"") | AI39: =IF(X39<>"是","非参评",IF(AND(AH39<=COUNTIF($X$2:$X$5000,"是")*0.2,AA39>MEDIAN(IF($X$2:$X$5000="是",$AA$2:$AA$5000))),"S",IF(AH39<=COUNTIF($X$2:$X$5000,"是")*0.5,"A",IF(AH39<=COUNTIF($X$2:$X$5000,"是")*0.8,"B","C")))) -> 非参评 | AJ39: =IF(G39="","无数据",IF(G39<30,"MOB1-",IF(G39<90,"MOB1-3",IF(G39<180,"MOB3-6",IF(G39<365,"MOB6-12","MOB12+"))))) -> MOB12+
A40: 首贷 | B40: 管户金条-毅航合肥职场 | C40: 804259 | D40: 赵梦晴 | E40: 2026-03-17 10:46:19 | F40: 2026-03-17 10:46:19 | G40: 26 | H40: 26 | I40: 2026-04-12 12:00:55 | J40: 2941 | K40: 3106 | L40: 1228 | M40: 120266 | N40: 95339 | O40: 20 | P40: 12 | Q40: 120200 | R40: 1 | S40: 1 | T40: 90000 | U40: 210200 | V40: =IF(OR(I40="",说明首页!$C$3-INT(I40)>7),"是","否") -> 否 | W40: =IF(OR(O40="",O40<22),"是","否") -> 是 | X40: =IF(AND(V40="否",W40="否"),"是","否") -> 否 | Y40: =IF(OR(I40="",说明首页!$C$3-INT(I40)>=3),"是","否") -> 否 | Z40: =IF(L40>0,N40/L40,0) -> 77.637622 | AA40: =IF(J40>0,P40/J40*100,0) -> 0.40802448 | AB40: =IF(AND(P40<>"",P40>0),Q40/P40,0) -> 10016.667 | AC40: =IF(O40>0,L40/O40,0) -> 61.4 | AD40: =IF(X40="是",COUNTIFS($X$2:$X$5000,"是",$Z$2:$Z$5000,"<"&Z40)/COUNTIF($X$2:$X$5000,"是")*100,"") | AE40: =IF(X40="是",COUNTIFS($X$2:$X$5000,"是",$AA$2:$AA$5000,"<"&AA40)/COUNTIF($X$2:$X$5000,"是")*100,"") | AF40: =IF(X40="是",COUNTIFS($X$2:$X$5000,"是",$AC$2:$AC$5000,"<"&AC40)/COUNTIF($X$2:$X$5000,"是")*100,"") | AG40: =IF(X40="是",ROUND(AD40*0.3+AE40*0.55+AF40*0.15,2),"") | AH40: =IF(X40="是",COUNTIFS($X$2:$X$5000,"是",$AG$2:$AG$5000,">"&AG40)+1,"") | AI40: =IF(X40<>"是","非参评",IF(AND(AH40<=COUNTIF($X$2:$X$5000,"是")*0.2,AA40>MEDIAN(IF($X$2:$X$5000="是",$AA$2:$AA$5000))),"S",IF(AH40<=COUNTIF($X$2:$X$5000,"是")*0.5,"A",IF(AH40<=COUNTIF($X$2:$X$5000,"是")*0.8,"B","C")))) -> 非参评 | AJ40: =IF(G40="","无数据",IF(G40<30,"MOB1-",IF(G40<90,"MOB1-3",IF(G40<180,"MOB3-6",IF(G40<365,"MOB6-12","MOB12+"))))) -> MOB1-
...

Sheet 复贷评级明细
A1: 坐席类型 | B1: 职场名称 | C1: 坐席id | D1: 坐席名称 | E1: 210客户池首次外呼日期 | F1: 金条业务首次外呼日期 | G1: 210客户池在职天数 | H1: 金条业务线在职日期 | I1: 最近一次有效外呼时间 | J1: 接通用户数 | K1: 接通话单数 | L1: 有效接通数话单数 | M1: 近30天累计通时（秒） | N1: 近30天累计有效通时 | O1: 近30天外呼天数（通话时长>30分钟天数） | P1: 近30日累计转化首贷用户数 | Q1: 近30日累计转化首贷GMV | R1: 近30日累计转化复贷用户数 | S1: 近30日累计转化复贷订单数 | T1: 近30日累计转化复贷GMV | U1: 近30日累计转化GMV | V1: 超7天未上线 | W1: 外呼天数不足22天 | X1: 是否参评 | Y1: 连续3天未上线预警 | Z1: 个人ATT(秒) | AA1: GMV(万) | AB1: 件均金额(元) | AC1: 日均拨打量 | AD1: ATT得分 | AE1: GMV得分 | AF1: 件均得分 | AG1: 拨打量得分 | AH1: 综合得分 | AI1: 参评排名 | AJ1: 等级 | AK1: 司龄分段
