Workbook

Sheet 说明首页
B1: 金条坐席SABC评级 · 数据口径与评级标准
B3: 数据截止日期 | C3: 2026-04-19 | D3: ← 更新数据时同步修改此单元格
B5: 一、数据口径
B6: 数据范围 | C6: 近30个自然日，截止日期见C3参数单元格
B7: 数据来源 | C7: CRM系统导出，每日T-1更新
B8: 底表结构 | C8: A-W列(23列)为原始数据（含首贷T0/复贷T0/总GMV），X列起为辅助公式列
B9: 更新方式 | C9: 粘贴新A-W列数据覆盖明细表，所有公式、参评判定、得分与汇总表自动重算
B10: 首贷/复贷 | C10: 由坐席类型字段(A列)直接判定，首贷和复贷分池独立评级
B11: 有效通话阈值 | C11: 单通通话时长≥30秒计为有效接通
B12: 转化率分母 | C12: 首贷转化率 = 首贷用户数(P列) ÷ 接通用户数(J列)；后续"名单下发数"字段到位后，改用该字段替换J作为分母
B13: 日均有效通时 | C13: 日均有效通时 = 近30天累计有效通时(N列，秒) ÷ 外呼天数(O列，日通时>30分钟天数) ÷ 60；单位"分钟/天"，反映在岗日的实际工作投入
B14: 二、参评条件
B15: 条件① 活跃度 | C15: 最近一次有效外呼距截止日不超过7天
B16: 条件② 出勤量 | C16: 近30天有效外呼天数(通话时长>30分钟)≥22天
B17: 参评判定 | C17: 同时满足①②标记为"是"，参与评级；否则标记"非参评"，不参与排名
B19: 三、评级权重
B20: 维度 | C20: 首贷权重 | D20: 复贷权重 | E20: 类型
B21: 个人转化率 / GMV | C21: 45% | D21: 35% | E21: 结果指标（核心）
B22: T0 GMV（当日发放） | C22: 20% | D22: 15% | E22: 结果指标·抗躺单
B23: 件均金额 | C23: — | D23: 15% | E23: 结果指标
B24: 个人ATT | C24: 15% | D24: 10% | E24: 过程指标·沟通深度
B25: 日均有效通时(分钟) | C25: 20% | D25: 25% | E25: 过程指标·工作投入
B26: 结果指标:过程指标 | C26: 65 : 35 | D26: 65 : 35
B27: 四、分级标准（百分位排名制 + S底线门槛）
B28: 等级 | C28: 排名范围 | D28: 底线门槛 | E28: 管理动作
B29: S | C29: 综合得分Top 20% | D29: 且核心结果指标>参评池中位值（首贷=个人转化率 / 复贷=个人GMV） | E29: 名单优先+话术萃取；不达底线降A，名额不递补
B30: A | C30: Top 20%-50% | D30: 无 | E30: 正常管理+常规培训
B31: B | C31: Top 50%-80% | D31: 无 | E31: 组长定向辅导+通关考核
B32: C | C32: Bottom 20% | D32: 无 | E32: 暂停优质名单+14天改善期
B34: 五、流失与预警定义
B35: 指标 | C35: 定义 | D35: 分母 | E35: 用途
B36: 有效在岗 | C36: 近30天外呼天数≥20天 | D36: — | E36: 司龄统计分母
B37: 流失（确认） | C37: 最近有效外呼距截止日>7天 | D37: 有效在岗人数 | E37: 已确认流失
B38: 预警（早期） | C38: 最近有效外呼距截止日≥3天 | D38: 有效在岗人数 | E38: 早期预警
B39: 司龄分段 | C39: MOB1-(<30天) | MOB1-3(30-89) | MOB3-6(90-179) | MOB6-12(180-364) | MOB12+(≥365) | D39: 基于210客户池在职天数
B41: 六、汇总表口径
B42: SABC占比 | C42: 各职场该等级人数 ÷ 全大盘参评总人数（非职场内部占比）
B43: 均值指标 | C43: ATT / 转化率 / GMV / 件均 / T0 GMV / 日均有效通时 均仅对参评坐席求均值
B44: 得分计算 | C44: 百分位排名仅在参评人中做排名，非参评不进入排名池
B45: 职场范围 | C45: 剔除赛维斯机器人、零犀伽玛机器人（纯机器人职场）
...

Sheet 首贷统计总览
A1: 首贷坐席SABC分级统计
A2: S=Top20%+底线 | 占比=该职场÷大盘总参评人数
A4: 职场 | B4: S级 | C4: A级 | D4: B级 | E4: C级 | F4: 参评人数 | G4: S占比 | H4: A占比 | I4: B占比 | J4: C占比 | K4: ATT均值(秒) | L4: 转化率均值% | M4: 首贷件均(元) | N4: 日均通时(分钟) | O4: 总人数 | P4: 超7天未上线 | Q4: 外呼天数不足22天
A5: 人和职场 | B5: =COUNTIFS(首贷评级明细!$B:$B,"*"&A5&"*",首贷评级明细!$AM:$AM,"S") -> 4 | C5: =COUNTIFS(首贷评级明细!$B:$B,"*"&A5&"*",首贷评级明细!$AM:$AM,"A") -> 4 | D5: =COUNTIFS(首贷评级明细!$B:$B,"*"&A5&"*",首贷评级明细!$AM:$AM,"B") -> 4 | E5: =COUNTIFS(首贷评级明细!$B:$B,"*"&A5&"*",首贷评级明细!$AM:$AM,"C") -> 0 | F5: =SUM(B5:E5) -> 12 | G5: =IF($F$17>0,B5/$F$17,0) -> 0.0075329567 | H5: =IF($F$17>0,C5/$F$17,0) -> 0.0075329567 | I5: =IF($F$17>0,D5/$F$17,0) -> 0.0075329567 | J5: =IF($F$17>0,E5/$F$17,0) -> 0 | K5: =IFERROR(AVERAGEIFS(首贷评级明细!$AB:$AB,首贷评级明细!$B:$B,"*"&A5&"*",首贷评级明细!$Z:$Z,"是"),0) -> 92.011108 | L5: =IFERROR(AVERAGEIFS(首贷评级明细!$AC:$AC,首贷评级明细!$B:$B,"*"&A5&"*",首贷评级明细!$Z:$Z,"是"),0) -> 1.1881661 | M5: =IFERROR(AVERAGEIFS(首贷评级明细!$AD:$AD,首贷评级明细!$B:$B,"*"&A5&"*",首贷评级明细!$Z:$Z,"是"),0) -> 34922.906 | N5: =IFERROR(AVERAGEIFS(首贷评级明细!$AF:$AF,首贷评级明细!$B:$B,"*"&A5&"*",首贷评级明细!$Z:$Z,"是"),0) -> 107.9788 | O5: =COUNTIF(首贷评级明细!$B:$B,"*"&A5&"*") -> 20 | P5: =COUNTIFS(首贷评级明细!$B:$B,"*"&A5&"*",首贷评级明细!$X:$X,"是") -> 0 | Q5: =COUNTIFS(首贷评级明细!$B:$B,"*"&A5&"*",首贷评级明细!$Y:$Y,"是") -> 8
A6: 伽玛职场 | B6: =COUNTIFS(首贷评级明细!$B:$B,"*"&A6&"*",首贷评级明细!$AM:$AM,"S") -> 5 | C6: =COUNTIFS(首贷评级明细!$B:$B,"*"&A6&"*",首贷评级明细!$AM:$AM,"A") -> 13 | D6: =COUNTIFS(首贷评级明细!$B:$B,"*"&A6&"*",首贷评级明细!$AM:$AM,"B") -> 16 | E6: =COUNTIFS(首贷评级明细!$B:$B,"*"&A6&"*",首贷评级明细!$AM:$AM,"C") -> 22 | F6: =SUM(B6:E6) -> 56 | G6: =IF($F$17>0,B6/$F$17,0) -> 0.0094161959 | H6: =IF($F$17>0,C6/$F$17,0) -> 0.024482109 | I6: =IF($F$17>0,D6/$F$17,0) -> 0.030131827 | J6: =IF($F$17>0,E6/$F$17,0) -> 0.041431262 | K6: =IFERROR(AVERAGEIFS(首贷评级明细!$AB:$AB,首贷评级明细!$B:$B,"*"&A6&"*",首贷评级明细!$Z:$Z,"是"),0) -> 86.097238 | L6: =IFERROR(AVERAGEIFS(首贷评级明细!$AC:$AC,首贷评级明细!$B:$B,"*"&A6&"*",首贷评级明细!$Z:$Z,"是"),0) -> 0.85301926 | M6: =IFERROR(AVERAGEIFS(首贷评级明细!$AD:$AD,首贷评级明细!$B:$B,"*"&A6&"*",首贷评级明细!$Z:$Z,"是"),0) -> 33611.354 | N6: =IFERROR(AVERAGEIFS(首贷评级明细!$AF:$AF,首贷评级明细!$B:$B,"*"&A6&"*",首贷评级明细!$Z:$Z,"是"),0) -> 109.99915 | O6: =COUNTIF(首贷评级明细!$B:$B,"*"&A6&"*") -> 120 | P6: =COUNTIFS(首贷评级明细!$B:$B,"*"&A6&"*",首贷评级明细!$X:$X,"是") -> 1 | Q6: =COUNTIFS(首贷评级明细!$B:$B,"*"&A6&"*",首贷评级明细!$Y:$Y,"是") -> 64
A7: 华啸职场 | B7: =COUNTIFS(首贷评级明细!$B:$B,"*"&A7&"*",首贷评级明细!$AM:$AM,"S") -> 0 | C7: =COUNTIFS(首贷评级明细!$B:$B,"*"&A7&"*",首贷评级明细!$AM:$AM,"A") -> 0 | D7: =COUNTIFS(首贷评级明细!$B:$B,"*"&A7&"*",首贷评级明细!$AM:$AM,"B") -> 0 | E7: =COUNTIFS(首贷评级明细!$B:$B,"*"&A7&"*",首贷评级明细!$AM:$AM,"C") -> 0 | F7: =SUM(B7:E7) -> 0 | G7: =IF($F$17>0,B7/$F$17,0) -> 0 | H7: =IF($F$17>0,C7/$F$17,0) -> 0 | I7: =IF($F$17>0,D7/$F$17,0) -> 0 | J7: =IF($F$17>0,E7/$F$17,0) -> 0 | K7: =IFERROR(AVERAGEIFS(首贷评级明细!$AB:$AB,首贷评级明细!$B:$B,"*"&A7&"*",首贷评级明细!$Z:$Z,"是"),0) -> 0 | L7: =IFERROR(AVERAGEIFS(首贷评级明细!$AC:$AC,首贷评级明细!$B:$B,"*"&A7&"*",首贷评级明细!$Z:$Z,"是"),0) -> 0 | M7: =IFERROR(AVERAGEIFS(首贷评级明细!$AD:$AD,首贷评级明细!$B:$B,"*"&A7&"*",首贷评级明细!$Z:$Z,"是"),0) -> 0 | N7: =IFERROR(AVERAGEIFS(首贷评级明细!$AF:$AF,首贷评级明细!$B:$B,"*"&A7&"*",首贷评级明细!$Z:$Z,"是"),0) -> 0 | O7: =COUNTIF(首贷评级明细!$B:$B,"*"&A7&"*") -> 53 | P7: =COUNTIFS(首贷评级明细!$B:$B,"*"&A7&"*",首贷评级明细!$X:$X,"是") -> 4 | Q7: =COUNTIFS(首贷评级明细!$B:$B,"*"&A7&"*",首贷评级明细!$Y:$Y,"是") -> 53
A8: 博岳石家庄职场 | B8: =COUNTIFS(首贷评级明细!$B:$B,"*"&A8&"*",首贷评级明细!$AM:$AM,"S") -> 10 | C8: =COUNTIFS(首贷评级明细!$B:$B,"*"&A8&"*",首贷评级明细!$AM:$AM,"A") -> 8 | D8: =COUNTIFS(首贷评级明细!$B:$B,"*"&A8&"*",首贷评级明细!$AM:$AM,"B") -> 12 | E8: =COUNTIFS(首贷评级明细!$B:$B,"*"&A8&"*",首贷评级明细!$AM:$AM,"C") -> 6 | F8: =SUM(B8:E8) -> 36 | G8: =IF($F$17>0,B8/$F$17,0) -> 0.018832392 | H8: =IF($F$17>0,C8/$F$17,0) -> 0.015065913 | I8: =IF($F$17>0,D8/$F$17,0) -> 0.02259887 | J8: =IF($F$17>0,E8/$F$17,0) -> 0.011299435 | K8: =IFERROR(AVERAGEIFS(首贷评级明细!$AB:$AB,首贷评级明细!$B:$B,"*"&A8&"*",首贷评级明细!$Z:$Z,"是"),0) -> 98.473678 | L8: =IFERROR(AVERAGEIFS(首贷评级明细!$AC:$AC,首贷评级明细!$B:$B,"*"&A8&"*",首贷评级明细!$Z:$Z,"是"),0) -> 1.1298539 | M8: =IFERROR(AVERAGEIFS(首贷评级明细!$AD:$AD,首贷评级明细!$B:$B,"*"&A8&"*",首贷评级明细!$Z:$Z,"是"),0) -> 43624.601 | N8: =IFERROR(AVERAGEIFS(首贷评级明细!$AF:$AF,首贷评级明细!$B:$B,"*"&A8&"*",首贷评级明细!$Z:$Z,"是"),0) -> 107.33321 | O8: =COUNTIF(首贷评级明细!$B:$B,"*"&A8&"*") -> 58 | P8: =COUNTIFS(首贷评级明细!$B:$B,"*"&A8&"*",首贷评级明细!$X:$X,"是") -> 3 | Q8: =COUNTIFS(首贷评级明细!$B:$B,"*"&A8&"*",首贷评级明细!$Y:$Y,"是") -> 22
A9: 宿迁兆科职场 | B9: =COUNTIFS(首贷评级明细!$B:$B,"*"&A9&"*",首贷评级明细!$AM:$AM,"S") -> 1 | C9: =COUNTIFS(首贷评级明细!$B:$B,"*"&A9&"*",首贷评级明细!$AM:$AM,"A") -> 3 | D9: =COUNTIFS(首贷评级明细!$B:$B,"*"&A9&"*",首贷评级明细!$AM:$AM,"B") -> 2 | E9: =COUNTIFS(首贷评级明细!$B:$B,"*"&A9&"*",首贷评级明细!$AM:$AM,"C") -> 1 | F9: =SUM(B9:E9) -> 7 | G9: =IF($F$17>0,B9/$F$17,0) -> 0.0018832392 | H9: =IF($F$17>0,C9/$F$17,0) -> 0.0056497175 | I9: =IF($F$17>0,D9/$F$17,0) -> 0.0037664783 | J9: =IF($F$17>0,E9/$F$17,0) -> 0.0018832392 | K9: =IFERROR(AVERAGEIFS(首贷评级明细!$AB:$AB,首贷评级明细!$B:$B,"*"&A9&"*",首贷评级明细!$Z:$Z,"是"),0) -> 93.040823 | L9: =IFERROR(AVERAGEIFS(首贷评级明细!$AC:$AC,首贷评级明细!$B:$B,"*"&A9&"*",首贷评级明细!$Z:$Z,"是"),0) -> 0.89309901 | M9: =IFERROR(AVERAGEIFS(首贷评级明细!$AD:$AD,首贷评级明细!$B:$B,"*"&A9&"*",首贷评级明细!$Z:$Z,"是"),0) -> 17444.374 | N9: =IFERROR(AVERAGEIFS(首贷评级明细!$AF:$AF,首贷评级明细!$B:$B,"*"&A9&"*",首贷评级明细!$Z:$Z,"是"),0) -> 137.96091 | O9: =COUNTIF(首贷评级明细!$B:$B,"*"&A9&"*") -> 11 | P9: =COUNTIFS(首贷评级明细!$B:$B,"*"&A9&"*",首贷评级明细!$X:$X,"是") -> 0 | Q9: =COUNTIFS(首贷评级明细!$B:$B,"*"&A9&"*",首贷评级明细!$Y:$Y,"是") -> 4
A10: 岐力职场 | B10: =COUNTIFS(首贷评级明细!$B:$B,"*"&A10&"*",首贷评级明细!$AM:$AM,"S") -> 0 | C10: =COUNTIFS(首贷评级明细!$B:$B,"*"&A10&"*",首贷评级明细!$AM:$AM,"A") -> 1 | D10: =COUNTIFS(首贷评级明细!$B:$B,"*"&A10&"*",首贷评级明细!$AM:$AM,"B") -> 1 | E10: =COUNTIFS(首贷评级明细!$B:$B,"*"&A10&"*",首贷评级明细!$AM:$AM,"C") -> 0 | F10: =SUM(B10:E10) -> 2 | G10: =IF($F$17>0,B10/$F$17,0) -> 0 | H10: =IF($F$17>0,C10/$F$17,0) -> 0.0018832392 | I10: =IF($F$17>0,D10/$F$17,0) -> 0.0018832392 | J10: =IF($F$17>0,E10/$F$17,0) -> 0 | K10: =IFERROR(AVERAGEIFS(首贷评级明细!$AB:$AB,首贷评级明细!$B:$B,"*"&A10&"*",首贷评级明细!$Z:$Z,"是"),0) -> 107.66031 | L10: =IFERROR(AVERAGEIFS(首贷评级明细!$AC:$AC,首贷评级明细!$B:$B,"*"&A10&"*",首贷评级明细!$Z:$Z,"是"),0) -> 1.3783947 | M10: =IFERROR(AVERAGEIFS(首贷评级明细!$AD:$AD,首贷评级明细!$B:$B,"*"&A10&"*",首贷评级明细!$Z:$Z,"是"),0) -> 24321.849 | N10: =IFERROR(AVERAGEIFS(首贷评级明细!$AF:$AF,首贷评级明细!$B:$B,"*"&A10&"*",首贷评级明细!$Z:$Z,"是"),0) -> 74.60947 | O10: =COUNTIF(首贷评级明细!$B:$B,"*"&A10&"*") -> 49 | P10: =COUNTIFS(首贷评级明细!$B:$B,"*"&A10&"*",首贷评级明细!$X:$X,"是") -> 14 | Q10: =COUNTIFS(首贷评级明细!$B:$B,"*"&A10&"*",首贷评级明细!$Y:$Y,"是") -> 47
A11: 广达陕西职场 | B11: =COUNTIFS(首贷评级明细!$B:$B,"*"&A11&"*",首贷评级明细!$AM:$AM,"S") -> 3 | C11: =COUNTIFS(首贷评级明细!$B:$B,"*"&A11&"*",首贷评级明细!$AM:$AM,"A") -> 8 | D11: =COUNTIFS(首贷评级明细!$B:$B,"*"&A11&"*",首贷评级明细!$AM:$AM,"B") -> 8 | E11: =COUNTIFS(首贷评级明细!$B:$B,"*"&A11&"*",首贷评级明细!$AM:$AM,"C") -> 2 | F11: =SUM(B11:E11) -> 21 | G11: =IF($F$17>0,B11/$F$17,0) -> 0.0056497175 | H11: =IF($F$17>0,C11/$F$17,0) -> 0.015065913 | I11: =IF($F$17>0,D11/$F$17,0) -> 0.015065913 | J11: =IF($F$17>0,E11/$F$17,0) -> 0.0037664783 | K11: =IFERROR(AVERAGEIFS(首贷评级明细!$AB:$AB,首贷评级明细!$B:$B,"*"&A11&"*",首贷评级明细!$Z:$Z,"是"),0) -> 82.829123 | L11: =IFERROR(AVERAGEIFS(首贷评级明细!$AC:$AC,首贷评级明细!$B:$B,"*"&A11&"*",首贷评级明细!$Z:$Z,"是"),0) -> 1.1907332 | M11: =IFERROR(AVERAGEIFS(首贷评级明细!$AD:$AD,首贷评级明细!$B:$B,"*"&A11&"*",首贷评级明细!$Z:$Z,"是"),0) -> 41027.419 | N11: =IFERROR(AVERAGEIFS(首贷评级明细!$AF:$AF,首贷评级明细!$B:$B,"*"&A11&"*",首贷评级明细!$Z:$Z,"是"),0) -> 99.716907 | O11: =COUNTIF(首贷评级明细!$B:$B,"*"&A11&"*") -> 48 | P11: =COUNTIFS(首贷评级明细!$B:$B,"*"&A11&"*",首贷评级明细!$X:$X,"是") -> 5 | Q11: =COUNTIFS(首贷评级明细!$B:$B,"*"&A11&"*",首贷评级明细!$Y:$Y,"是") -> 27
A12: 毅航合肥职场 | B12: =COUNTIFS(首贷评级明细!$B:$B,"*"&A12&"*",首贷评级明细!$AM:$AM,"S") -> 45 | C12: =COUNTIFS(首贷评级明细!$B:$B,"*"&A12&"*",首贷评级明细!$AM:$AM,"A") -> 51 | D12: =COUNTIFS(首贷评级明细!$B:$B,"*"&A12&"*",首贷评级明细!$AM:$AM,"B") -> 39 | E12: =COUNTIFS(首贷评级明细!$B:$B,"*"&A12&"*",首贷评级明细!$AM:$AM,"C") -> 30 | F12: =SUM(B12:E12) -> 165 | G12: =IF($F$17>0,B12/$F$17,0) -> 0.084745763 | H12: =IF($F$17>0,C12/$F$17,0) -> 0.096045198 | I12: =IF($F$17>0,D12/$F$17,0) -> 0.073446328 | J12: =IF($F$17>0,E12/$F$17,0) -> 0.056497175 | K12: =IFERROR(AVERAGEIFS(首贷评级明细!$AB:$AB,首贷评级明细!$B:$B,"*"&A12&"*",首贷评级明细!$Z:$Z,"是"),0) -> 92.688929 | L12: =IFERROR(AVERAGEIFS(首贷评级明细!$AC:$AC,首贷评级明细!$B:$B,"*"&A12&"*",首贷评级明细!$Z:$Z,"是"),0) -> 0.92169769 | M12: =IFERROR(AVERAGEIFS(首贷评级明细!$AD:$AD,首贷评级明细!$B:$B,"*"&A12&"*",首贷评级明细!$Z:$Z,"是"),0) -> 39647.198 | N12: =IFERROR(AVERAGEIFS(首贷评级明细!$AF:$AF,首贷评级明细!$B:$B,"*"&A12&"*",首贷评级明细!$Z:$Z,"是"),0) -> 123.32706 | O12: =COUNTIF(首贷评级明细!$B:$B,"*"&A12&"*") -> 217 | P12: =COUNTIFS(首贷评级明细!$B:$B,"*"&A12&"*",首贷评级明细!$X:$X,"是") -> 0 | Q12: =COUNTIFS(首贷评级明细!$B:$B,"*"&A12&"*",首贷评级明细!$Y:$Y,"是") -> 52
A13: 毛毛虫职场 | B13: =COUNTIFS(首贷评级明细!$B:$B,"*"&A13&"*",首贷评级明细!$AM:$AM,"S") -> 23 | C13: =COUNTIFS(首贷评级明细!$B:$B,"*"&A13&"*",首贷评级明细!$AM:$AM,"A") -> 39 | D13: =COUNTIFS(首贷评级明细!$B:$B,"*"&A13&"*",首贷评级明细!$AM:$AM,"B") -> 50 | E13: =COUNTIFS(首贷评级明细!$B:$B,"*"&A13&"*",首贷评级明细!$AM:$AM,"C") -> 12 | F13: =SUM(B13:E13) -> 124 | G13: =IF($F$17>0,B13/$F$17,0) -> 0.043314501 | H13: =IF($F$17>0,C13/$F$17,0) -> 0.073446328 | I13: =IF($F$17>0,D13/$F$17,0) -> 0.094161959 | J13: =IF($F$17>0,E13/$F$17,0) -> 0.02259887 | K13: =IFERROR(AVERAGEIFS(首贷评级明细!$AB:$AB,首贷评级明细!$B:$B,"*"&A13&"*",首贷评级明细!$Z:$Z,"是"),0) -> 90.452186 | L13: =IFERROR(AVERAGEIFS(首贷评级明细!$AC:$AC,首贷评级明细!$B:$B,"*"&A13&"*",首贷评级明细!$Z:$Z,"是"),0) -> 0.93041466 | M13: =IFERROR(AVERAGEIFS(首贷评级明细!$AD:$AD,首贷评级明细!$B:$B,"*"&A13&"*",首贷评级明细!$Z:$Z,"是"),0) -> 44725.237 | N13: =IFERROR(AVERAGEIFS(首贷评级明细!$AF:$AF,首贷评级明细!$B:$B,"*"&A13&"*",首贷评级明细!$Z:$Z,"是"),0) -> 116.33271 | O13: =COUNTIF(首贷评级明细!$B:$B,"*"&A13&"*") -> 210 | P13: =COUNTIFS(首贷评级明细!$B:$B,"*"&A13&"*",首贷评级明细!$X:$X,"是") -> 0 | Q13: =COUNTIFS(首贷评级明细!$B:$B,"*"&A13&"*",首贷评级明细!$Y:$Y,"是") -> 86
A14: 汇讯职场 | B14: =COUNTIFS(首贷评级明细!$B:$B,"*"&A14&"*",首贷评级明细!$AM:$AM,"S") -> 9 | C14: =COUNTIFS(首贷评级明细!$B:$B,"*"&A14&"*",首贷评级明细!$AM:$AM,"A") -> 13 | D14: =COUNTIFS(首贷评级明细!$B:$B,"*"&A14&"*",首贷评级明细!$AM:$AM,"B") -> 10 | E14: =COUNTIFS(首贷评级明细!$B:$B,"*"&A14&"*",首贷评级明细!$AM:$AM,"C") -> 15 | F14: =SUM(B14:E14) -> 47 | G14: =IF($F$17>0,B14/$F$17,0) -> 0.016949153 | H14: =IF($F$17>0,C14/$F$17,0) -> 0.024482109 | I14: =IF($F$17>0,D14/$F$17,0) -> 0.018832392 | J14: =IF($F$17>0,E14/$F$17,0) -> 0.028248588 | K14: =IFERROR(AVERAGEIFS(首贷评级明细!$AB:$AB,首贷评级明细!$B:$B,"*"&A14&"*",首贷评级明细!$Z:$Z,"是"),0) -> 90.961793 | L14: =IFERROR(AVERAGEIFS(首贷评级明细!$AC:$AC,首贷评级明细!$B:$B,"*"&A14&"*",首贷评级明细!$Z:$Z,"是"),0) -> 0.85149944 | M14: =IFERROR(AVERAGEIFS(首贷评级明细!$AD:$AD,首贷评级明细!$B:$B,"*"&A14&"*",首贷评级明细!$Z:$Z,"是"),0) -> 37743.668 | N14: =IFERROR(AVERAGEIFS(首贷评级明细!$AF:$AF,首贷评级明细!$B:$B,"*"&A14&"*",首贷评级明细!$Z:$Z,"是"),0) -> 110.88426 | O14: =COUNTIF(首贷评级明细!$B:$B,"*"&A14&"*") -> 104 | P14: =COUNTIFS(首贷评级明细!$B:$B,"*"&A14&"*",首贷评级明细!$X:$X,"是") -> 0 | Q14: =COUNTIFS(首贷评级明细!$B:$B,"*"&A14&"*",首贷评级明细!$Y:$Y,"是") -> 57
A15: 翰锐曲靖职场 | B15: =COUNTIFS(首贷评级明细!$B:$B,"*"&A15&"*",首贷评级明细!$AM:$AM,"S") -> 1 | C15: =COUNTIFS(首贷评级明细!$B:$B,"*"&A15&"*",首贷评级明细!$AM:$AM,"A") -> 6 | D15: =COUNTIFS(首贷评级明细!$B:$B,"*"&A15&"*",首贷评级明细!$AM:$AM,"B") -> 4 | E15: =COUNTIFS(首贷评级明细!$B:$B,"*"&A15&"*",首贷评级明细!$AM:$AM,"C") -> 8 | F15: =SUM(B15:E15) -> 19 | G15: =IF($F$17>0,B15/$F$17,0) -> 0.0018832392 | H15: =IF($F$17>0,C15/$F$17,0) -> 0.011299435 | I15: =IF($F$17>0,D15/$F$17,0) -> 0.0075329567 | J15: =IF($F$17>0,E15/$F$17,0) -> 0.015065913 | K15: =IFERROR(AVERAGEIFS(首贷评级明细!$AB:$AB,首贷评级明细!$B:$B,"*"&A15&"*",首贷评级明细!$Z:$Z,"是"),0) -> 72.498962 | L15: =IFERROR(AVERAGEIFS(首贷评级明细!$AC:$AC,首贷评级明细!$B:$B,"*"&A15&"*",首贷评级明细!$Z:$Z,"是"),0) -> 1.0428059 | M15: =IFERROR(AVERAGEIFS(首贷评级明细!$AD:$AD,首贷评级明细!$B:$B,"*"&A15&"*",首贷评级明细!$Z:$Z,"是"),0) -> 34562.062 | N15: =IFERROR(AVERAGEIFS(首贷评级明细!$AF:$AF,首贷评级明细!$B:$B,"*"&A15&"*",首贷评级明细!$Z:$Z,"是"),0) -> 93.444745 | O15: =COUNTIF(首贷评级明细!$B:$B,"*"&A15&"*") -> 44 | P15: =COUNTIFS(首贷评级明细!$B:$B,"*"&A15&"*",首贷评级明细!$X:$X,"是") -> 1 | Q15: =COUNTIFS(首贷评级明细!$B:$B,"*"&A15&"*",首贷评级明细!$Y:$Y,"是") -> 25
A16: 赛维斯职场 | B16: =COUNTIFS(首贷评级明细!$B:$B,"*"&A16&"*",首贷评级明细!$AM:$AM,"S") -> 5 | C16: =COUNTIFS(首贷评级明细!$B:$B,"*"&A16&"*",首贷评级明细!$AM:$AM,"A") -> 13 | D16: =COUNTIFS(首贷评级明细!$B:$B,"*"&A16&"*",首贷评级明细!$AM:$AM,"B") -> 13 | E16: =COUNTIFS(首贷评级明细!$B:$B,"*"&A16&"*",首贷评级明细!$AM:$AM,"C") -> 11 | F16: =SUM(B16:E16) -> 42 | G16: =IF($F$17>0,B16/$F$17,0) -> 0.0094161959 | H16: =IF($F$17>0,C16/$F$17,0) -> 0.024482109 | I16: =IF($F$17>0,D16/$F$17,0) -> 0.024482109 | J16: =IF($F$17>0,E16/$F$17,0) -> 0.020715631 | K16: =IFERROR(AVERAGEIFS(首贷评级明细!$AB:$AB,首贷评级明细!$B:$B,"*"&A16&"*",首贷评级明细!$Z:$Z,"是"),0) -> 80.250615 | L16: =IFERROR(AVERAGEIFS(首贷评级明细!$AC:$AC,首贷评级明细!$B:$B,"*"&A16&"*",首贷评级明细!$Z:$Z,"是"),0) -> 1.0181981 | M16: =IFERROR(AVERAGEIFS(首贷评级明细!$AD:$AD,首贷评级明细!$B:$B,"*"&A16&"*",首贷评级明细!$Z:$Z,"是"),0) -> 43114.625 | N16: =IFERROR(AVERAGEIFS(首贷评级明细!$AF:$AF,首贷评级明细!$B:$B,"*"&A16&"*",首贷评级明细!$Z:$Z,"是"),0) -> 92.174759 | O16: =COUNTIF(首贷评级明细!$B:$B,"*"&A16&"*") -> 87 | P16: =COUNTIFS(首贷评级明细!$B:$B,"*"&A16&"*",首贷评级明细!$X:$X,"是") -> 0 | Q16: =COUNTIFS(首贷评级明细!$B:$B,"*"&A16&"*",首贷评级明细!$Y:$Y,"是") -> 45
A17: 整体 | B17: =SUM(B5:B16) -> 106 | C17: =SUM(C5:C16) -> 159 | D17: =SUM(D5:D16) -> 159 | E17: =SUM(E5:E16) -> 107 | F17: =SUM(F5:F16) -> 531 | G17: =IF(F17>0,B17/F17,0) -> 0.19962335 | H17: =IF(F17>0,C17/F17,0) -> 0.29943503 | I17: =IF(F17>0,D17/F17,0) -> 0.29943503 | J17: =IF(F17>0,E17/F17,0) -> 0.20150659 | K17: =IFERROR(AVERAGEIFS(首贷评级明细!$AB:$AB,首贷评级明细!$Z:$Z,"是"),0) -> 89.660271 | L17: =IFERROR(AVERAGEIFS(首贷评级明细!$AC:$AC,首贷评级明细!$Z:$Z,"是"),0) -> 0.95436033 | M17: =IFERROR(AVERAGEIFS(首贷评级明细!$AD:$AD,首贷评级明细!$Z:$Z,"是"),0) -> 39987.362 | N17: =IFERROR(AVERAGEIFS(首贷评级明细!$AF:$AF,首贷评级明细!$Z:$Z,"是"),0) -> 113.29805 | O17: =SUM(O5:O16) -> 1021 | P17: =SUM(P5:P16) -> 28 | Q17: =SUM(Q5:Q16) -> 490

Sheet 复贷统计总览
A1: 复贷坐席SABC分级统计
A2: S=Top20%+底线 | 占比=该职场÷大盘总参评人数
A4: 职场 | B4: S级 | C4: A级 | D4: B级 | E4: C级 | F4: 参评人数 | G4: S占比 | H4: A占比 | I4: B占比 | J4: C占比 | K4: ATT均值(秒) | L4: GMV均值(万) | M4: 件均均值(元) | N4: 日均通时(分钟) | O4: 总人数 | P4: 超7天未上线 | Q4: 外呼天数不足22天
A5: 人和职场 | B5: =COUNTIFS(复贷评级明细!$B:$B,"*"&A5&"*",复贷评级明细!$AN:$AN,"S") -> 1 | C5: =COUNTIFS(复贷评级明细!$B:$B,"*"&A5&"*",复贷评级明细!$AN:$AN,"A") -> 6 | D5: =COUNTIFS(复贷评级明细!$B:$B,"*"&A5&"*",复贷评级明细!$AN:$AN,"B") -> 6 | E5: =COUNTIFS(复贷评级明细!$B:$B,"*"&A5&"*",复贷评级明细!$AN:$AN,"C") -> 3 | F5: =SUM(B5:E5) -> 16 | G5: =IF($F$17>0,B5/$F$17,0) -> 0.0016863406 | H5: =IF($F$17>0,C5/$F$17,0) -> 0.010118044 | I5: =IF($F$17>0,D5/$F$17,0) -> 0.010118044 | J5: =IF($F$17>0,E5/$F$17,0) -> 0.0050590219 | K5: =IFERROR(AVERAGEIFS(复贷评级明细!$AB:$AB,复贷评级明细!$B:$B,"*"&A5&"*",复贷评级明细!$Z:$Z,"是"),0) -> 107.65211 | L5: =IFERROR(AVERAGEIFS(复贷评级明细!$AC:$AC,复贷评级明细!$B:$B,"*"&A5&"*",复贷评级明细!$Z:$Z,"是"),0) -> 796.47562 | M5: =IFERROR(AVERAGEIFS(复贷评级明细!$AD:$AD,复贷评级明细!$B:$B,"*"&A5&"*",复贷评级明细!$Z:$Z,"是"),0) -> 23453.386 | N5: =IFERROR(AVERAGEIFS(复贷评级明细!$AF:$AF,复贷评级明细!$B:$B,"*"&A5&"*",复贷评级明细!$Z:$Z,"是"),0) -> 125.07565 | O5: =COUNTIF(复贷评级明细!$B:$B,"*"&A5&"*") -> 32 | P5: =COUNTIFS(复贷评级明细!$B:$B,"*"&A5&"*",复贷评级明细!$X:$X,"是") -> 0 | Q5: =COUNTIFS(复贷评级明细!$B:$B,"*"&A5&"*",复贷评级明细!$Y:$Y,"是") -> 16
A6: 伽玛职场 | B6: =COUNTIFS(复贷评级明细!$B:$B,"*"&A6&"*",复贷评级明细!$AN:$AN,"S") -> 7 | C6: =COUNTIFS(复贷评级明细!$B:$B,"*"&A6&"*",复贷评级明细!$AN:$AN,"A") -> 33 | D6: =COUNTIFS(复贷评级明细!$B:$B,"*"&A6&"*",复贷评级明细!$AN:$AN,"B") -> 40 | E6: =COUNTIFS(复贷评级明细!$B:$B,"*"&A6&"*",复贷评级明细!$AN:$AN,"C") -> 13 | F6: =SUM(B6:E6) -> 93 | G6: =IF($F$17>0,B6/$F$17,0) -> 0.011804384 | H6: =IF($F$17>0,C6/$F$17,0) -> 0.055649241 | I6: =IF($F$17>0,D6/$F$17,0) -> 0.067453626 | J6: =IF($F$17>0,E6/$F$17,0) -> 0.021922428 | K6: =IFERROR(AVERAGEIFS(复贷评级明细!$AB:$AB,复贷评级明细!$B:$B,"*"&A6&"*",复贷评级明细!$Z:$Z,"是"),0) -> 92.945672 | L6: =IFERROR(AVERAGEIFS(复贷评级明细!$AC:$AC,复贷评级明细!$B:$B,"*"&A6&"*",复贷评级明细!$Z:$Z,"是"),0) -> 805.83688 | M6: =IFERROR(AVERAGEIFS(复贷评级明细!$AD:$AD,复贷评级明细!$B:$B,"*"&A6&"*",复贷评级明细!$Z:$Z,"是"),0) -> 23910.947 | N6: =IFERROR(AVERAGEIFS(复贷评级明细!$AF:$AF,复贷评级明细!$B:$B,"*"&A6&"*",复贷评级明细!$Z:$Z,"是"),0) -> 127.80216 | O6: =COUNTIF(复贷评级明细!$B:$B,"*"&A6&"*") -> 223 | P6: =COUNTIFS(复贷评级明细!$B:$B,"*"&A6&"*",复贷评级明细!$X:$X,"是") -> 1 | Q6: =COUNTIFS(复贷评级明细!$B:$B,"*"&A6&"*",复贷评级明细!$Y:$Y,"是") -> 130
A7: 华啸职场 | B7: =COUNTIFS(复贷评级明细!$B:$B,"*"&A7&"*",复贷评级明细!$AN:$AN,"S") -> 6 | C7: =COUNTIFS(复贷评级明细!$B:$B,"*"&A7&"*",复贷评级明细!$AN:$AN,"A") -> 10 | D7: =COUNTIFS(复贷评级明细!$B:$B,"*"&A7&"*",复贷评级明细!$AN:$AN,"B") -> 5 | E7: =COUNTIFS(复贷评级明细!$B:$B,"*"&A7&"*",复贷评级明细!$AN:$AN,"C") -> 0 | F7: =SUM(B7:E7) -> 21 | G7: =IF($F$17>0,B7/$F$17,0) -> 0.010118044 | H7: =IF($F$17>0,C7/$F$17,0) -> 0.016863406 | I7: =IF($F$17>0,D7/$F$17,0) -> 0.0084317032 | J7: =IF($F$17>0,E7/$F$17,0) -> 0 | K7: =IFERROR(AVERAGEIFS(复贷评级明细!$AB:$AB,复贷评级明细!$B:$B,"*"&A7&"*",复贷评级明细!$Z:$Z,"是"),0) -> 156.19284 | L7: =IFERROR(AVERAGEIFS(复贷评级明细!$AC:$AC,复贷评级明细!$B:$B,"*"&A7&"*",复贷评级明细!$Z:$Z,"是"),0) -> 848.78524 | M7: =IFERROR(AVERAGEIFS(复贷评级明细!$AD:$AD,复贷评级明细!$B:$B,"*"&A7&"*",复贷评级明细!$Z:$Z,"是"),0) -> 28721.232 | N7: =IFERROR(AVERAGEIFS(复贷评级明细!$AF:$AF,复贷评级明细!$B:$B,"*"&A7&"*",复贷评级明细!$Z:$Z,"是"),0) -> 140.59192 | O7: =COUNTIF(复贷评级明细!$B:$B,"*"&A7&"*") -> 54 | P7: =COUNTIFS(复贷评级明细!$B:$B,"*"&A7&"*",复贷评级明细!$X:$X,"是") -> 1 | Q7: =COUNTIFS(复贷评级明细!$B:$B,"*"&A7&"*",复贷评级明细!$Y:$Y,"是") -> 33
A8: 博岳石家庄职场 | B8: =COUNTIFS(复贷评级明细!$B:$B,"*"&A8&"*",复贷评级明细!$AN:$AN,"S") -> 9 | C8: =COUNTIFS(复贷评级明细!$B:$B,"*"&A8&"*",复贷评级明细!$AN:$AN,"A") -> 6 | D8: =COUNTIFS(复贷评级明细!$B:$B,"*"&A8&"*",复贷评级明细!$AN:$AN,"B") -> 11 | E8: =COUNTIFS(复贷评级明细!$B:$B,"*"&A8&"*",复贷评级明细!$AN:$AN,"C") -> 20 | F8: =SUM(B8:E8) -> 46 | G8: =IF($F$17>0,B8/$F$17,0) -> 0.015177066 | H8: =IF($F$17>0,C8/$F$17,0) -> 0.010118044 | I8: =IF($F$17>0,D8/$F$17,0) -> 0.018549747 | J8: =IF($F$17>0,E8/$F$17,0) -> 0.033726813 | K8: =IFERROR(AVERAGEIFS(复贷评级明细!$AB:$AB,复贷评级明细!$B:$B,"*"&A8&"*",复贷评级明细!$Z:$Z,"是"),0) -> 103.07 | L8: =IFERROR(AVERAGEIFS(复贷评级明细!$AC:$AC,复贷评级明细!$B:$B,"*"&A8&"*",复贷评级明细!$Z:$Z,"是"),0) -> 786.97783 | M8: =IFERROR(AVERAGEIFS(复贷评级明细!$AD:$AD,复贷评级明细!$B:$B,"*"&A8&"*",复贷评级明细!$Z:$Z,"是"),0) -> 21012.681 | N8: =IFERROR(AVERAGEIFS(复贷评级明细!$AF:$AF,复贷评级明细!$B:$B,"*"&A8&"*",复贷评级明细!$Z:$Z,"是"),0) -> 123.8028 | O8: =COUNTIF(复贷评级明细!$B:$B,"*"&A8&"*") -> 97 | P8: =COUNTIFS(复贷评级明细!$B:$B,"*"&A8&"*",复贷评级明细!$X:$X,"是") -> 1 | Q8: =COUNTIFS(复贷评级明细!$B:$B,"*"&A8&"*",复贷评级明细!$Y:$Y,"是") -> 51
A9: 宿迁兆科职场 | B9: =COUNTIFS(复贷评级明细!$B:$B,"*"&A9&"*",复贷评级明细!$AN:$AN,"S") -> 3 | C9: =COUNTIFS(复贷评级明细!$B:$B,"*"&A9&"*",复贷评级明细!$AN:$AN,"A") -> 3 | D9: =COUNTIFS(复贷评级明细!$B:$B,"*"&A9&"*",复贷评级明细!$AN:$AN,"B") -> 2 | E9: =COUNTIFS(复贷评级明细!$B:$B,"*"&A9&"*",复贷评级明细!$AN:$AN,"C") -> 0 | F9: =SUM(B9:E9) -> 8 | G9: =IF($F$17>0,B9/$F$17,0) -> 0.0050590219 | H9: =IF($F$17>0,C9/$F$17,0) -> 0.0050590219 | I9: =IF($F$17>0,D9/$F$17,0) -> 0.0033726813 | J9: =IF($F$17>0,E9/$F$17,0) -> 0 | K9: =IFERROR(AVERAGEIFS(复贷评级明细!$AB:$AB,复贷评级明细!$B:$B,"*"&A9&"*",复贷评级明细!$Z:$Z,"是"),0) -> 91.557512 | L9: =IFERROR(AVERAGEIFS(复贷评级明细!$AC:$AC,复贷评级明细!$B:$B,"*"&A9&"*",复贷评级明细!$Z:$Z,"是"),0) -> 1102.5163 | M9: =IFERROR(AVERAGEIFS(复贷评级明细!$AD:$AD,复贷评级明细!$B:$B,"*"&A9&"*",复贷评级明细!$Z:$Z,"是"),0) -> 26876.218 | N9: =IFERROR(AVERAGEIFS(复贷评级明细!$AF:$AF,复贷评级明细!$B:$B,"*"&A9&"*",复贷评级明细!$Z:$Z,"是"),0) -> 154.22636 | O9: =COUNTIF(复贷评级明细!$B:$B,"*"&A9&"*") -> 17 | P9: =COUNTIFS(复贷评级明细!$B:$B,"*"&A9&"*",复贷评级明细!$X:$X,"是") -> 0 | Q9: =COUNTIFS(复贷评级明细!$B:$B,"*"&A9&"*",复贷评级明细!$Y:$Y,"是") -> 9
A10: 岐力职场 | B10: =COUNTIFS(复贷评级明细!$B:$B,"*"&A10&"*",复贷评级明细!$AN:$AN,"S") -> 1 | C10: =COUNTIFS(复贷评级明细!$B:$B,"*"&A10&"*",复贷评级明细!$AN:$AN,"A") -> 11 | D10: =COUNTIFS(复贷评级明细!$B:$B,"*"&A10&"*",复贷评级明细!$AN:$AN,"B") -> 16 | E10: =COUNTIFS(复贷评级明细!$B:$B,"*"&A10&"*",复贷评级明细!$AN:$AN,"C") -> 18 | F10: =SUM(B10:E10) -> 46 | G10: =IF($F$17>0,B10/$F$17,0) -> 0.0016863406 | H10: =IF($F$17>0,C10/$F$17,0) -> 0.018549747 | I10: =IF($F$17>0,D10/$F$17,0) -> 0.02698145 | J10: =IF($F$17>0,E10/$F$17,0) -> 0.030354132 | K10: =IFERROR(AVERAGEIFS(复贷评级明细!$AB:$AB,复贷评级明细!$B:$B,"*"&A10&"*",复贷评级明细!$Z:$Z,"是"),0) -> 91.217098 | L10: =IFERROR(AVERAGEIFS(复贷评级明细!$AC:$AC,复贷评级明细!$B:$B,"*"&A10&"*",复贷评级明细!$Z:$Z,"是"),0) -> 655.16065 | M10: =IFERROR(AVERAGEIFS(复贷评级明细!$AD:$AD,复贷评级明细!$B:$B,"*"&A10&"*",复贷评级明细!$Z:$Z,"是"),0) -> 22504.932 | N10: =IFERROR(AVERAGEIFS(复贷评级明细!$AF:$AF,复贷评级明细!$B:$B,"*"&A10&"*",复贷评级明细!$Z:$Z,"是"),0) -> 119.40478 | O10: =COUNTIF(复贷评级明细!$B:$B,"*"&A10&"*") -> 118 | P10: =COUNTIFS(复贷评级明细!$B:$B,"*"&A10&"*",复贷评级明细!$X:$X,"是") -> 2 | Q10: =COUNTIFS(复贷评级明细!$B:$B,"*"&A10&"*",复贷评级明细!$Y:$Y,"是") -> 72
A11: 广达陕西职场 | B11: =COUNTIFS(复贷评级明细!$B:$B,"*"&A11&"*",复贷评级明细!$AN:$AN,"S") -> 0 | C11: =COUNTIFS(复贷评级明细!$B:$B,"*"&A11&"*",复贷评级明细!$AN:$AN,"A") -> 7 | D11: =COUNTIFS(复贷评级明细!$B:$B,"*"&A11&"*",复贷评级明细!$AN:$AN,"B") -> 11 | E11: =COUNTIFS(复贷评级明细!$B:$B,"*"&A11&"*",复贷评级明细!$AN:$AN,"C") -> 9 | F11: =SUM(B11:E11) -> 27 | G11: =IF($F$17>0,B11/$F$17,0) -> 0 | H11: =IF($F$17>0,C11/$F$17,0) -> 0.011804384 | I11: =IF($F$17>0,D11/$F$17,0) -> 0.018549747 | J11: =IF($F$17>0,E11/$F$17,0) -> 0.015177066 | K11: =IFERROR(AVERAGEIFS(复贷评级明细!$AB:$AB,复贷评级明细!$B:$B,"*"&A11&"*",复贷评级明细!$Z:$Z,"是"),0) -> 87.813889 | L11: =IFERROR(AVERAGEIFS(复贷评级明细!$AC:$AC,复贷评级明细!$B:$B,"*"&A11&"*",复贷评级明细!$Z:$Z,"是"),0) -> 649.14556 | M11: =IFERROR(AVERAGEIFS(复贷评级明细!$AD:$AD,复贷评级明细!$B:$B,"*"&A11&"*",复贷评级明细!$Z:$Z,"是"),0) -> 24540.28 | N11: =IFERROR(AVERAGEIFS(复贷评级明细!$AF:$AF,复贷评级明细!$B:$B,"*"&A11&"*",复贷评级明细!$Z:$Z,"是"),0) -> 118.33061 | O11: =COUNTIF(复贷评级明细!$B:$B,"*"&A11&"*") -> 81 | P11: =COUNTIFS(复贷评级明细!$B:$B,"*"&A11&"*",复贷评级明细!$X:$X,"是") -> 0 | Q11: =COUNTIFS(复贷评级明细!$B:$B,"*"&A11&"*",复贷评级明细!$Y:$Y,"是") -> 54
A12: 毅航合肥职场 | B12: =COUNTIFS(复贷评级明细!$B:$B,"*"&A12&"*",复贷评级明细!$AN:$AN,"S") -> 64 | C12: =COUNTIFS(复贷评级明细!$B:$B,"*"&A12&"*",复贷评级明细!$AN:$AN,"A") -> 51 | D12: =COUNTIFS(复贷评级明细!$B:$B,"*"&A12&"*",复贷评级明细!$AN:$AN,"B") -> 10 | E12: =COUNTIFS(复贷评级明细!$B:$B,"*"&A12&"*",复贷评级明细!$AN:$AN,"C") -> 3 | F12: =SUM(B12:E12) -> 128 | G12: =IF($F$17>0,B12/$F$17,0) -> 0.1079258 | H12: =IF($F$17>0,C12/$F$17,0) -> 0.086003373 | I12: =IF($F$17>0,D12/$F$17,0) -> 0.016863406 | J12: =IF($F$17>0,E12/$F$17,0) -> 0.0050590219 | K12: =IFERROR(AVERAGEIFS(复贷评级明细!$AB:$AB,复贷评级明细!$B:$B,"*"&A12&"*",复贷评级明细!$Z:$Z,"是"),0) -> 111.48424 | L12: =IFERROR(AVERAGEIFS(复贷评级明细!$AC:$AC,复贷评级明细!$B:$B,"*"&A12&"*",复贷评级明细!$Z:$Z,"是"),0) -> 1231.0566 | M12: =IFERROR(AVERAGEIFS(复贷评级明细!$AD:$AD,复贷评级明细!$B:$B,"*"&A12&"*",复贷评级明细!$Z:$Z,"是"),0) -> 28015.32 | N12: =IFERROR(AVERAGEIFS(复贷评级明细!$AF:$AF,复贷评级明细!$B:$B,"*"&A12&"*",复贷评级明细!$Z:$Z,"是"),0) -> 164.70455 | O12: =COUNTIF(复贷评级明细!$B:$B,"*"&A12&"*") -> 371 | P12: =COUNTIFS(复贷评级明细!$B:$B,"*"&A12&"*",复贷评级明细!$X:$X,"是") -> 0 | Q12: =COUNTIFS(复贷评级明细!$B:$B,"*"&A12&"*",复贷评级明细!$Y:$Y,"是") -> 243
A13: 毛毛虫职场 | B13: =COUNTIFS(复贷评级明细!$B:$B,"*"&A13&"*",复贷评级明细!$AN:$AN,"S") -> 17 | C13: =COUNTIFS(复贷评级明细!$B:$B,"*"&A13&"*",复贷评级明细!$AN:$AN,"A") -> 10 | D13: =COUNTIFS(复贷评级明细!$B:$B,"*"&A13&"*",复贷评级明细!$AN:$AN,"B") -> 18 | E13: =COUNTIFS(复贷评级明细!$B:$B,"*"&A13&"*",复贷评级明细!$AN:$AN,"C") -> 4 | F13: =SUM(B13:E13) -> 49 | G13: =IF($F$17>0,B13/$F$17,0) -> 0.028667791 | H13: =IF($F$17>0,C13/$F$17,0) -> 0.016863406 | I13: =IF($F$17>0,D13/$F$17,0) -> 0.030354132 | J13: =IF($F$17>0,E13/$F$17,0) -> 0.0067453626 | K13: =IFERROR(AVERAGEIFS(复贷评级明细!$AB:$AB,复贷评级明细!$B:$B,"*"&A13&"*",复贷评级明细!$Z:$Z,"是"),0) -> 86.307951 | L13: =IFERROR(AVERAGEIFS(复贷评级明细!$AC:$AC,复贷评级明细!$B:$B,"*"&A13&"*",复贷评级明细!$Z:$Z,"是"),0) -> 1018.1169 | M13: =IFERROR(AVERAGEIFS(复贷评级明细!$AD:$AD,复贷评级明细!$B:$B,"*"&A13&"*",复贷评级明细!$Z:$Z,"是"),0) -> 26175.932 | N13: =IFERROR(AVERAGEIFS(复贷评级明细!$AF:$AF,复贷评级明细!$B:$B,"*"&A13&"*",复贷评级明细!$Z:$Z,"是"),0) -> 147.72749 | O13: =COUNTIF(复贷评级明细!$B:$B,"*"&A13&"*") -> 266 | P13: =COUNTIFS(复贷评级明细!$B:$B,"*"&A13&"*",复贷评级明细!$X:$X,"是") -> 3 | Q13: =COUNTIFS(复贷评级明细!$B:$B,"*"&A13&"*",复贷评级明细!$Y:$Y,"是") -> 217
A14: 汇讯职场 | B14: =COUNTIFS(复贷评级明细!$B:$B,"*"&A14&"*",复贷评级明细!$AN:$AN,"S") -> 3 | C14: =COUNTIFS(复贷评级明细!$B:$B,"*"&A14&"*",复贷评级明细!$AN:$AN,"A") -> 6 | D14: =COUNTIFS(复贷评级明细!$B:$B,"*"&A14&"*",复贷评级明细!$AN:$AN,"B") -> 10 | E14: =COUNTIFS(复贷评级明细!$B:$B,"*"&A14&"*",复贷评级明细!$AN:$AN,"C") -> 8 | F14: =SUM(B14:E14) -> 27 | G14: =IF($F$17>0,B14/$F$17,0) -> 0.0050590219 | H14: =IF($F$17>0,C14/$F$17,0) -> 0.010118044 | I14: =IF($F$17>0,D14/$F$17,0) -> 0.016863406 | J14: =IF($F$17>0,E14/$F$17,0) -> 0.013490725 | K14: =IFERROR(AVERAGEIFS(复贷评级明细!$AB:$AB,复贷评级明细!$B:$B,"*"&A14&"*",复贷评级明细!$Z:$Z,"是"),0) -> 87.250453 | L14: =IFERROR(AVERAGEIFS(复贷评级明细!$AC:$AC,复贷评级明细!$B:$B,"*"&A14&"*",复贷评级明细!$Z:$Z,"是"),0) -> 921.39037 | M14: =IFERROR(AVERAGEIFS(复贷评级明细!$AD:$AD,复贷评级明细!$B:$B,"*"&A14&"*",复贷评级明细!$Z:$Z,"是"),0) -> 22513.272 | N14: =IFERROR(AVERAGEIFS(复贷评级明细!$AF:$AF,复贷评级明细!$B:$B,"*"&A14&"*",复贷评级明细!$Z:$Z,"是"),0) -> 124.93085 | O14: =COUNTIF(复贷评级明细!$B:$B,"*"&A14&"*") -> 66 | P14: =COUNTIFS(复贷评级明细!$B:$B,"*"&A14&"*",复贷评级明细!$X:$X,"是") -> 0 | Q14: =COUNTIFS(复贷评级明细!$B:$B,"*"&A14&"*",复贷评级明细!$Y:$Y,"是") -> 39
A15: 翰锐曲靖职场 | B15: =COUNTIFS(复贷评级明细!$B:$B,"*"&A15&"*",复贷评级明细!$AN:$AN,"S") -> 3 | C15: =COUNTIFS(复贷评级明细!$B:$B,"*"&A15&"*",复贷评级明细!$AN:$AN,"A") -> 11 | D15: =COUNTIFS(复贷评级明细!$B:$B,"*"&A15&"*",复贷评级明细!$AN:$AN,"B") -> 18 | E15: =COUNTIFS(复贷评级明细!$B:$B,"*"&A15&"*",复贷评级明细!$AN:$AN,"C") -> 23 | F15: =SUM(B15:E15) -> 55 | G15: =IF($F$17>0,B15/$F$17,0) -> 0.0050590219 | H15: =IF($F$17>0,C15/$F$17,0) -> 0.018549747 | I15: =IF($F$17>0,D15/$F$17,0) -> 0.030354132 | J15: =IF($F$17>0,E15/$F$17,0) -> 0.038785835 | K15: =IFERROR(AVERAGEIFS(复贷评级明细!$AB:$AB,复贷评级明细!$B:$B,"*"&A15&"*",复贷评级明细!$Z:$Z,"是"),0) -> 80.230799 | L15: =IFERROR(AVERAGEIFS(复贷评级明细!$AC:$AC,复贷评级明细!$B:$B,"*"&A15&"*",复贷评级明细!$Z:$Z,"是"),0) -> 693.70382 | M15: =IFERROR(AVERAGEIFS(复贷评级明细!$AD:$AD,复贷评级明细!$B:$B,"*"&A15&"*",复贷评级明细!$Z:$Z,"是"),0) -> 23507.141 | N15: =IFERROR(AVERAGEIFS(复贷评级明细!$AF:$AF,复贷评级明细!$B:$B,"*"&A15&"*",复贷评级明细!$Z:$Z,"是"),0) -> 119.44613 | O15: =COUNTIF(复贷评级明细!$B:$B,"*"&A15&"*") -> 143 | P15: =COUNTIFS(复贷评级明细!$B:$B,"*"&A15&"*",复贷评级明细!$X:$X,"是") -> 2 | Q15: =COUNTIFS(复贷评级明细!$B:$B,"*"&A15&"*",复贷评级明细!$Y:$Y,"是") -> 88
A16: 赛维斯职场 | B16: =COUNTIFS(复贷评级明细!$B:$B,"*"&A16&"*",复贷评级明细!$AN:$AN,"S") -> 4 | C16: =COUNTIFS(复贷评级明细!$B:$B,"*"&A16&"*",复贷评级明细!$AN:$AN,"A") -> 24 | D16: =COUNTIFS(复贷评级明细!$B:$B,"*"&A16&"*",复贷评级明细!$AN:$AN,"B") -> 31 | E16: =COUNTIFS(复贷评级明细!$B:$B,"*"&A16&"*",复贷评级明细!$AN:$AN,"C") -> 18 | F16: =SUM(B16:E16) -> 77 | G16: =IF($F$17>0,B16/$F$17,0) -> 0.0067453626 | H16: =IF($F$17>0,C16/$F$17,0) -> 0.040472175 | I16: =IF($F$17>0,D16/$F$17,0) -> 0.05227656 | J16: =IF($F$17>0,E16/$F$17,0) -> 0.030354132 | K16: =IFERROR(AVERAGEIFS(复贷评级明细!$AB:$AB,复贷评级明细!$B:$B,"*"&A16&"*",复贷评级明细!$Z:$Z,"是"),0) -> 79.906792 | L16: =IFERROR(AVERAGEIFS(复贷评级明细!$AC:$AC,复贷评级明细!$B:$B,"*"&A16&"*",复贷评级明细!$Z:$Z,"是"),0) -> 805.21026 | M16: =IFERROR(AVERAGEIFS(复贷评级明细!$AD:$AD,复贷评级明细!$B:$B,"*"&A16&"*",复贷评级明细!$Z:$Z,"是"),0) -> 21854.925 | N16: =IFERROR(AVERAGEIFS(复贷评级明细!$AF:$AF,复贷评级明细!$B:$B,"*"&A16&"*",复贷评级明细!$Z:$Z,"是"),0) -> 130.90568 | O16: =COUNTIF(复贷评级明细!$B:$B,"*"&A16&"*") -> 197 | P16: =COUNTIFS(复贷评级明细!$B:$B,"*"&A16&"*",复贷评级明细!$X:$X,"是") -> 0 | Q16: =COUNTIFS(复贷评级明细!$B:$B,"*"&A16&"*",复贷评级明细!$Y:$Y,"是") -> 120
A17: 整体 | B17: =SUM(B5:B16) -> 118 | C17: =SUM(C5:C16) -> 178 | D17: =SUM(D5:D16) -> 178 | E17: =SUM(E5:E16) -> 119 | F17: =SUM(F5:F16) -> 593 | G17: =IF(F17>0,B17/F17,0) -> 0.1989882 | H17: =IF(F17>0,C17/F17,0) -> 0.30016863 | I17: =IF(F17>0,D17/F17,0) -> 0.30016863 | J17: =IF(F17>0,E17/F17,0) -> 0.20067454 | K17: =IFERROR(AVERAGEIFS(复贷评级明细!$AB:$AB,复贷评级明细!$Z:$Z,"是"),0) -> 96.302569 | L17: =IFERROR(AVERAGEIFS(复贷评级明细!$AC:$AC,复贷评级明细!$Z:$Z,"是"),0) -> 894.9271 | M17: =IFERROR(AVERAGEIFS(复贷评级明细!$AD:$AD,复贷评级明细!$Z:$Z,"是"),0) -> 24508.748 | N17: =IFERROR(AVERAGEIFS(复贷评级明细!$AF:$AF,复贷评级明细!$Z:$Z,"是"),0) -> 136.25424 | O17: =SUM(O5:O16) -> 1665 | P17: =SUM(P5:P16) -> 10 | Q17: =SUM(Q5:Q16) -> 1072

Sheet 司龄统计
A1: 首贷坐席司龄统计
A2: 有效在岗=外呼天数≥20天 | 流失=超7天未上线 | 预警=连续3天未上线
A3: 一、有效在岗人数（外呼天数≥20天）
A4: 职场 | B4: MOB1- | C4: MOB1-3 | D4: MOB3-6 | E4: MOB6-12 | F4: MOB12+ | G4: 合计 | H4: 平均司龄(天) | I4: MOB1-占比 | J4: MOB1-3占比 | K4: MOB3-6占比 | L4: MOB6-12占比 | M4: MOB12+占比
A5: 人和职场 | B5: =COUNTIFS(首贷评级明细!$B:$B,"*"&A5&"*",首贷评级明细!$AN:$AN,"MOB1-",首贷评级明细!$O:$O,">="&20) -> 0 | C5: =COUNTIFS(首贷评级明细!$B:$B,"*"&A5&"*",首贷评级明细!$AN:$AN,"MOB1-3",首贷评级明细!$O:$O,">="&20) -> 1 | D5: =COUNTIFS(首贷评级明细!$B:$B,"*"&A5&"*",首贷评级明细!$AN:$AN,"MOB3-6",首贷评级明细!$O:$O,">="&20) -> 1 | E5: =COUNTIFS(首贷评级明细!$B:$B,"*"&A5&"*",首贷评级明细!$AN:$AN,"MOB6-12",首贷评级明细!$O:$O,">="&20) -> 2 | F5: =COUNTIFS(首贷评级明细!$B:$B,"*"&A5&"*",首贷评级明细!$AN:$AN,"MOB12+",首贷评级明细!$O:$O,">="&20) -> 8 | G5: =SUM(B5:F5) -> 12 | H5: =IFERROR(AVERAGEIFS(首贷评级明细!$G:$G,首贷评级明细!$B:$B,"*"&A5&"*",首贷评级明细!$O:$O,">="&20),0) -> 527.25 | I5: =IF(G5>0,B5/G5,0) -> 0 | J5: =IF(G5>0,C5/G5,0) -> 0.083333333 | K5: =IF(G5>0,D5/G5,0) -> 0.083333333 | L5: =IF(G5>0,E5/G5,0) -> 0.16666667 | M5: =IF(G5>0,F5/G5,0) -> 0.66666667
A6: 伽玛职场 | B6: =COUNTIFS(首贷评级明细!$B:$B,"*"&A6&"*",首贷评级明细!$AN:$AN,"MOB1-",首贷评级明细!$O:$O,">="&20) -> 4 | C6: =COUNTIFS(首贷评级明细!$B:$B,"*"&A6&"*",首贷评级明细!$AN:$AN,"MOB1-3",首贷评级明细!$O:$O,">="&20) -> 23 | D6: =COUNTIFS(首贷评级明细!$B:$B,"*"&A6&"*",首贷评级明细!$AN:$AN,"MOB3-6",首贷评级明细!$O:$O,">="&20) -> 8 | E6: =COUNTIFS(首贷评级明细!$B:$B,"*"&A6&"*",首贷评级明细!$AN:$AN,"MOB6-12",首贷评级明细!$O:$O,">="&20) -> 8 | F6: =COUNTIFS(首贷评级明细!$B:$B,"*"&A6&"*",首贷评级明细!$AN:$AN,"MOB12+",首贷评级明细!$O:$O,">="&20) -> 18 | G6: =SUM(B6:F6) -> 61 | H6: =IFERROR(AVERAGEIFS(首贷评级明细!$G:$G,首贷评级明细!$B:$B,"*"&A6&"*",首贷评级明细!$O:$O,">="&20),0) -> 324.77049 | I6: =IF(G6>0,B6/G6,0) -> 0.06557377 | J6: =IF(G6>0,C6/G6,0) -> 0.37704918 | K6: =IF(G6>0,D6/G6,0) -> 0.13114754 | L6: =IF(G6>0,E6/G6,0) -> 0.13114754 | M6: =IF(G6>0,F6/G6,0) -> 0.29508197
A7: 华啸职场 | B7: =COUNTIFS(首贷评级明细!$B:$B,"*"&A7&"*",首贷评级明细!$AN:$AN,"MOB1-",首贷评级明细!$O:$O,">="&20) -> 0 | C7: =COUNTIFS(首贷评级明细!$B:$B,"*"&A7&"*",首贷评级明细!$AN:$AN,"MOB1-3",首贷评级明细!$O:$O,">="&20) -> 0 | D7: =COUNTIFS(首贷评级明细!$B:$B,"*"&A7&"*",首贷评级明细!$AN:$AN,"MOB3-6",首贷评级明细!$O:$O,">="&20) -> 0 | E7: =COUNTIFS(首贷评级明细!$B:$B,"*"&A7&"*",首贷评级明细!$AN:$AN,"MOB6-12",首贷评级明细!$O:$O,">="&20) -> 0 | F7: =COUNTIFS(首贷评级明细!$B:$B,"*"&A7&"*",首贷评级明细!$AN:$AN,"MOB12+",首贷评级明细!$O:$O,">="&20) -> 0 | G7: =SUM(B7:F7) -> 0 | H7: =IFERROR(AVERAGEIFS(首贷评级明细!$G:$G,首贷评级明细!$B:$B,"*"&A7&"*",首贷评级明细!$O:$O,">="&20),0) -> 0 | I7: =IF(G7>0,B7/G7,0) -> 0 | J7: =IF(G7>0,C7/G7,0) -> 0 | K7: =IF(G7>0,D7/G7,0) -> 0 | L7: =IF(G7>0,E7/G7,0) -> 0 | M7: =IF(G7>0,F7/G7,0) -> 0
A8: 博岳石家庄职场 | B8: =COUNTIFS(首贷评级明细!$B:$B,"*"&A8&"*",首贷评级明细!$AN:$AN,"MOB1-",首贷评级明细!$O:$O,">="&20) -> 0 | C8: =COUNTIFS(首贷评级明细!$B:$B,"*"&A8&"*",首贷评级明细!$AN:$AN,"MOB1-3",首贷评级明细!$O:$O,">="&20) -> 17 | D8: =COUNTIFS(首贷评级明细!$B:$B,"*"&A8&"*",首贷评级明细!$AN:$AN,"MOB3-6",首贷评级明细!$O:$O,">="&20) -> 2 | E8: =COUNTIFS(首贷评级明细!$B:$B,"*"&A8&"*",首贷评级明细!$AN:$AN,"MOB6-12",首贷评级明细!$O:$O,">="&20) -> 7 | F8: =COUNTIFS(首贷评级明细!$B:$B,"*"&A8&"*",首贷评级明细!$AN:$AN,"MOB12+",首贷评级明细!$O:$O,">="&20) -> 10 | G8: =SUM(B8:F8) -> 36 | H8: =IFERROR(AVERAGEIFS(首贷评级明细!$G:$G,首贷评级明细!$B:$B,"*"&A8&"*",首贷评级明细!$O:$O,">="&20),0) -> 299.11111 | I8: =IF(G8>0,B8/G8,0) -> 0 | J8: =IF(G8>0,C8/G8,0) -> 0.47222222 | K8: =IF(G8>0,D8/G8,0) -> 0.055555556 | L8: =IF(G8>0,E8/G8,0) -> 0.19444444 | M8: =IF(G8>0,F8/G8,0) -> 0.27777778
A9: 宿迁兆科职场 | B9: =COUNTIFS(首贷评级明细!$B:$B,"*"&A9&"*",首贷评级明细!$AN:$AN,"MOB1-",首贷评级明细!$O:$O,">="&20) -> 0 | C9: =COUNTIFS(首贷评级明细!$B:$B,"*"&A9&"*",首贷评级明细!$AN:$AN,"MOB1-3",首贷评级明细!$O:$O,">="&20) -> 3 | D9: =COUNTIFS(首贷评级明细!$B:$B,"*"&A9&"*",首贷评级明细!$AN:$AN,"MOB3-6",首贷评级明细!$O:$O,">="&20) -> 3 | E9: =COUNTIFS(首贷评级明细!$B:$B,"*"&A9&"*",首贷评级明细!$AN:$AN,"MOB6-12",首贷评级明细!$O:$O,">="&20) -> 0 | F9: =COUNTIFS(首贷评级明细!$B:$B,"*"&A9&"*",首贷评级明细!$AN:$AN,"MOB12+",首贷评级明细!$O:$O,">="&20) -> 1 | G9: =SUM(B9:F9) -> 7 | H9: =IFERROR(AVERAGEIFS(首贷评级明细!$G:$G,首贷评级明细!$B:$B,"*"&A9&"*",首贷评级明细!$O:$O,">="&20),0) -> 159.71429 | I9: =IF(G9>0,B9/G9,0) -> 0 | J9: =IF(G9>0,C9/G9,0) -> 0.42857143 | K9: =IF(G9>0,D9/G9,0) -> 0.42857143 | L9: =IF(G9>0,E9/G9,0) -> 0 | M9: =IF(G9>0,F9/G9,0) -> 0.14285714
A10: 岐力职场 | B10: =COUNTIFS(首贷评级明细!$B:$B,"*"&A10&"*",首贷评级明细!$AN:$AN,"MOB1-",首贷评级明细!$O:$O,">="&20) -> 0 | C10: =COUNTIFS(首贷评级明细!$B:$B,"*"&A10&"*",首贷评级明细!$AN:$AN,"MOB1-3",首贷评级明细!$O:$O,">="&20) -> 3 | D10: =COUNTIFS(首贷评级明细!$B:$B,"*"&A10&"*",首贷评级明细!$AN:$AN,"MOB3-6",首贷评级明细!$O:$O,">="&20) -> 0 | E10: =COUNTIFS(首贷评级明细!$B:$B,"*"&A10&"*",首贷评级明细!$AN:$AN,"MOB6-12",首贷评级明细!$O:$O,">="&20) -> 0 | F10: =COUNTIFS(首贷评级明细!$B:$B,"*"&A10&"*",首贷评级明细!$AN:$AN,"MOB12+",首贷评级明细!$O:$O,">="&20) -> 0 | G10: =SUM(B10:F10) -> 3 | H10: =IFERROR(AVERAGEIFS(首贷评级明细!$G:$G,首贷评级明细!$B:$B,"*"&A10&"*",首贷评级明细!$O:$O,">="&20),0) -> 71 | I10: =IF(G10>0,B10/G10,0) -> 0 | J10: =IF(G10>0,C10/G10,0) -> 1 | K10: =IF(G10>0,D10/G10,0) -> 0 | L10: =IF(G10>0,E10/G10,0) -> 0 | M10: =IF(G10>0,F10/G10,0) -> 0
A11: 广达陕西职场 | B11: =COUNTIFS(首贷评级明细!$B:$B,"*"&A11&"*",首贷评级明细!$AN:$AN,"MOB1-",首贷评级明细!$O:$O,">="&20) -> 0 | C11: =COUNTIFS(首贷评级明细!$B:$B,"*"&A11&"*",首贷评级明细!$AN:$AN,"MOB1-3",首贷评级明细!$O:$O,">="&20) -> 2 | D11: =COUNTIFS(首贷评级明细!$B:$B,"*"&A11&"*",首贷评级明细!$AN:$AN,"MOB3-6",首贷评级明细!$O:$O,">="&20) -> 3 | E11: =COUNTIFS(首贷评级明细!$B:$B,"*"&A11&"*",首贷评级明细!$AN:$AN,"MOB6-12",首贷评级明细!$O:$O,">="&20) -> 0 | F11: =COUNTIFS(首贷评级明细!$B:$B,"*"&A11&"*",首贷评级明细!$AN:$AN,"MOB12+",首贷评级明细!$O:$O,">="&20) -> 16 | G11: =SUM(B11:F11) -> 21 | H11: =IFERROR(AVERAGEIFS(首贷评级明细!$G:$G,首贷评级明细!$B:$B,"*"&A11&"*",首贷评级明细!$O:$O,">="&20),0) -> 908.61905 | I11: =IF(G11>0,B11/G11,0) -> 0 | J11: =IF(G11>0,C11/G11,0) -> 0.095238095 | K11: =IF(G11>0,D11/G11,0) -> 0.14285714 | L11: =IF(G11>0,E11/G11,0) -> 0 | M11: =IF(G11>0,F11/G11,0) -> 0.76190476
A12: 毅航合肥职场 | B12: =COUNTIFS(首贷评级明细!$B:$B,"*"&A12&"*",首贷评级明细!$AN:$AN,"MOB1-",首贷评级明细!$O:$O,">="&20) -> 3 | C12: =COUNTIFS(首贷评级明细!$B:$B,"*"&A12&"*",首贷评级明细!$AN:$AN,"MOB1-3",首贷评级明细!$O:$O,">="&20) -> 41 | D12: =COUNTIFS(首贷评级明细!$B:$B,"*"&A12&"*",首贷评级明细!$AN:$AN,"MOB3-6",首贷评级明细!$O:$O,">="&20) -> 11 | E12: =COUNTIFS(首贷评级明细!$B:$B,"*"&A12&"*",首贷评级明细!$AN:$AN,"MOB6-12",首贷评级明细!$O:$O,">="&20) -> 23 | F12: =COUNTIFS(首贷评级明细!$B:$B,"*"&A12&"*",首贷评级明细!$AN:$AN,"MOB12+",首贷评级明细!$O:$O,">="&20) -> 94 | G12: =SUM(B12:F12) -> 172 | H12: =IFERROR(AVERAGEIFS(首贷评级明细!$G:$G,首贷评级明细!$B:$B,"*"&A12&"*",首贷评级明细!$O:$O,">="&20),0) -> 570.65116 | I12: =IF(G12>0,B12/G12,0) -> 0.01744186 | J12: =IF(G12>0,C12/G12,0) -> 0.23837209 | K12: =IF(G12>0,D12/G12,0) -> 0.063953488 | L12: =IF(G12>0,E12/G12,0) -> 0.13372093 | M12: =IF(G12>0,F12/G12,0) -> 0.54651163
A13: 毛毛虫职场 | B13: =COUNTIFS(首贷评级明细!$B:$B,"*"&A13&"*",首贷评级明细!$AN:$AN,"MOB1-",首贷评级明细!$O:$O,">="&20) -> 2 | C13: =COUNTIFS(首贷评级明细!$B:$B,"*"&A13&"*",首贷评级明细!$AN:$AN,"MOB1-3",首贷评级明细!$O:$O,">="&20) -> 27 | D13: =COUNTIFS(首贷评级明细!$B:$B,"*"&A13&"*",首贷评级明细!$AN:$AN,"MOB3-6",首贷评级明细!$O:$O,">="&20) -> 12 | E13: =COUNTIFS(首贷评级明细!$B:$B,"*"&A13&"*",首贷评级明细!$AN:$AN,"MOB6-12",首贷评级明细!$O:$O,">="&20) -> 17 | F13: =COUNTIFS(首贷评级明细!$B:$B,"*"&A13&"*",首贷评级明细!$AN:$AN,"MOB12+",首贷评级明细!$O:$O,">="&20) -> 77 | G13: =SUM(B13:F13) -> 135 | H13: =IFERROR(AVERAGEIFS(首贷评级明细!$G:$G,首贷评级明细!$B:$B,"*"&A13&"*",首贷评级明细!$O:$O,">="&20),0) -> 602.36296 | I13: =IF(G13>0,B13/G13,0) -> 0.014814815 | J13: =IF(G13>0,C13/G13,0) -> 0.2 | K13: =IF(G13>0,D13/G13,0) -> 0.088888889 | L13: =IF(G13>0,E13/G13,0) -> 0.12592593 | M13: =IF(G13>0,F13/G13,0) -> 0.57037037
A14: 汇讯职场 | B14: =COUNTIFS(首贷评级明细!$B:$B,"*"&A14&"*",首贷评级明细!$AN:$AN,"MOB1-",首贷评级明细!$O:$O,">="&20) -> 0 | C14: =COUNTIFS(首贷评级明细!$B:$B,"*"&A14&"*",首贷评级明细!$AN:$AN,"MOB1-3",首贷评级明细!$O:$O,">="&20) -> 26 | D14: =COUNTIFS(首贷评级明细!$B:$B,"*"&A14&"*",首贷评级明细!$AN:$AN,"MOB3-6",首贷评级明细!$O:$O,">="&20) -> 4 | E14: =COUNTIFS(首贷评级明细!$B:$B,"*"&A14&"*",首贷评级明细!$AN:$AN,"MOB6-12",首贷评级明细!$O:$O,">="&20) -> 4 | F14: =COUNTIFS(首贷评级明细!$B:$B,"*"&A14&"*",首贷评级明细!$AN:$AN,"MOB12+",首贷评级明细!$O:$O,">="&20) -> 16 | G14: =SUM(B14:F14) -> 50 | H14: =IFERROR(AVERAGEIFS(首贷评级明细!$G:$G,首贷评级明细!$B:$B,"*"&A14&"*",首贷评级明细!$O:$O,">="&20),0) -> 247.74 | I14: =IF(G14>0,B14/G14,0) -> 0 | J14: =IF(G14>0,C14/G14,0) -> 0.52 | K14: =IF(G14>0,D14/G14,0) -> 0.08 | L14: =IF(G14>0,E14/G14,0) -> 0.08 | M14: =IF(G14>0,F14/G14,0) -> 0.32
A15: 翰锐曲靖职场 | B15: =COUNTIFS(首贷评级明细!$B:$B,"*"&A15&"*",首贷评级明细!$AN:$AN,"MOB1-",首贷评级明细!$O:$O,">="&20) -> 2 | C15: =COUNTIFS(首贷评级明细!$B:$B,"*"&A15&"*",首贷评级明细!$AN:$AN,"MOB1-3",首贷评级明细!$O:$O,">="&20) -> 8 | D15: =COUNTIFS(首贷评级明细!$B:$B,"*"&A15&"*",首贷评级明细!$AN:$AN,"MOB3-6",首贷评级明细!$O:$O,">="&20) -> 0 | E15: =COUNTIFS(首贷评级明细!$B:$B,"*"&A15&"*",首贷评级明细!$AN:$AN,"MOB6-12",首贷评级明细!$O:$O,">="&20) -> 1 | F15: =COUNTIFS(首贷评级明细!$B:$B,"*"&A15&"*",首贷评级明细!$AN:$AN,"MOB12+",首贷评级明细!$O:$O,">="&20) -> 10 | G15: =SUM(B15:F15) -> 21 | H15: =IFERROR(AVERAGEIFS(首贷评级明细!$G:$G,首贷评级明细!$B:$B,"*"&A15&"*",首贷评级明细!$O:$O,">="&20),0) -> 614.61905 | I15: =IF(G15>0,B15/G15,0) -> 0.095238095 | J15: =IF(G15>0,C15/G15,0) -> 0.38095238 | K15: =IF(G15>0,D15/G15,0) -> 0 | L15: =IF(G15>0,E15/G15,0) -> 0.047619048 | M15: =IF(G15>0,F15/G15,0) -> 0.47619048
A16: 赛维斯职场 | B16: =COUNTIFS(首贷评级明细!$B:$B,"*"&A16&"*",首贷评级明细!$AN:$AN,"MOB1-",首贷评级明细!$O:$O,">="&20) -> 0 | C16: =COUNTIFS(首贷评级明细!$B:$B,"*"&A16&"*",首贷评级明细!$AN:$AN,"MOB1-3",首贷评级明细!$O:$O,">="&20) -> 7 | D16: =COUNTIFS(首贷评级明细!$B:$B,"*"&A16&"*",首贷评级明细!$AN:$AN,"MOB3-6",首贷评级明细!$O:$O,">="&20) -> 1 | E16: =COUNTIFS(首贷评级明细!$B:$B,"*"&A16&"*",首贷评级明细!$AN:$AN,"MOB6-12",首贷评级明细!$O:$O,">="&20) -> 1 | F16: =COUNTIFS(首贷评级明细!$B:$B,"*"&A16&"*",首贷评级明细!$AN:$AN,"MOB12+",首贷评级明细!$O:$O,">="&20) -> 35 | G16: =SUM(B16:F16) -> 44 | H16: =IFERROR(AVERAGEIFS(首贷评级明细!$G:$G,首贷评级明细!$B:$B,"*"&A16&"*",首贷评级明细!$O:$O,">="&20),0) -> 774.56818 | I16: =IF(G16>0,B16/G16,0) -> 0 | J16: =IF(G16>0,C16/G16,0) -> 0.15909091 | K16: =IF(G16>0,D16/G16,0) -> 0.022727273 | L16: =IF(G16>0,E16/G16,0) -> 0.022727273 | M16: =IF(G16>0,F16/G16,0) -> 0.79545455
A17: 整体 | B17: =SUM(B5:B16) -> 11 | C17: =SUM(C5:C16) -> 158 | D17: =SUM(D5:D16) -> 45 | E17: =SUM(E5:E16) -> 63 | F17: =SUM(F5:F16) -> 285 | G17: =SUM(G5:G16) -> 562 | H17: =IFERROR(AVERAGEIFS(首贷评级明细!$G:$G,首贷评级明细!$O:$O,">="&20),0) -> 526.98221 | I17: =IF(G17>0,B17/G17,0) -> 0.019572954 | J17: =IF(G17>0,C17/G17,0) -> 0.28113879 | K17: =IF(G17>0,D17/G17,0) -> 0.080071174 | L17: =IF(G17>0,E17/G17,0) -> 0.11209964 | M17: =IF(G17>0,F17/G17,0) -> 0.50711744
A21: 复贷坐席司龄统计
A22: 有效在岗=外呼天数≥20天 | 流失=超7天未上线 | 预警=连续3天未上线
A23: 一、有效在岗人数（外呼天数≥20天）
A24: 职场 | B24: MOB1- | C24: MOB1-3 | D24: MOB3-6 | E24: MOB6-12 | F24: MOB12+ | G24: 合计 | H24: 平均司龄(天) | I24: MOB1-占比 | J24: MOB1-3占比 | K24: MOB3-6占比 | L24: MOB6-12占比 | M24: MOB12+占比
A25: 人和职场 | B25: =COUNTIFS(复贷评级明细!$B:$B,"*"&A25&"*",复贷评级明细!$AO:$AO,"MOB1-",复贷评级明细!$O:$O,">="&20) -> 1 | C25: =COUNTIFS(复贷评级明细!$B:$B,"*"&A25&"*",复贷评级明细!$AO:$AO,"MOB1-3",复贷评级明细!$O:$O,">="&20) -> 7 | D25: =COUNTIFS(复贷评级明细!$B:$B,"*"&A25&"*",复贷评级明细!$AO:$AO,"MOB3-6",复贷评级明细!$O:$O,">="&20) -> 6 | E25: =COUNTIFS(复贷评级明细!$B:$B,"*"&A25&"*",复贷评级明细!$AO:$AO,"MOB6-12",复贷评级明细!$O:$O,">="&20) -> 1 | F25: =COUNTIFS(复贷评级明细!$B:$B,"*"&A25&"*",复贷评级明细!$AO:$AO,"MOB12+",复贷评级明细!$O:$O,">="&20) -> 2 | G25: =SUM(B25:F25) -> 17 | H25: =IFERROR(AVERAGEIFS(复贷评级明细!$G:$G,复贷评级明细!$B:$B,"*"&A25&"*",复贷评级明细!$O:$O,">="&20),0) -> 142.35294 | I25: =IF(G25>0,B25/G25,0) -> 0.058823529 | J25: =IF(G25>0,C25/G25,0) -> 0.41176471 | K25: =IF(G25>0,D25/G25,0) -> 0.35294118 | L25: =IF(G25>0,E25/G25,0) -> 0.058823529 | M25: =IF(G25>0,F25/G25,0) -> 0.11764706
A26: 伽玛职场 | B26: =COUNTIFS(复贷评级明细!$B:$B,"*"&A26&"*",复贷评级明细!$AO:$AO,"MOB1-",复贷评级明细!$O:$O,">="&20) -> 2 | C26: =COUNTIFS(复贷评级明细!$B:$B,"*"&A26&"*",复贷评级明细!$AO:$AO,"MOB1-3",复贷评级明细!$O:$O,">="&20) -> 29 | D26: =COUNTIFS(复贷评级明细!$B:$B,"*"&A26&"*",复贷评级明细!$AO:$AO,"MOB3-6",复贷评级明细!$O:$O,">="&20) -> 17 | E26: =COUNTIFS(复贷评级明细!$B:$B,"*"&A26&"*",复贷评级明细!$AO:$AO,"MOB6-12",复贷评级明细!$O:$O,">="&20) -> 21 | F26: =COUNTIFS(复贷评级明细!$B:$B,"*"&A26&"*",复贷评级明细!$AO:$AO,"MOB12+",复贷评级明细!$O:$O,">="&20) -> 28 | G26: =SUM(B26:F26) -> 97 | H26: =IFERROR(AVERAGEIFS(复贷评级明细!$G:$G,复贷评级明细!$B:$B,"*"&A26&"*",复贷评级明细!$O:$O,">="&20),0) -> 255.29897 | I26: =IF(G26>0,B26/G26,0) -> 0.020618557 | J26: =IF(G26>0,C26/G26,0) -> 0.29896907 | K26: =IF(G26>0,D26/G26,0) -> 0.17525773 | L26: =IF(G26>0,E26/G26,0) -> 0.21649485 | M26: =IF(G26>0,F26/G26,0) -> 0.28865979
A27: 华啸职场 | B27: =COUNTIFS(复贷评级明细!$B:$B,"*"&A27&"*",复贷评级明细!$AO:$AO,"MOB1-",复贷评级明细!$O:$O,">="&20) -> 0 | C27: =COUNTIFS(复贷评级明细!$B:$B,"*"&A27&"*",复贷评级明细!$AO:$AO,"MOB1-3",复贷评级明细!$O:$O,">="&20) -> 21 | D27: =COUNTIFS(复贷评级明细!$B:$B,"*"&A27&"*",复贷评级明细!$AO:$AO,"MOB3-6",复贷评级明细!$O:$O,">="&20) -> 2 | E27: =COUNTIFS(复贷评级明细!$B:$B,"*"&A27&"*",复贷评级明细!$AO:$AO,"MOB6-12",复贷评级明细!$O:$O,">="&20) -> 0 | F27: =COUNTIFS(复贷评级明细!$B:$B,"*"&A27&"*",复贷评级明细!$AO:$AO,"MOB12+",复贷评级明细!$O:$O,">="&20) -> 0 | G27: =SUM(B27:F27) -> 23 | H27: =IFERROR(AVERAGEIFS(复贷评级明细!$G:$G,复贷评级明细!$B:$B,"*"&A27&"*",复贷评级明细!$O:$O,">="&20),0) -> 66.391304 | I27: =IF(G27>0,B27/G27,0) -> 0 | J27: =IF(G27>0,C27/G27,0) -> 0.91304348 | K27: =IF(G27>0,D27/G27,0) -> 0.086956522 | L27: =IF(G27>0,E27/G27,0) -> 0 | M27: =IF(G27>0,F27/G27,0) -> 0
A28: 博岳石家庄职场 | B28: =COUNTIFS(复贷评级明细!$B:$B,"*"&A28&"*",复贷评级明细!$AO:$AO,"MOB1-",复贷评级明细!$O:$O,">="&20) -> 1 | C28: =COUNTIFS(复贷评级明细!$B:$B,"*"&A28&"*",复贷评级明细!$AO:$AO,"MOB1-3",复贷评级明细!$O:$O,">="&20) -> 25 | D28: =COUNTIFS(复贷评级明细!$B:$B,"*"&A28&"*",复贷评级明细!$AO:$AO,"MOB3-6",复贷评级明细!$O:$O,">="&20) -> 6 | E28: =COUNTIFS(复贷评级明细!$B:$B,"*"&A28&"*",复贷评级明细!$AO:$AO,"MOB6-12",复贷评级明细!$O:$O,">="&20) -> 8 | F28: =COUNTIFS(复贷评级明细!$B:$B,"*"&A28&"*",复贷评级明细!$AO:$AO,"MOB12+",复贷评级明细!$O:$O,">="&20) -> 8 | G28: =SUM(B28:F28) -> 48 | H28: =IFERROR(AVERAGEIFS(复贷评级明细!$G:$G,复贷评级明细!$B:$B,"*"&A28&"*",复贷评级明细!$O:$O,">="&20),0) -> 282.375 | I28: =IF(G28>0,B28/G28,0) -> 0.020833333 | J28: =IF(G28>0,C28/G28,0) -> 0.52083333 | K28: =IF(G28>0,D28/G28,0) -> 0.125 | L28: =IF(G28>0,E28/G28,0) -> 0.16666667 | M28: =IF(G28>0,F28/G28,0) -> 0.16666667
A29: 宿迁兆科职场 | B29: =COUNTIFS(复贷评级明细!$B:$B,"*"&A29&"*",复贷评级明细!$AO:$AO,"MOB1-",复贷评级明细!$O:$O,">="&20) -> 0 | C29: =COUNTIFS(复贷评级明细!$B:$B,"*"&A29&"*",复贷评级明细!$AO:$AO,"MOB1-3",复贷评级明细!$O:$O,">="&20) -> 7 | D29: =COUNTIFS(复贷评级明细!$B:$B,"*"&A29&"*",复贷评级明细!$AO:$AO,"MOB3-6",复贷评级明细!$O:$O,">="&20) -> 0 | E29: =COUNTIFS(复贷评级明细!$B:$B,"*"&A29&"*",复贷评级明细!$AO:$AO,"MOB6-12",复贷评级明细!$O:$O,">="&20) -> 1 | F29: =COUNTIFS(复贷评级明细!$B:$B,"*"&A29&"*",复贷评级明细!$AO:$AO,"MOB12+",复贷评级明细!$O:$O,">="&20) -> 0 | G29: =SUM(B29:F29) -> 8 | H29: =IFERROR(AVERAGEIFS(复贷评级明细!$G:$G,复贷评级明细!$B:$B,"*"&A29&"*",复贷评级明细!$O:$O,">="&20),0) -> 83.25 | I29: =IF(G29>0,B29/G29,0) -> 0 | J29: =IF(G29>0,C29/G29,0) -> 0.875 | K29: =IF(G29>0,D29/G29,0) -> 0 | L29: =IF(G29>0,E29/G29,0) -> 0.125 | M29: =IF(G29>0,F29/G29,0) -> 0
A30: 岐力职场 | B30: =COUNTIFS(复贷评级明细!$B:$B,"*"&A30&"*",复贷评级明细!$AO:$AO,"MOB1-",复贷评级明细!$O:$O,">="&20) -> 0 | C30: =COUNTIFS(复贷评级明细!$B:$B,"*"&A30&"*",复贷评级明细!$AO:$AO,"MOB1-3",复贷评级明细!$O:$O,">="&20) -> 37 | D30: =COUNTIFS(复贷评级明细!$B:$B,"*"&A30&"*",复贷评级明细!$AO:$AO,"MOB3-6",复贷评级明细!$O:$O,">="&20) -> 8 | E30: =COUNTIFS(复贷评级明细!$B:$B,"*"&A30&"*",复贷评级明细!$AO:$AO,"MOB6-12",复贷评级明细!$O:$O,">="&20) -> 12 | F30: =COUNTIFS(复贷评级明细!$B:$B,"*"&A30&"*",复贷评级明细!$AO:$AO,"MOB12+",复贷评级明细!$O:$O,">="&20) -> 0 | G30: =SUM(B30:F30) -> 57 | H30: =IFERROR(AVERAGEIFS(复贷评级明细!$G:$G,复贷评级明细!$B:$B,"*"&A30&"*",复贷评级明细!$O:$O,">="&20),0) -> 118.36842 | I30: =IF(G30>0,B30/G30,0) -> 0 | J30: =IF(G30>0,C30/G30,0) -> 0.64912281 | K30: =IF(G30>0,D30/G30,0) -> 0.14035088 | L30: =IF(G30>0,E30/G30,0) -> 0.21052632 | M30: =IF(G30>0,F30/G30,0) -> 0
A31: 广达陕西职场 | B31: =COUNTIFS(复贷评级明细!$B:$B,"*"&A31&"*",复贷评级明细!$AO:$AO,"MOB1-",复贷评级明细!$O:$O,">="&20) -> 0 | C31: =COUNTIFS(复贷评级明细!$B:$B,"*"&A31&"*",复贷评级明细!$AO:$AO,"MOB1-3",复贷评级明细!$O:$O,">="&20) -> 8 | D31: =COUNTIFS(复贷评级明细!$B:$B,"*"&A31&"*",复贷评级明细!$AO:$AO,"MOB3-6",复贷评级明细!$O:$O,">="&20) -> 12 | E31: =COUNTIFS(复贷评级明细!$B:$B,"*"&A31&"*",复贷评级明细!$AO:$AO,"MOB6-12",复贷评级明细!$O:$O,">="&20) -> 6 | F31: =COUNTIFS(复贷评级明细!$B:$B,"*"&A31&"*",复贷评级明细!$AO:$AO,"MOB12+",复贷评级明细!$O:$O,">="&20) -> 2 | G31: =SUM(B31:F31) -> 28 | H31: =IFERROR(AVERAGEIFS(复贷评级明细!$G:$G,复贷评级明细!$B:$B,"*"&A31&"*",复贷评级明细!$O:$O,">="&20),0) -> 202.35714 | I31: =IF(G31>0,B31/G31,0) -> 0 | J31: =IF(G31>0,C31/G31,0) -> 0.28571429 | K31: =IF(G31>0,D31/G31,0) -> 0.42857143 | L31: =IF(G31>0,E31/G31,0) -> 0.21428571 | M31: =IF(G31>0,F31/G31,0) -> 0.071428571
A32: 毅航合肥职场 | B32: =COUNTIFS(复贷评级明细!$B:$B,"*"&A32&"*",复贷评级明细!$AO:$AO,"MOB1-",复贷评级明细!$O:$O,">="&20) -> 7 | C32: =COUNTIFS(复贷评级明细!$B:$B,"*"&A32&"*",复贷评级明细!$AO:$AO,"MOB1-3",复贷评级明细!$O:$O,">="&20) -> 39 | D32: =COUNTIFS(复贷评级明细!$B:$B,"*"&A32&"*",复贷评级明细!$AO:$AO,"MOB3-6",复贷评级明细!$O:$O,">="&20) -> 26 | E32: =COUNTIFS(复贷评级明细!$B:$B,"*"&A32&"*",复贷评级明细!$AO:$AO,"MOB6-12",复贷评级明细!$O:$O,">="&20) -> 27 | F32: =COUNTIFS(复贷评级明细!$B:$B,"*"&A32&"*",复贷评级明细!$AO:$AO,"MOB12+",复贷评级明细!$O:$O,">="&20) -> 34 | G32: =SUM(B32:F32) -> 133 | H32: =IFERROR(AVERAGEIFS(复贷评级明细!$G:$G,复贷评级明细!$B:$B,"*"&A32&"*",复贷评级明细!$O:$O,">="&20),0) -> 265.60902 | I32: =IF(G32>0,B32/G32,0) -> 0.052631579 | J32: =IF(G32>0,C32/G32,0) -> 0.29323308 | K32: =IF(G32>0,D32/G32,0) -> 0.19548872 | L32: =IF(G32>0,E32/G32,0) -> 0.20300752 | M32: =IF(G32>0,F32/G32,0) -> 0.2556391
A33: 毛毛虫职场 | B33: =COUNTIFS(复贷评级明细!$B:$B,"*"&A33&"*",复贷评级明细!$AO:$AO,"MOB1-",复贷评级明细!$O:$O,">="&20) -> 3 | C33: =COUNTIFS(复贷评级明细!$B:$B,"*"&A33&"*",复贷评级明细!$AO:$AO,"MOB1-3",复贷评级明细!$O:$O,">="&20) -> 9 | D33: =COUNTIFS(复贷评级明细!$B:$B,"*"&A33&"*",复贷评级明细!$AO:$AO,"MOB3-6",复贷评级明细!$O:$O,">="&20) -> 7 | E33: =COUNTIFS(复贷评级明细!$B:$B,"*"&A33&"*",复贷评级明细!$AO:$AO,"MOB6-12",复贷评级明细!$O:$O,">="&20) -> 13 | F33: =COUNTIFS(复贷评级明细!$B:$B,"*"&A33&"*",复贷评级明细!$AO:$AO,"MOB12+",复贷评级明细!$O:$O,">="&20) -> 22 | G33: =SUM(B33:F33) -> 54 | H33: =IFERROR(AVERAGEIFS(复贷评级明细!$G:$G,复贷评级明细!$B:$B,"*"&A33&"*",复贷评级明细!$O:$O,">="&20),0) -> 307.53704 | I33: =IF(G33>0,B33/G33,0) -> 0.055555556 | J33: =IF(G33>0,C33/G33,0) -> 0.16666667 | K33: =IF(G33>0,D33/G33,0) -> 0.12962963 | L33: =IF(G33>0,E33/G33,0) -> 0.24074074 | M33: =IF(G33>0,F33/G33,0) -> 0.40740741
A34: 汇讯职场 | B34: =COUNTIFS(复贷评级明细!$B:$B,"*"&A34&"*",复贷评级明细!$AO:$AO,"MOB1-",复贷评级明细!$O:$O,">="&20) -> 1 | C34: =COUNTIFS(复贷评级明细!$B:$B,"*"&A34&"*",复贷评级明细!$AO:$AO,"MOB1-3",复贷评级明细!$O:$O,">="&20) -> 6 | D34: =COUNTIFS(复贷评级明细!$B:$B,"*"&A34&"*",复贷评级明细!$AO:$AO,"MOB3-6",复贷评级明细!$O:$O,">="&20) -> 1 | E34: =COUNTIFS(复贷评级明细!$B:$B,"*"&A34&"*",复贷评级明细!$AO:$AO,"MOB6-12",复贷评级明细!$O:$O,">="&20) -> 4 | F34: =COUNTIFS(复贷评级明细!$B:$B,"*"&A34&"*",复贷评级明细!$AO:$AO,"MOB12+",复贷评级明细!$O:$O,">="&20) -> 15 | G34: =SUM(B34:F34) -> 27 | H34: =IFERROR(AVERAGEIFS(复贷评级明细!$G:$G,复贷评级明细!$B:$B,"*"&A34&"*",复贷评级明细!$O:$O,">="&20),0) -> 582.62963 | I34: =IF(G34>0,B34/G34,0) -> 0.037037037 | J34: =IF(G34>0,C34/G34,0) -> 0.22222222 | K34: =IF(G34>0,D34/G34,0) -> 0.037037037 | L34: =IF(G34>0,E34/G34,0) -> 0.14814815 | M34: =IF(G34>0,F34/G34,0) -> 0.55555556
A35: 翰锐曲靖职场 | B35: =COUNTIFS(复贷评级明细!$B:$B,"*"&A35&"*",复贷评级明细!$AO:$AO,"MOB1-",复贷评级明细!$O:$O,">="&20) -> 4 | C35: =COUNTIFS(复贷评级明细!$B:$B,"*"&A35&"*",复贷评级明细!$AO:$AO,"MOB1-3",复贷评级明细!$O:$O,">="&20) -> 14 | D35: =COUNTIFS(复贷评级明细!$B:$B,"*"&A35&"*",复贷评级明细!$AO:$AO,"MOB3-6",复贷评级明细!$O:$O,">="&20) -> 5 | E35: =COUNTIFS(复贷评级明细!$B:$B,"*"&A35&"*",复贷评级明细!$AO:$AO,"MOB6-12",复贷评级明细!$O:$O,">="&20) -> 10 | F35: =COUNTIFS(复贷评级明细!$B:$B,"*"&A35&"*",复贷评级明细!$AO:$AO,"MOB12+",复贷评级明细!$O:$O,">="&20) -> 25 | G35: =SUM(B35:F35) -> 58 | H35: =IFERROR(AVERAGEIFS(复贷评级明细!$G:$G,复贷评级明细!$B:$B,"*"&A35&"*",复贷评级明细!$O:$O,">="&20),0) -> 344.53448 | I35: =IF(G35>0,B35/G35,0) -> 0.068965517 | J35: =IF(G35>0,C35/G35,0) -> 0.24137931 | K35: =IF(G35>0,D35/G35,0) -> 0.086206897 | L35: =IF(G35>0,E35/G35,0) -> 0.17241379 | M35: =IF(G35>0,F35/G35,0) -> 0.43103448
A36: 赛维斯职场 | B36: =COUNTIFS(复贷评级明细!$B:$B,"*"&A36&"*",复贷评级明细!$AO:$AO,"MOB1-",复贷评级明细!$O:$O,">="&20) -> 3 | C36: =COUNTIFS(复贷评级明细!$B:$B,"*"&A36&"*",复贷评级明细!$AO:$AO,"MOB1-3",复贷评级明细!$O:$O,">="&20) -> 47 | D36: =COUNTIFS(复贷评级明细!$B:$B,"*"&A36&"*",复贷评级明细!$AO:$AO,"MOB3-6",复贷评级明细!$O:$O,">="&20) -> 3 | E36: =COUNTIFS(复贷评级明细!$B:$B,"*"&A36&"*",复贷评级明细!$AO:$AO,"MOB6-12",复贷评级明细!$O:$O,">="&20) -> 7 | F36: =COUNTIFS(复贷评级明细!$B:$B,"*"&A36&"*",复贷评级明细!$AO:$AO,"MOB12+",复贷评级明细!$O:$O,">="&20) -> 29 | G36: =SUM(B36:F36) -> 89 | H36: =IFERROR(AVERAGEIFS(复贷评级明细!$G:$G,复贷评级明细!$B:$B,"*"&A36&"*",复贷评级明细!$O:$O,">="&20),0) -> 234.70787 | I36: =IF(G36>0,B36/G36,0) -> 0.033707865 | J36: =IF(G36>0,C36/G36,0) -> 0.52808989 | K36: =IF(G36>0,D36/G36,0) -> 0.033707865 | L36: =IF(G36>0,E36/G36,0) -> 0.078651685 | M36: =IF(G36>0,F36/G36,0) -> 0.3258427
A37: 整体 | B37: =SUM(B25:B36) -> 22 | C37: =SUM(C25:C36) -> 249 | D37: =SUM(D25:D36) -> 93 | E37: =SUM(E25:E36) -> 110 | F37: =SUM(F25:F36) -> 165 | G37: =SUM(G25:G36) -> 639 | H37: =IFERROR(AVERAGEIFS(复贷评级明细!$G:$G,复贷评级明细!$O:$O,">="&20),0) -> 256.46322 | I37: =IF(G37>0,B37/G37,0) -> 0.034428795 | J37: =IF(G37>0,C37/G37,0) -> 0.38967136 | K37: =IF(G37>0,D37/G37,0) -> 0.14553991 | L37: =IF(G37>0,E37/G37,0) -> 0.17214397 | M37: =IF(G37>0,F37/G37,0) -> 0.25821596

Sheet 首贷评级明细
A1: 坐席类型 | B1: 职场名称 | C1: 坐席id | D1: 坐席名称 | E1: 210客户池首次外呼日期 | F1: 金条业务首次外呼日期 | G1: 210客户池在职天数 | H1: 金条业务线在职日期 | I1: 最近一次有效外呼时间 | J1: 接通用户数 | K1: 接通话单数 | L1: 有效接通数话单数 | M1: 近30天累计通时（秒） | N1: 近30天累计有效通时 | O1: 近30天外呼天数（通话时长>30分钟天数） | P1: 近30日累计转化首贷用户数 | Q1: 近30日累计转化首贷GMV | R1: 近30日累计转化t0首贷GMV | S1: 近30日累计转化复贷用户数 | T1: 近30日累计转化复贷订单数 | U1: 近30日累计转化复贷GMV | V1: 近30日累计转化t0复贷GMV | W1: 近30日累计转化GMV | X1: 超7天未上线 | Y1: 外呼天数不足22天 | Z1: 是否参评 | AA1: 连续3天未上线预警 | AB1: 个人ATT(秒) | AC1: 转化率% | AD1: 首贷件均(元) | AE1: T0首贷GMV(万) | AF1: 日均有效通时(分钟) | AG1: ATT得分 | AH1: 转化率得分 | AI1: T0GMV得分 | AJ1: 通时得分 | AK1: 综合得分 | AL1: 参评排名 | AM1: 等级 | AN1: 司龄分段
A2: 首贷 | B2: 管户金条-赛维斯职场 | C2: 601489 | D2: 于天赋 | E2: 45127.408 | F2: 45127.408 | G2: 1027 | H2: 1027 | I2: 46154.65 | J2: 1355 | K2: 1378 | L2: 628 | M2: 54355 | N2: 43117 | O2: 22 | P2: 13 | Q2: 172000 | R2: 165900 | S2: 0 | T2: 0 | W2: 172000 | X2: =IF(OR(I2="",说明首页!$C$3-INT(I2)>7),"是","否") -> 否 | Y2: =IF(OR(O2="",O2<22),"是","否") -> 否 | Z2: =IF(AND(X2="否",Y2="否"),"是","否") -> 是 | AA2: =IF(OR(I2="",说明首页!$C$3-INT(I2)>=3),"是","否") -> 否 | AB2: =IFERROR(IF(L2>0,N2/L2,0),0) -> 68.657643 | AC2: =IFERROR(IF(J2>0,P2/J2*100,0),0) -> 0.95940959 | AD2: =IFERROR(IF(AND(P2<>"",P2>0),Q2/P2,0),0) -> 13230.769 | AE2: =IFERROR(IF(R2="",0,R2/10000),0) -> 16.59 | AF2: =IFERROR(IF(O2>0,N2/O2/60,0),0) -> 32.664394 | AG2: =IF(Z2="是",COUNTIFS($Z$2:$Z$4650,"是",$AB$2:$AB$4650,"<"&AB2)/COUNTIF($Z$2:$Z$4650,"是")*100,"") -> 6.2146893 | AH2: =IF(Z2="是",COUNTIFS($Z$2:$Z$4650,"是",$AC$2:$AC$4650,"<"&AC2)/COUNTIF($Z$2:$Z$4650,"是")*100,"") -> 57.250471 | AI2: =IF(Z2="是",COUNTIFS($Z$2:$Z$4650,"是",$AE$2:$AE$4650,"<"&AE2)/COUNTIF($Z$2:$Z$4650,"是")*100,"") -> 6.5913371 | AJ2: =IF(Z2="是",COUNTIFS($Z$2:$Z$4650,"是",$AF$2:$AF$4650,"<"&AF2)/COUNTIF($Z$2:$Z$4650,"是")*100,"") -> 0 | AK2: =IF(Z2="是",ROUND(AG2*0.15+AH2*0.45+AI2*0.2+AJ2*0.2,2),"") -> 28.01 | AL2: =IF(Z2="是",COUNTIFS($Z$2:$Z$4650,"是",$AK$2:$AK$4650,">"&AK2)+1,"") -> 432 | AM2: =IF(Z2<>"是","非参评",IF(AND(AL2<=COUNTIF($Z$2:$Z$4650,"是")*0.2,AC2>MEDIAN(IF($Z$2:$Z$4650="是",$AC$2:$AC$4650))),"S",IF(AL2<=COUNTIF($Z$2:$Z$4650,"是")*0.5,"A",IF(AL2<=COUNTIF($Z$2:$Z$4650,"是")*0.8,"B","C")))) -> C | AN2: =IF(G2="","无数据",IF(G2<30,"MOB1-",IF(G2<90,"MOB1-3",IF(G2<180,"MOB3-6",IF(G2<365,"MOB6-12","MOB12+"))))) -> MOB12+
A3: 首贷 | B3: 管户金条-毛毛虫职场 | C3: 605334 | D3: 徐文雁 | E3: 46119.594 | F3: 46119.594 | G3: 35 | H3: 35 | I3: 46154.811 | J3: 6053 | K3: 6724 | L3: 1778 | M3: 215849 | N3: 146366 | O3: 26 | P3: 74 | Q3: 2550500 | R3: 1730500 | S3: 9 | T3: 13 | U3: 28600 | V3: 21500 | W3: 2579100 | X3: =IF(OR(I3="",说明首页!$C$3-INT(I3)>7),"是","否") -> 否 | Y3: =IF(OR(O3="",O3<22),"是","否") -> 否 | Z3: =IF(AND(X3="否",Y3="否"),"是","否") -> 是 | AA3: =IF(OR(I3="",说明首页!$C$3-INT(I3)>=3),"是","否") -> 否 | AB3: =IFERROR(IF(L3>0,N3/L3,0),0) -> 82.320585 | AC3: =IFERROR(IF(J3>0,P3/J3*100,0),0) -> 1.2225343 | AD3: =IFERROR(IF(AND(P3<>"",P3>0),Q3/P3,0),0) -> 34466.216 | AE3: =IFERROR(IF(R3="",0,R3/10000),0) -> 173.05 | AF3: =IFERROR(IF(O3>0,N3/O3/60,0),0) -> 93.824359 | AG3: =IF(Z3="是",COUNTIFS($Z$2:$Z$4650,"是",$AB$2:$AB$4650,"<"&AB3)/COUNTIF($Z$2:$Z$4650,"是")*100,"") -> 31.26177 | AH3: =IF(Z3="是",COUNTIFS($Z$2:$Z$4650,"是",$AC$2:$AC$4650,"<"&AC3)/COUNTIF($Z$2:$Z$4650,"是")*100,"") -> 78.719397 | AI3: =IF(Z3="是",COUNTIFS($Z$2:$Z$4650,"是",$AE$2:$AE$4650,"<"&AE3)/COUNTIF($Z$2:$Z$4650,"是")*100,"") -> 69.491525 | AJ3: =IF(Z3="是",COUNTIFS($Z$2:$Z$4650,"是",$AF$2:$AF$4650,"<"&AF3)/COUNTIF($Z$2:$Z$4650,"是")*100,"") -> 13.747646 | AK3: =IF(Z3="是",ROUND(AG3*0.15+AH3*0.45+AI3*0.2+AJ3*0.2,2),"") -> 56.76 | AL3: =IF(Z3="是",COUNTIFS($Z$2:$Z$4650,"是",$AK$2:$AK$4650,">"&AK3)+1,"") -> 211 | AM3: =IF(Z3<>"是","非参评",IF(AND(AL3<=COUNTIF($Z$2:$Z$4650,"是")*0.2,AC3>MEDIAN(IF($Z$2:$Z$4650="是",$AC$2:$AC$4650))),"S",IF(AL3<=COUNTIF($Z$2:$Z$4650,"是")*0.5,"A",IF(AL3<=COUNTIF($Z$2:$Z$4650,"是")*0.8,"B","C")))) -> A | AN3: =IF(G3="","无数据",IF(G3<30,"MOB1-",IF(G3<90,"MOB1-3",IF(G3<180,"MOB3-6",IF(G3<365,"MOB6-12","MOB12+"))))) -> MOB1-3
A4: 首贷 | B4: 管户金条-毅航合肥职场 | C4: 605420 | D4: 孙靖 | E4: 44608.658 | F4: 44608.658 | G4: 1546 | H4: 1546 | I4: 46154.863 | J4: 5970 | K4: 6378 | L4: 2167 | M4: 235325 | N4: 168746 | O4: 26 | P4: 53 | Q4: 3834700 | R4: 2337400 | S4: 4 | T4: 4 | U4: 311500 | V4: 300000 | W4: 4146200 | X4: =IF(OR(I4="",说明首页!$C$3-INT(I4)>7),"是","否") -> 否 | Y4: =IF(OR(O4="",O4<22),"是","否") -> 否 | Z4: =IF(AND(X4="否",Y4="否"),"是","否") -> 是 | AA4: =IF(OR(I4="",说明首页!$C$3-INT(I4)>=3),"是","否") -> 否 | AB4: =IFERROR(IF(L4>0,N4/L4,0),0) -> 77.870789 | AC4: =IFERROR(IF(J4>0,P4/J4*100,0),0) -> 0.88777219 | AD4: =IFERROR(IF(AND(P4<>"",P4>0),Q4/P4,0),0) -> 72352.83 | AE4: =IFERROR(IF(R4="",0,R4/10000),0) -> 233.74 | AF4: =IFERROR(IF(O4>0,N4/O4/60,0),0) -> 108.17051 | AG4: =IF(Z4="是",COUNTIFS($Z$2:$Z$4650,"是",$AB$2:$AB$4650,"<"&AB4)/COUNTIF($Z$2:$Z$4650,"是")*100,"") -> 22.59887 | AH4: =IF(Z4="是",COUNTIFS($Z$2:$Z$4650,"是",$AC$2:$AC$4650,"<"&AC4)/COUNTIF($Z$2:$Z$4650,"是")*100,"") -> 49.905838 | AI4: =IF(Z4="是",COUNTIFS($Z$2:$Z$4650,"是",$AE$2:$AE$4650,"<"&AE4)/COUNTIF($Z$2:$Z$4650,"是")*100,"") -> 83.050847 | AJ4: =IF(Z4="是",COUNTIFS($Z$2:$Z$4650,"是",$AF$2:$AF$4650,"<"&AF4)/COUNTIF($Z$2:$Z$4650,"是")*100,"") -> 37.288136 | AK4: =IF(Z4="是",ROUND(AG4*0.15+AH4*0.45+AI4*0.2+AJ4*0.2,2),"") -> 49.92 | AL4: =IF(Z4="是",COUNTIFS($Z$2:$Z$4650,"是",$AK$2:$AK$4650,">"&AK4)+1,"") -> 263 | AM4: =IF(Z4<>"是","非参评",IF(AND(AL4<=COUNTIF($Z$2:$Z$4650,"是")*0.2,AC4>MEDIAN(IF($Z$2:$Z$4650="是",$AC$2:$AC$4650))),"S",IF(AL4<=COUNTIF($Z$2:$Z$4650,"是")*0.5,"A",IF(AL4<=COUNTIF($Z$2:$Z$4650,"是")*0.8,"B","C")))) -> A | AN4: =IF(G4="","无数据",IF(G4<30,"MOB1-",IF(G4<90,"MOB1-3",IF(G4<180,"MOB3-6",IF(G4<365,"MOB6-12","MOB12+"))))) -> MOB12+
A5: 首贷 | B5: 管户金条-毛毛虫职场 | C5: 606024 | D5: 李敏 | E5: 45750.762 | F5: 45750.762 | G5: 404 | H5: 404 | I5: 46154.815 | J5: 3606 | K5: 4092 | L5: 1568 | M5: 176480 | N5: 139195 | O5: 21 | P5: 26 | Q5: 1211800 | R5: 790600 | S5: 2 | T5: 2 | U5: 68900 | W5: 1280700 | X5: =IF(OR(I5="",说明首页!$C$3-INT(I5)>7),"是","否") -> 否 | Y5: =IF(OR(O5="",O5<22),"是","否") -> 是 | Z5: =IF(AND(X5="否",Y5="否"),"是","否") -> 否 | AA5: =IF(OR(I5="",说明首页!$C$3-INT(I5)>=3),"是","否") -> 否 | AB5: =IFERROR(IF(L5>0,N5/L5,0),0) -> 88.772321 | AC5: =IFERROR(IF(J5>0,P5/J5*100,0),0) -> 0.72102052 | AD5: =IFERROR(IF(AND(P5<>"",P5>0),Q5/P5,0),0) -> 46607.692 | AE5: =IFERROR(IF(R5="",0,R5/10000),0) -> 79.06 | AF5: =IFERROR(IF(O5>0,N5/O5/60,0),0) -> 110.47222 | AG5: =IF(Z5="是",COUNTIFS($Z$2:$Z$4650,"是",$AB$2:$AB$4650,"<"&AB5)/COUNTIF($Z$2:$Z$4650,"是")*100,"") | AH5: =IF(Z5="是",COUNTIFS($Z$2:$Z$4650,"是",$AC$2:$AC$4650,"<"&AC5)/COUNTIF($Z$2:$Z$4650,"是")*100,"") | AI5: =IF(Z5="是",COUNTIFS($Z$2:$Z$4650,"是",$AE$2:$AE$4650,"<"&AE5)/COUNTIF($Z$2:$Z$4650,"是")*100,"") | AJ5: =IF(Z5="是",COUNTIFS($Z$2:$Z$4650,"是",$AF$2:$AF$4650,"<"&AF5)/COUNTIF($Z$2:$Z$4650,"是")*100,"") | AK5: =IF(Z5="是",ROUND(AG5*0.15+AH5*0.45+AI5*0.2+AJ5*0.2,2),"") | AL5: =IF(Z5="是",COUNTIFS($Z$2:$Z$4650,"是",$AK$2:$AK$4650,">"&AK5)+1,"") | AM5: =IF(Z5<>"是","非参评",IF(AND(AL5<=COUNTIF($Z$2:$Z$4650,"是")*0.2,AC5>MEDIAN(IF($Z$2:$Z$4650="是",$AC$2:$AC$4650))),"S",IF(AL5<=COUNTIF($Z$2:$Z$4650,"是")*0.5,"A",IF(AL5<=COUNTIF($Z$2:$Z$4650,"是")*0.8,"B","C")))) -> 非参评 | AN5: =IF(G5="","无数据",IF(G5<30,"MOB1-",IF(G5<90,"MOB1-3",IF(G5<180,"MOB3-6",IF(G5<365,"MOB6-12","MOB12+"))))) -> MOB12+
A6: 首贷 | B6: 管户金条-毛毛虫职场 | C6: 606240 | D6: 万文娟 | E6: 44653.392 | F6: 44653.392 | G6: 1501 | H6: 1501 | I6: 46154.81 | J6: 3223 | K6: 3524 | L6: 1504 | M6: 173142 | N6: 142411 | O6: 23 | P6: 17 | Q6: 1216000 | R6: 1213000 | S6: 1 | T6: 1 | U6: 1000 | V6: 1000 | W6: 1217000 | X6: =IF(OR(I6="",说明首页!$C$3-INT(I6)>7),"是","否") -> 否 | Y6: =IF(OR(O6="",O6<22),"是","否") -> 否 | Z6: =IF(AND(X6="否",Y6="否"),"是","否") -> 是 | AA6: =IF(OR(I6="",说明首页!$C$3-INT(I6)>=3),"是","否") -> 否 | AB6: =IFERROR(IF(L6>0,N6/L6,0),0) -> 94.688165 | AC6: =IFERROR(IF(J6>0,P6/J6*100,0),0) -> 0.52745889 | AD6: =IFERROR(IF(AND(P6<>"",P6>0),Q6/P6,0),0) -> 71529.412 | AE6: =IFERROR(IF(R6="",0,R6/10000),0) -> 121.3 | AF6: =IFERROR(IF(O6>0,N6/O6/60,0),0) -> 103.19638 | AG6: =IF(Z6="是",COUNTIFS($Z$2:$Z$4650,"是",$AB$2:$AB$4650,"<"&AB6)/COUNTIF($Z$2:$Z$4650,"是")*100,"") -> 67.608286 | AH6: =IF(Z6="是",COUNTIFS($Z$2:$Z$4650,"是",$AC$2:$AC$4650,"<"&AC6)/COUNTIF($Z$2:$Z$4650,"是")*100,"") -> 9.9811676 | AI6: =IF(Z6="是",COUNTIFS($Z$2:$Z$4650,"是",$AE$2:$AE$4650,"<"&AE6)/COUNTIF($Z$2:$Z$4650,"是")*100,"") -> 49.52919 | AJ6: =IF(Z6="是",COUNTIFS($Z$2:$Z$4650,"是",$AF$2:$AF$4650,"<"&AF6)/COUNTIF($Z$2:$Z$4650,"是")*100,"") -> 27.683616 | AK6: =IF(Z6="是",ROUND(AG6*0.15+AH6*0.45+AI6*0.2+AJ6*0.2,2),"") -> 30.08 | AL6: =IF(Z6="是",COUNTIFS($Z$2:$Z$4650,"是",$AK$2:$AK$4650,">"&AK6)+1,"") -> 419 | AM6: =IF(Z6<>"是","非参评",IF(AND(AL6<=COUNTIF($Z$2:$Z$4650,"是")*0.2,AC6>MEDIAN(IF($Z$2:$Z$4650="是",$AC$2:$AC$4650))),"S",IF(AL6<=COUNTIF($Z$2:$Z$4650,"是")*0.5,"A",IF(AL6<=COUNTIF($Z$2:$Z$4650,"是")*0.8,"B","C")))) -> B | AN6: =IF(G6="","无数据",IF(G6<30,"MOB1-",IF(G6<90,"MOB1-3",IF(G6<180,"MOB3-6",IF(G6<365,"MOB6-12","MOB12+"))))) -> MOB12+
