Workbook

Sheet 清洗后明细
A1: 月份 | B1: 业务线 | C1: 首复贷 | D1: 作业模式 | E1: 供应商 | F1: 下发用户 | G1: 贷款用户 | H1: 贷款金额 | I1: 线路费 | J1: 还款系数 | K1: 税率 | L1: 费效成本 | M1: 到手薪资 | N1: 数据人力 | O1: 佣金部分 | P1: 人工占比% | Q1: 转化率% | R1: 户均贷款 | S1: 单用户费效 | T1: 单用户薪资 | U1: 元/人/月 | V1: 线路费占比% | W1: 有效分佣率 | X1: 真实人工x70%
A2: 2025-12 | B2: 金条 | C2: 首贷 | D2: 人机 | E2: 零犀伽玛 | F2: 2038874 | G2: 6006 | H2: 92456600 | I2: 197432 | J2: 0.07 | K2: 1.068 | L2: 562995 | M2: 342288 | N2: 30 | O2: =IF(L2>0,L2-I2,"") | P2: =IF(AND(M2>0,L2>0),M2/L2*100,"") | Q2: =IF(AND(G2>0,F2>0),G2/F2*100,"") | R2: =IF(AND(H2>0,G2>0),H2/G2,"") | S2: =IF(AND(L2>0,G2>0),L2/G2,"") | T2: =IF(AND(M2>0,G2>0),M2/G2,"") | U2: =IF(AND(M2>0,N2>0),M2/N2,"") | V2: =IF(AND(I2>=0,L2>0),I2/L2*100,"") | W2: =IF(AND(L2>0,H2>0,J2>0),(L2-I2)/(H2*J2),"") | X2: =IF(AND(M2>0,N2>0),M2/N2*0.7,"")
A3: 2025-12 | B3: 金条 | C3: 首贷 | D3: 人机 | E3: 零犀 | F3: 8089614 | G3: 28195 | H3: 500741300 | I3: 857516 | J3: 0.07 | K3: 1.068 | L3: 3102415 | M3: 2101966 | N3: 81 | O3: =IF(L3>0,L3-I3,"") | P3: =IF(AND(M3>0,L3>0),M3/L3*100,"") | Q3: =IF(AND(G3>0,F3>0),G3/F3*100,"") | R3: =IF(AND(H3>0,G3>0),H3/G3,"") | S3: =IF(AND(L3>0,G3>0),L3/G3,"") | T3: =IF(AND(M3>0,G3>0),M3/G3,"") | U3: =IF(AND(M3>0,N3>0),M3/N3,"") | V3: =IF(AND(I3>=0,L3>0),I3/L3*100,"") | W3: =IF(AND(L3>0,H3>0,J3>0),(L3-I3)/(H3*J3),"") | X3: =IF(AND(M3>0,N3>0),M3/N3*0.7,"")
A4: 2025-12 | B4: 金条 | C4: 复贷 | D4: 人机 | E4: 零犀 | F4: 3118729 | G4: 13855 | H4: 584973900 | I4: 242156 | J4: 0.36 | K4: 1.068 | L4: 666176 | M4: 397023 | N4: 13 | O4: =IF(L4>0,L4-I4,"") | P4: =IF(AND(M4>0,L4>0),M4/L4*100,"") | Q4: =IF(AND(G4>0,F4>0),G4/F4*100,"") | R4: =IF(AND(H4>0,G4>0),H4/G4,"") | S4: =IF(AND(L4>0,G4>0),L4/G4,"") | T4: =IF(AND(M4>0,G4>0),M4/G4,"") | U4: =IF(AND(M4>0,N4>0),M4/N4,"") | V4: =IF(AND(I4>=0,L4>0),I4/L4*100,"") | W4: =IF(AND(L4>0,H4>0,J4>0),(L4-I4)/(H4*J4),"") | X4: =IF(AND(M4>0,N4>0),M4/N4*0.7,"")
A5: 2025-12 | B5: 金条 | C5: 首贷 | D5: 人机 | E5: 零犀毛毛虫 | F5: 1572247 | G5: 5317 | H5: 92059900 | I5: 171887 | J5: 0.07 | K5: 1.068 | L5: 554755 | M5: 358491 | N5: 32 | O5: =IF(L5>0,L5-I5,"") | P5: =IF(AND(M5>0,L5>0),M5/L5*100,"") | Q5: =IF(AND(G5>0,F5>0),G5/F5*100,"") | R5: =IF(AND(H5>0,G5>0),H5/G5,"") | S5: =IF(AND(L5>0,G5>0),L5/G5,"") | T5: =IF(AND(M5>0,G5>0),M5/G5,"") | U5: =IF(AND(M5>0,N5>0),M5/N5,"") | V5: =IF(AND(I5>=0,L5>0),I5/L5*100,"") | W5: =IF(AND(L5>0,H5>0,J5>0),(L5-I5)/(H5*J5),"") | X5: =IF(AND(M5>0,N5>0),M5/N5*0.7,"")
A6: 2025-12 | B6: 金条 | C6: 首贷 | D6: 人机 | E6: 零犀赛维斯 | F6: 1343102 | G6: 4569 | H6: 74540300 | I6: 148613 | J6: 0.07 | K6: 1.068 | L6: 455865 | M6: 287689 | N6: 23 | O6: =IF(L6>0,L6-I6,"") | P6: =IF(AND(M6>0,L6>0),M6/L6*100,"") | Q6: =IF(AND(G6>0,F6>0),G6/F6*100,"") | R6: =IF(AND(H6>0,G6>0),H6/G6,"") | S6: =IF(AND(L6>0,G6>0),L6/G6,"") | T6: =IF(AND(M6>0,G6>0),M6/G6,"") | U6: =IF(AND(M6>0,N6>0),M6/N6,"") | V6: =IF(AND(I6>=0,L6>0),I6/L6*100,"") | W6: =IF(AND(L6>0,H6>0,J6>0),(L6-I6)/(H6*J6),"") | X6: =IF(AND(M6>0,N6>0),M6/N6*0.7,"")
A7: 2025-12 | B7: 金条 | C7: 首贷 | D7: 人机 | E7: 零犀毅航 | F7: 2981407 | G7: 10029 | H7: 174547100 | I7: 306773 | J7: 0.07 | K7: 1.068 | L7: 1087956 | M7: 731445 | N7: 49 | O7: =IF(L7>0,L7-I7,"") | P7: =IF(AND(M7>0,L7>0),M7/L7*100,"") | Q7: =IF(AND(G7>0,F7>0),G7/F7*100,"") | R7: =IF(AND(H7>0,G7>0),H7/G7,"") | S7: =IF(AND(L7>0,G7>0),L7/G7,"") | T7: =IF(AND(M7>0,G7>0),M7/G7,"") | U7: =IF(AND(M7>0,N7>0),M7/N7,"") | V7: =IF(AND(I7>=0,L7>0),I7/L7*100,"") | W7: =IF(AND(L7>0,H7>0,J7>0),(L7-I7)/(H7*J7),"") | X7: =IF(AND(M7>0,N7>0),M7/N7*0.7,"")
A8: 2025-12 | B8: 金条 | C8: 复贷 | D8: 人机 | E8: 毛毛虫 | F8: 1041009 | G8: 5086 | H8: 226073700 | I8: 97778 | J8: 0.36 | K8: 1.068 | L8: 257543 | M8: 149593 | O8: =IF(L8>0,L8-I8,"") | P8: =IF(AND(M8>0,L8>0),M8/L8*100,"") | Q8: =IF(AND(G8>0,F8>0),G8/F8*100,"") | R8: =IF(AND(H8>0,G8>0),H8/G8,"") | S8: =IF(AND(L8>0,G8>0),L8/G8,"") | T8: =IF(AND(M8>0,G8>0),M8/G8,"") | U8: =IF(AND(M8>0,N8>0),M8/N8,"") | V8: =IF(AND(I8>=0,L8>0),I8/L8*100,"") | W8: =IF(AND(L8>0,H8>0,J8>0),(L8-I8)/(H8*J8),"") | X8: =IF(AND(M8>0,N8>0),M8/N8*0.7,"")
A9: 2025-12 | B9: 金条 | C9: 首贷 | D9: 人机 | E9: 赛维斯 | F9: 1941415 | G9: 6177 | H9: 95096000 | I9: 221692 | J9: 0.07 | K9: 1.068 | L9: 592297 | M9: 347008 | N9: 26 | O9: =IF(L9>0,L9-I9,"") | P9: =IF(AND(M9>0,L9>0),M9/L9*100,"") | Q9: =IF(AND(G9>0,F9>0),G9/F9*100,"") | R9: =IF(AND(H9>0,G9>0),H9/G9,"") | S9: =IF(AND(L9>0,G9>0),L9/G9,"") | T9: =IF(AND(M9>0,G9>0),M9/G9,"") | U9: =IF(AND(M9>0,N9>0),M9/N9,"") | V9: =IF(AND(I9>=0,L9>0),I9/L9*100,"") | W9: =IF(AND(L9>0,H9>0,J9>0),(L9-I9)/(H9*J9),"") | X9: =IF(AND(M9>0,N9>0),M9/N9*0.7,"")
A10: 2025-12 | B10: 金条 | C10: 复贷 | D10: 人机 | E10: 赛维斯 | F10: 754936 | G10: 3827 | H10: 166906700 | I10: 79638 | J10: 0.36 | K10: 1.068 | L10: 190140 | M10: 103466 | N10: 12 | O10: =IF(L10>0,L10-I10,"") | P10: =IF(AND(M10>0,L10>0),M10/L10*100,"") | Q10: =IF(AND(G10>0,F10>0),G10/F10*100,"") | R10: =IF(AND(H10>0,G10>0),H10/G10,"") | S10: =IF(AND(L10>0,G10>0),L10/G10,"") | T10: =IF(AND(M10>0,G10>0),M10/G10,"") | U10: =IF(AND(M10>0,N10>0),M10/N10,"") | V10: =IF(AND(I10>=0,L10>0),I10/L10*100,"") | W10: =IF(AND(L10>0,H10>0,J10>0),(L10-I10)/(H10*J10),"") | X10: =IF(AND(M10>0,N10>0),M10/N10*0.7,"")
A11: 2025-12 | B11: 金条 | C11: 首贷 | D11: 人工 | E11: 博岳石家庄 | F11: 183762 | G11: 2943 | H11: 100186300 | I11: 28178 | J11: 0.07 | K11: 1.068 | L11: 453933 | M11: 398647 | N11: 42 | O11: =IF(L11>0,L11-I11,"") | P11: =IF(AND(M11>0,L11>0),M11/L11*100,"") | Q11: =IF(AND(G11>0,F11>0),G11/F11*100,"") | R11: =IF(AND(H11>0,G11>0),H11/G11,"") | S11: =IF(AND(L11>0,G11>0),L11/G11,"") | T11: =IF(AND(M11>0,G11>0),M11/G11,"") | U11: =IF(AND(M11>0,N11>0),M11/N11,"") | V11: =IF(AND(I11>=0,L11>0),I11/L11*100,"") | W11: =IF(AND(L11>0,H11>0,J11>0),(L11-I11)/(H11*J11),"") | X11: =IF(AND(M11>0,N11>0),M11/N11*0.7,"")
A12: 2025-12 | B12: 金条 | C12: 复贷 | D12: 人工 | E12: 博岳石家庄 | F12: 96381 | G12: 4660 | H12: 168733200 | I12: 15541 | J12: 0.36 | K12: 1.068 | L12: 164995 | M12: 139938 | N12: 54 | O12: =IF(L12>0,L12-I12,"") | P12: =IF(AND(M12>0,L12>0),M12/L12*100,"") | Q12: =IF(AND(G12>0,F12>0),G12/F12*100,"") | R12: =IF(AND(H12>0,G12>0),H12/G12,"") | S12: =IF(AND(L12>0,G12>0),L12/G12,"") | T12: =IF(AND(M12>0,G12>0),M12/G12,"") | U12: =IF(AND(M12>0,N12>0),M12/N12,"") | V12: =IF(AND(I12>=0,L12>0),I12/L12*100,"") | W12: =IF(AND(L12>0,H12>0,J12>0),(L12-I12)/(H12*J12),"") | X12: =IF(AND(M12>0,N12>0),M12/N12*0.7,"")
A13: 2025-12 | B13: 金条 | C13: 首贷 | D13: 人工 | E13: 伽玛 | F13: 261882 | G13: 3944 | H13: 142868400 | I13: 47100 | J13: 0.07 | K13: 1.068 | L13: 648910 | M13: 563493 | N13: 76 | O13: =IF(L13>0,L13-I13,"") | P13: =IF(AND(M13>0,L13>0),M13/L13*100,"") | Q13: =IF(AND(G13>0,F13>0),G13/F13*100,"") | R13: =IF(AND(H13>0,G13>0),H13/G13,"") | S13: =IF(AND(L13>0,G13>0),L13/G13,"") | T13: =IF(AND(M13>0,G13>0),M13/G13,"") | U13: =IF(AND(M13>0,N13>0),M13/N13,"") | V13: =IF(AND(I13>=0,L13>0),I13/L13*100,"") | W13: =IF(AND(L13>0,H13>0,J13>0),(L13-I13)/(H13*J13),"") | X13: =IF(AND(M13>0,N13>0),M13/N13*0.7,"")
A14: 2025-12 | B14: 金条 | C14: 复贷 | D14: 人工 | E14: 伽玛 | F14: 218023 | G14: 11078 | H14: 402258300 | I14: 44314 | J14: 0.36 | K14: 1.068 | L14: 391833 | M14: 325391 | N14: 88 | O14: =IF(L14>0,L14-I14,"") | P14: =IF(AND(M14>0,L14>0),M14/L14*100,"") | Q14: =IF(AND(G14>0,F14>0),G14/F14*100,"") | R14: =IF(AND(H14>0,G14>0),H14/G14,"") | S14: =IF(AND(L14>0,G14>0),L14/G14,"") | T14: =IF(AND(M14>0,G14>0),M14/G14,"") | U14: =IF(AND(M14>0,N14>0),M14/N14,"") | V14: =IF(AND(I14>=0,L14>0),I14/L14*100,"") | W14: =IF(AND(L14>0,H14>0,J14>0),(L14-I14)/(H14*J14),"") | X14: =IF(AND(M14>0,N14>0),M14/N14*0.7,"")
A15: 2025-12 | B15: 金条 | C15: 首贷 | D15: 人工 | E15: 广达陕西 | F15: 102006 | G15: 1553 | H15: 50760600 | I15: 16148 | J15: 0.07 | K15: 1.068 | L15: 226020 | M15: 196509 | N15: 28 | O15: =IF(L15>0,L15-I15,"") | P15: =IF(AND(M15>0,L15>0),M15/L15*100,"") | Q15: =IF(AND(G15>0,F15>0),G15/F15*100,"") | R15: =IF(AND(H15>0,G15>0),H15/G15,"") | S15: =IF(AND(L15>0,G15>0),L15/G15,"") | T15: =IF(AND(M15>0,G15>0),M15/G15,"") | U15: =IF(AND(M15>0,N15>0),M15/N15,"") | V15: =IF(AND(I15>=0,L15>0),I15/L15*100,"") | W15: =IF(AND(L15>0,H15>0,J15>0),(L15-I15)/(H15*J15),"") | X15: =IF(AND(M15>0,N15>0),M15/N15*0.7,"")
A16: 2025-12 | B16: 金条 | C16: 复贷 | D16: 人工 | E16: 广达陕西 | F16: 65815 | G16: 3338 | H16: 103037500 | I16: 12893 | J16: 0.36 | K16: 1.068 | L16: 100148 | M16: 81699 | N16: 34 | O16: =IF(L16>0,L16-I16,"") | P16: =IF(AND(M16>0,L16>0),M16/L16*100,"") | Q16: =IF(AND(G16>0,F16>0),G16/F16*100,"") | R16: =IF(AND(H16>0,G16>0),H16/G16,"") | S16: =IF(AND(L16>0,G16>0),L16/G16,"") | T16: =IF(AND(M16>0,G16>0),M16/G16,"") | U16: =IF(AND(M16>0,N16>0),M16/N16,"") | V16: =IF(AND(I16>=0,L16>0),I16/L16*100,"") | W16: =IF(AND(L16>0,H16>0,J16>0),(L16-I16)/(H16*J16),"") | X16: =IF(AND(M16>0,N16>0),M16/N16*0.7,"")
A17: 2025-12 | B17: 金条 | C17: 首贷 | D17: 人工 | E17: 翰锐曲靖 | F17: 86514 | G17: 1249 | H17: 48331400 | I17: 13458 | J17: 0.07 | K17: 1.068 | L17: 226712 | M17: 199676 | N17: 21 | O17: =IF(L17>0,L17-I17,"") | P17: =IF(AND(M17>0,L17>0),M17/L17*100,"") | Q17: =IF(AND(G17>0,F17>0),G17/F17*100,"") | R17: =IF(AND(H17>0,G17>0),H17/G17,"") | S17: =IF(AND(L17>0,G17>0),L17/G17,"") | T17: =IF(AND(M17>0,G17>0),M17/G17,"") | U17: =IF(AND(M17>0,N17>0),M17/N17,"") | V17: =IF(AND(I17>=0,L17>0),I17/L17*100,"") | W17: =IF(AND(L17>0,H17>0,J17>0),(L17-I17)/(H17*J17),"") | X17: =IF(AND(M17>0,N17>0),M17/N17*0.7,"")
A18: 2025-12 | B18: 金条 | C18: 复贷 | D18: 人工 | E18: 翰锐曲靖 | F18: 283201 | G18: 13663 | H18: 384957000 | I18: 44832 | J18: 0.36 | K18: 1.068 | L18: 364143 | M18: 298981 | N18: 66 | O18: =IF(L18>0,L18-I18,"") | P18: =IF(AND(M18>0,L18>0),M18/L18*100,"") | Q18: =IF(AND(G18>0,F18>0),G18/F18*100,"") | R18: =IF(AND(H18>0,G18>0),H18/G18,"") | S18: =IF(AND(L18>0,G18>0),L18/G18,"") | T18: =IF(AND(M18>0,G18>0),M18/G18,"") | U18: =IF(AND(M18>0,N18>0),M18/N18,"") | V18: =IF(AND(I18>=0,L18>0),I18/L18*100,"") | W18: =IF(AND(L18>0,H18>0,J18>0),(L18-I18)/(H18*J18),"") | X18: =IF(AND(M18>0,N18>0),M18/N18*0.7,"")
A19: 2025-12 | B19: 金条 | C19: 复贷 | D19: 人工 | E19: 华啸 | F19: 130372 | G19: 6160 | H19: 218499100 | I19: 19837 | J19: 0.36 | K19: 1.068 | L19: 213901 | M19: 181708 | N19: 50 | O19: =IF(L19>0,L19-I19,"") | P19: =IF(AND(M19>0,L19>0),M19/L19*100,"") | Q19: =IF(AND(G19>0,F19>0),G19/F19*100,"") | R19: =IF(AND(H19>0,G19>0),H19/G19,"") | S19: =IF(AND(L19>0,G19>0),L19/G19,"") | T19: =IF(AND(M19>0,G19>0),M19/G19,"") | U19: =IF(AND(M19>0,N19>0),M19/N19,"") | V19: =IF(AND(I19>=0,L19>0),I19/L19*100,"") | W19: =IF(AND(L19>0,H19>0,J19>0),(L19-I19)/(H19*J19),"") | X19: =IF(AND(M19>0,N19>0),M19/N19*0.7,"")
A20: 2025-12 | B20: 金条 | C20: 首贷 | D20: 人工 | E20: 汇讯 | F20: 258886 | G20: 4111 | H20: 141470800 | I20: 44125 | J20: 0.07 | K20: 1.068 | L20: 641638 | M20: 559469 | N20: 74 | O20: =IF(L20>0,L20-I20,"") | P20: =IF(AND(M20>0,L20>0),M20/L20*100,"") | Q20: =IF(AND(G20>0,F20>0),G20/F20*100,"") | R20: =IF(AND(H20>0,G20>0),H20/G20,"") | S20: =IF(AND(L20>0,G20>0),L20/G20,"") | T20: =IF(AND(M20>0,G20>0),M20/G20,"") | U20: =IF(AND(M20>0,N20>0),M20/N20,"") | V20: =IF(AND(I20>=0,L20>0),I20/L20*100,"") | W20: =IF(AND(L20>0,H20>0,J20>0),(L20-I20)/(H20*J20),"") | X20: =IF(AND(M20>0,N20>0),M20/N20*0.7,"")
... A28: 2025-12 | B28: 金条 | C28: 复贷 | D28: 人工 | E28: 赛维斯 | F28: 135848 | G28: 7142 | H28: 240903300 | I28: 25715 | J28: 0.36 | K28: 1.068 | L28: 240107 | M28: 200742 | N28: 64 | O28: =IF(L28>0,L28-I28,"") | P28: =IF(AND(M28>0,L28>0),M28/L28*100,"") | Q28: =IF(AND(G28>0,F28>0),G28/F28*100,"") | R28: =IF(AND(H28>0,G28>0),H28/G28,"") | S28: =IF(AND(L28>0,G28>0),L28/G28,"") | T28: =IF(AND(M28>0,G28>0),M28/G28,"") | U28: =IF(AND(M28>0,N28>0),M28/N28,"") | V28: =IF(AND(I28>=0,L28>0),I28/L28*100,"") | W28: =IF(AND(L28>0,H28>0,J28>0),(L28-I28)/(H28*J28),"") | X28: =IF(AND(M28>0,N28>0),M28/N28*0.7,"")
A29: 2025-12 | B29: 金条 | C29: 复贷 | D29: 人工 | E29: 兴格毅 | F29: 90649 | G29: 4725 | H29: 167128500 | I29: 13080 | J29: 0.36 | K29: 1.068 | L29: 164057 | M29: 141364 | O29: =IF(L29>0,L29-I29,"") | P29: =IF(AND(M29>0,L29>0),M29/L29*100,"") | Q29: =IF(AND(G29>0,F29>0),G29/F29*100,"") | R29: =IF(AND(H29>0,G29>0),H29/G29,"") | S29: =IF(AND(L29>0,G29>0),L29/G29,"") | T29: =IF(AND(M29>0,G29>0),M29/G29,"") | U29: =IF(AND(M29>0,N29>0),M29/N29,"") | V29: =IF(AND(I29>=0,L29>0),I29/L29*100,"") | W29: =IF(AND(L29>0,H29>0,J29>0),(L29-I29)/(H29*J29),"") | X29: =IF(AND(M29>0,N29>0),M29/N29*0.7,"")
A30: 2025-12 | B30: 金条 | C30: 首贷 | D30: 人工 | E30: 宿迁兆科 | F30: 39853 | G30: 617 | H30: 11267300 | I30: 5090 | J30: 0.07 | K30: 1.068 | L30: 49248 | M30: 41346 | O30: =IF(L30>0,L30-I30,"") | P30: =IF(AND(M30>0,L30>0),M30/L30*100,"") | Q30: =IF(AND(G30>0,F30>0),G30/F30*100,"") | R30: =IF(AND(H30>0,G30>0),H30/G30,"") | S30: =IF(AND(L30>0,G30>0),L30/G30,"") | T30: =IF(AND(M30>0,G30>0),M30/G30,"") | U30: =IF(AND(M30>0,N30>0),M30/N30,"") | V30: =IF(AND(I30>=0,L30>0),I30/L30*100,"") | W30: =IF(AND(L30>0,H30>0,J30>0),(L30-I30)/(H30*J30),"") | X30: =IF(AND(M30>0,N30>0),M30/N30*0.7,"")
A31: 2025-12 | B31: 金条 | C31: 复贷 | D31: 人工 | E31: 宿迁兆科 | F31: 58432 | G31: 4133 | H31: 145065000 | I31: 8442 | J31: 0.36 | K31: 1.068 | L31: 147618 | M31: 130315 | O31: =IF(L31>0,L31-I31,"") | P31: =IF(AND(M31>0,L31>0),M31/L31*100,"") | Q31: =IF(AND(G31>0,F31>0),G31/F31*100,"") | R31: =IF(AND(H31>0,G31>0),H31/G31,"") | S31: =IF(AND(L31>0,G31>0),L31/G31,"") | T31: =IF(AND(M31>0,G31>0),M31/G31,"") | U31: =IF(AND(M31>0,N31>0),M31/N31,"") | V31: =IF(AND(I31>=0,L31>0),I31/L31*100,"") | W31: =IF(AND(L31>0,H31>0,J31>0),(L31-I31)/(H31*J31),"") | X31: =IF(AND(M31>0,N31>0),M31/N31*0.7,"")
A32: 2025-12 | B32: 金条 | C32: 首贷 | D32: 人工 | E32: 毅航合肥 | F32: 786515 | G32: 12669 | H32: 489557600 | I32: 129470 | J32: 0.07 | K32: 1.068 | L32: 2174183 | M32: 1914526 | N32: 220 | O32: =IF(L32>0,L32-I32,"") | P32: =IF(AND(M32>0,L32>0),M32/L32*100,"") | Q32: =IF(AND(G32>0,F32>0),G32/F32*100,"") | R32: =IF(AND(H32>0,G32>0),H32/G32,"") | S32: =IF(AND(L32>0,G32>0),L32/G32,"") | T32: =IF(AND(M32>0,G32>0),M32/G32,"") | U32: =IF(AND(M32>0,N32>0),M32/N32,"") | V32: =IF(AND(I32>=0,L32>0),I32/L32*100,"") | W32: =IF(AND(L32>0,H32>0,J32>0),(L32-I32)/(H32*J32),"") | X32: =IF(AND(M32>0,N32>0),M32/N32*0.7,"")
A33: 2025-12 | B33: 金条 | C33: 复贷 | D33: 人工 | E33: 毅航合肥 | F33: 444317 | G33: 21452 | H33: 822502600 | I33: 69899 | J33: 0.36 | K33: 1.068 | L33: 797874 | M33: 681624 | N33: 140 | O33: =IF(L33>0,L33-I33,"") | P33: =IF(AND(M33>0,L33>0),M33/L33*100,"") | Q33: =IF(AND(G33>0,F33>0),G33/F33*100,"") | R33: =IF(AND(H33>0,G33>0),H33/G33,"") | S33: =IF(AND(L33>0,G33>0),L33/G33,"") | T33: =IF(AND(M33>0,G33>0),M33/G33,"") | U33: =IF(AND(M33>0,N33>0),M33/N33,"") | V33: =IF(AND(I33>=0,L33>0),I33/L33*100,"") | W33: =IF(AND(L33>0,H33>0,J33>0),(L33-I33)/(H33*J33),"") | X33: =IF(AND(M33>0,N33>0),M33/N33*0.7,"")
A34: 2025-12 | B34: 金条 | C34: 首贷 | D34: 纯机 | E34: 电话邦 | F34: 1059862 | G34: 660 | H34: 8137100 | I34: 87373 | J34: 0.07 | K34: 1.068 | L34: 92070 | M34: 4398 | O34: =IF(L34>0,L34-I34,"") | P34: =IF(AND(M34>0,L34>0),M34/L34*100,"") | Q34: =IF(AND(G34>0,F34>0),G34/F34*100,"") | R34: =IF(AND(H34>0,G34>0),H34/G34,"") | S34: =IF(AND(L34>0,G34>0),L34/G34,"") | T34: =IF(AND(M34>0,G34>0),M34/G34,"") | U34: =IF(AND(M34>0,N34>0),M34/N34,"") | V34: =IF(AND(I34>=0,L34>0),I34/L34*100,"") | W34: =IF(AND(L34>0,H34>0,J34>0),(L34-I34)/(H34*J34),"") | X34: =IF(AND(M34>0,N34>0),M34/N34*0.7,"")
A35: 2025-12 | B35: 金条 | C35: 首贷 | D35: 纯机 | E35: 九四 | F35: 965603 | G35: 700 | H35: 9968800 | I35: 83899 | J35: 0.07 | K35: 1.068 | L35: 97650 | M35: 12876 | O35: =IF(L35>0,L35-I35,"") | P35: =IF(AND(M35>0,L35>0),M35/L35*100,"") | Q35: =IF(AND(G35>0,F35>0),G35/F35*100,"") | R35: =IF(AND(H35>0,G35>0),H35/G35,"") | S35: =IF(AND(L35>0,G35>0),L35/G35,"") | T35: =IF(AND(M35>0,G35>0),M35/G35,"") | U35: =IF(AND(M35>0,N35>0),M35/N35,"") | V35: =IF(AND(I35>=0,L35>0),I35/L35*100,"") | W35: =IF(AND(L35>0,H35>0,J35>0),(L35-I35)/(H35*J35),"") | X35: =IF(AND(M35>0,N35>0),M35/N35*0.7,"")
A36: 2025-12 | B36: 金条 | C36: 首贷 | D36: 纯机 | E36: 零犀 | F36: 16613015 | G36: 17336 | H36: 412741500 | I36: 1383837 | J36: 0.07 | K36: 1.068 | L36: 2418372 | M36: 968666 | O36: =IF(L36>0,L36-I36,"") | P36: =IF(AND(M36>0,L36>0),M36/L36*100,"") | Q36: =IF(AND(G36>0,F36>0),G36/F36*100,"") | R36: =IF(AND(H36>0,G36>0),H36/G36,"") | S36: =IF(AND(L36>0,G36>0),L36/G36,"") | T36: =IF(AND(M36>0,G36>0),M36/G36,"") | U36: =IF(AND(M36>0,N36>0),M36/N36,"") | V36: =IF(AND(I36>=0,L36>0),I36/L36*100,"") | W36: =IF(AND(L36>0,H36>0,J36>0),(L36-I36)/(H36*J36),"") | X36: =IF(AND(M36>0,N36>0),M36/N36*0.7,"")
A37: 2025-12 | B37: 金条 | C37: 复贷 | D37: 纯机 | E37: 零犀 | F37: 308351 | G37: 21166 | H37: 501287700 | I37: 33257 | J37: 0.36 | K37: 1.068 | L37: 76998 | M37: 40956 | O37: =IF(L37>0,L37-I37,"") | P37: =IF(AND(M37>0,L37>0),M37/L37*100,"") | Q37: =IF(AND(G37>0,F37>0),G37/F37*100,"") | R37: =IF(AND(H37>0,G37>0),H37/G37,"") | S37: =IF(AND(L37>0,G37>0),L37/G37,"") | T37: =IF(AND(M37>0,G37>0),M37/G37,"") | U37: =IF(AND(M37>0,N37>0),M37/N37,"") | V37: =IF(AND(I37>=0,L37>0),I37/L37*100,"") | W37: =IF(AND(L37>0,H37>0,J37>0),(L37-I37)/(H37*J37),"") | X37: =IF(AND(M37>0,N37>0),M37/N37*0.7,"")
A38: 2025-12 | B38: 金条 | C38: 首贷 | D38: 纯机 | E38: 言犀赛夫 | F38: 6058258 | G38: 4186 | H38: 75743800 | I38: 519620 | J38: 0.07 | K38: 1.068 | L38: 583947 | M38: 60232 | O38: =IF(L38>0,L38-I38,"") | P38: =IF(AND(M38>0,L38>0),M38/L38*100,"") | Q38: =IF(AND(G38>0,F38>0),G38/F38*100,"") | R38: =IF(AND(H38>0,G38>0),H38/G38,"") | S38: =IF(AND(L38>0,G38>0),L38/G38,"") | T38: =IF(AND(M38>0,G38>0),M38/G38,"") | U38: =IF(AND(M38>0,N38>0),M38/N38,"") | V38: =IF(AND(I38>=0,L38>0),I38/L38*100,"") | W38: =IF(AND(L38>0,H38>0,J38>0),(L38-I38)/(H38*J38),"") | X38: =IF(AND(M38>0,N38>0),M38/N38*0.7,"")
A39: 2025-12 | B39: 金条 | C39: 复贷 | D39: 纯机 | E39: 言犀赛夫 | F39: 220889 | G39: 14071 | H39: 331601200 | I39: 24351 | J39: 0.36 | K39: 1.068 | L39: 50934 | M39: 24890 | O39: =IF(L39>0,L39-I39,"") | P39: =IF(AND(M39>0,L39>0),M39/L39*100,"") | Q39: =IF(AND(G39>0,F39>0),G39/F39*100,"") | R39: =IF(AND(H39>0,G39>0),H39/G39,"") | S39: =IF(AND(L39>0,G39>0),L39/G39,"") | T39: =IF(AND(M39>0,G39>0),M39/G39,"") | U39: =IF(AND(M39>0,N39>0),M39/N39,"") | V39: =IF(AND(I39>=0,L39>0),I39/L39*100,"") | W39: =IF(AND(L39>0,H39>0,J39>0),(L39-I39)/(H39*J39),"") | X39: =IF(AND(M39>0,N39>0),M39/N39*0.7,"")
A40: 2026-01 | B40: 金条 | C40: 首贷 | D40: 人机 | E40: 零犀伽玛 | F40: 2513420 | G40: 7945 | H40: 144302700 | I40: 271934 | J40: 0.07 | K40: 1.068 | L40: 781279 | M40: 476915 | N40: 30 | O40: =IF(L40>0,L40-I40,"") | P40: =IF(AND(M40>0,L40>0),M40/L40*100,"") | Q40: =IF(AND(G40>0,F40>0),G40/F40*100,"") | R40: =IF(AND(H40>0,G40>0),H40/G40,"") | S40: =IF(AND(L40>0,G40>0),L40/G40,"") | T40: =IF(AND(M40>0,G40>0),M40/G40,"") | U40: =IF(AND(M40>0,N40>0),M40/N40,"") | V40: =IF(AND(I40>=0,L40>0),I40/L40*100,"") | W40: =IF(AND(L40>0,H40>0,J40>0),(L40-I40)/(H40*J40),"") | X40: =IF(AND(M40>0,N40>0),M40/N40*0.7,"")
A41: 2026-01 | B41: 金条 | C41: 首贷 | D41: 人机 | E41: 零犀 | F41: 10262894 | G41: 34844 | H41: 768615100 | I41: 1072642 | J41: 0.07 | K41: 1.068 | L41: 4169398 | M41: 2899584 | N41: 81 | O41: =IF(L41>0,L41-I41,"") | P41: =IF(AND(M41>0,L41>0),M41/L41*100,"") | Q41: =IF(AND(G41>0,F41>0),G41/F41*100,"") | R41: =IF(AND(H41>0,G41>0),H41/G41,"") | S41: =IF(AND(L41>0,G41>0),L41/G41,"") | T41: =IF(AND(M41>0,G41>0),M41/G41,"") | U41: =IF(AND(M41>0,N41>0),M41/N41,"") | V41: =IF(AND(I41>=0,L41>0),I41/L41*100,"") | W41: =IF(AND(L41>0,H41>0,J41>0),(L41-I41)/(H41*J41),"") | X41: =IF(AND(M41>0,N41>0),M41/N41*0.7,"")
A42: 2026-01 | B42: 金条 | C42: 复贷 | D42: 人机 | E42: 零犀 | F42: 1917233 | G42: 13579 | H42: 669310200 | I42: 186327 | J42: 0.36 | K42: 1.068 | L42: 771045 | M42: 547490 | N42: 13 | O42: =IF(L42>0,L42-I42,"") | P42: =IF(AND(M42>0,L42>0),M42/L42*100,"") | Q42: =IF(AND(G42>0,F42>0),G42/F42*100,"") | R42: =IF(AND(H42>0,G42>0),H42/G42,"") | S42: =IF(AND(L42>0,G42>0),L42/G42,"") | T42: =IF(AND(M42>0,G42>0),M42/G42,"") | U42: =IF(AND(M42>0,N42>0),M42/N42,"") | V42: =IF(AND(I42>=0,L42>0),I42/L42*100,"") | W42: =IF(AND(L42>0,H42>0,J42>0),(L42-I42)/(H42*J42),"") | X42: =IF(AND(M42>0,N42>0),M42/N42*0.7,"")
A43: 2026-01 | B43: 金条 | C43: 首贷 | D43: 人机 | E43: 零犀毛毛虫 | F43: 1948705 | G43: 6662 | H43: 131905400 | I43: 211660 | J43: 0.07 | K43: 1.068 | L43: 703632 | M43: 460647 | N43: 32 | O43: =IF(L43>0,L43-I43,"") | P43: =IF(AND(M43>0,L43>0),M43/L43*100,"") | Q43: =IF(AND(G43>0,F43>0),G43/F43*100,"") | R43: =IF(AND(H43>0,G43>0),H43/G43,"") | S43: =IF(AND(L43>0,G43>0),L43/G43,"") | T43: =IF(AND(M43>0,G43>0),M43/G43,"") | U43: =IF(AND(M43>0,N43>0),M43/N43,"") | V43: =IF(AND(I43>=0,L43>0),I43/L43*100,"") | W43: =IF(AND(L43>0,H43>0,J43>0),(L43-I43)/(H43*J43),"") | X43: =IF(AND(M43>0,N43>0),M43/N43*0.7,"")
A44: 2026-01 | B44: 金条 | C44: 首贷 | D44: 人机 | E44: 零犀赛维斯 | F44: 2011172 | G44: 6569 | H44: 120954300 | I44: 233130 | J44: 0.07 | K44: 1.068 | L44: 646912 | M44: 387437 | N44: 23 | O44: =IF(L44>0,L44-I44,"") | P44: =IF(AND(M44>0,L44>0),M44/L44*100,"") | Q44: =IF(AND(G44>0,F44>0),G44/F44*100,"") | R44: =IF(AND(H44>0,G44>0),H44/G44,"") | S44: =IF(AND(L44>0,G44>0),L44/G44,"") | T44: =IF(AND(M44>0,G44>0),M44/G44,"") | U44: =IF(AND(M44>0,N44>0),M44/N44,"") | V44: =IF(AND(I44>=0,L44>0),I44/L44*100,"") | W44: =IF(AND(L44>0,H44>0,J44>0),(L44-I44)/(H44*J44),"") | X44: =IF(AND(M44>0,N44>0),M44/N44*0.7,"")
A45: 2026-01 | B45: 金条 | C45: 首贷 | D45: 人机 | E45: 零犀毅航 | F45: 3781808 | G45: 12862 | H45: 262594900 | I45: 401334 | J45: 0.07 | K45: 1.068 | L45: 1422467 | M45: 956117 | N45: 49 | O45: =IF(L45>0,L45-I45,"") | P45: =IF(AND(M45>0,L45>0),M45/L45*100,"") | Q45: =IF(AND(G45>0,F45>0),G45/F45*100,"") | R45: =IF(AND(H45>0,G45>0),H45/G45,"") | S45: =IF(AND(L45>0,G45>0),L45/G45,"") | T45: =IF(AND(M45>0,G45>0),M45/G45,"") | U45: =IF(AND(M45>0,N45>0),M45/N45,"") | V45: =IF(AND(I45>=0,L45>0),I45/L45*100,"") | W45: =IF(AND(L45>0,H45>0,J45>0),(L45-I45)/(H45*J45),"") | X45: =IF(AND(M45>0,N45>0),M45/N45*0.7,"")
A46: 2026-01 | B46: 金条 | C46: 复贷 | D46: 人机 | E46: 毛毛虫 | F46: 133138 | G46: 2032 | H46: 81377200 | I46: 15711 | J46: 0.36 | K46: 1.068 | L46: 93747 | M46: 73067 | O46: =IF(L46>0,L46-I46,"") | P46: =IF(AND(M46>0,L46>0),M46/L46*100,"") | Q46: =IF(AND(G46>0,F46>0),G46/F46*100,"") | R46: =IF(AND(H46>0,G46>0),H46/G46,"") | S46: =IF(AND(L46>0,G46>0),L46/G46,"") | T46: =IF(AND(M46>0,G46>0),M46/G46,"") | U46: =IF(AND(M46>0,N46>0),M46/N46,"") | V46: =IF(AND(I46>=0,L46>0),I46/L46*100,"") | W46: =IF(AND(L46>0,H46>0,J46>0),(L46-I46)/(H46*J46),"") | X46: =IF(AND(M46>0,N46>0),M46/N46*0.7,"")
A47: 2026-01 | B47: 金条 | C47: 首贷 | D47: 人机 | E47: 赛维斯 | F47: 2278892 | G47: 6405 | H47: 107764500 | I47: 261155 | J47: 0.07 | K47: 1.068 | L47: 581592 | M47: 300035 | N47: 26 | O47: =IF(L47>0,L47-I47,"") | P47: =IF(AND(M47>0,L47>0),M47/L47*100,"") | Q47: =IF(AND(G47>0,F47>0),G47/F47*100,"") | R47: =IF(AND(H47>0,G47>0),H47/G47,"") | S47: =IF(AND(L47>0,G47>0),L47/G47,"") | T47: =IF(AND(M47>0,G47>0),M47/G47,"") | U47: =IF(AND(M47>0,N47>0),M47/N47,"") | V47: =IF(AND(I47>=0,L47>0),I47/L47*100,"") | W47: =IF(AND(L47>0,H47>0,J47>0),(L47-I47)/(H47*J47),"") | X47: =IF(AND(M47>0,N47>0),M47/N47*0.7,"")
...

Sheet 人机全景
A1: 人机供应商全景分析
A3: 供应商 | B3: 月份 | C3: 到手薪资 | D3: 人力 | E3: 元/人/月 | F3: 真实人工x70% | G3: 线路费占比% | H3: 转化率% | I3: 户均贷款
A4: 宿迁兆科 | B4: 2025-12 | C4: =SUMIFS(清洗后明细!M:M,清洗后明细!A:A,"2025-12",清洗后明细!E:E,"宿迁兆科",清洗后明细!D:D,"人机") | D4: =SUMIFS(清洗后明细!N:N,清洗后明细!A:A,"2025-12",清洗后明细!E:E,"宿迁兆科",清洗后明细!D:D,"人机") | E4: =IF(SUMIFS(清洗后明细!M:M,清洗后明细!A:A,"2025-12",清洗后明细!E:E,"宿迁兆科",清洗后明细!D:D,"人机")>0,SUMIFS(清洗后明细!M:M,清洗后明细!A:A,"2025-12",清洗后明细!E:E,"宿迁兆科",清洗后明细!D:D,"人机")/SUMIFS(清洗后明细!N:N,清洗后明细!A:A,"2025-12",清洗后明细!E:E,"宿迁兆科",清洗后明细!D:D,"人机"),"") | F4: =IF(SUMIFS(清洗后明细!M:M,清洗后明细!A:A,"2025-12",清洗后明细!E:E,"宿迁兆科",清洗后明细!D:D,"人机")>0,SUMIFS(清洗后明细!M:M,清洗后明细!A:A,"2025-12",清洗后明细!E:E,"宿迁兆科",清洗后明细!D:D,"人机")/SUMIFS(清洗后明细!N:N,清洗后明细!A:A,"2025-12",清洗后明细!E:E,"宿迁兆科",清洗后明细!D:D,"人机")*0.7,"") | G4: =IF(SUMIFS(清洗后明细!L:L,清洗后明细!A:A,"2025-12",清洗后明细!E:E,"宿迁兆科",清洗后明细!D:D,"人机")>0,SUMIFS(清洗后明细!I:I,清洗后明细!A:A,"2025-12",清洗后明细!E:E,"宿迁兆科",清洗后明细!D:D,"人机")/SUMIFS(清洗后明细!L:L,清洗后明细!A:A,"2025-12",清洗后明细!E:E,"宿迁兆科",清洗后明细!D:D,"人机")*100,"") | H4: =IF(SUMIFS(清洗后明细!F:F,清洗后明细!A:A,"2025-12",清洗后明细!E:E,"宿迁兆科",清洗后明细!D:D,"人机")>0,SUMIFS(清洗后明细!G:G,清洗后明细!A:A,"2025-12",清洗后明细!E:E,"宿迁兆科",清洗后明细!D:D,"人机")/SUMIFS(清洗后明细!F:F,清洗后明细!A:A,"2025-12",清洗后明细!E:E,"宿迁兆科",清洗后明细!D:D,"人机")*100,"") | I4: =IF(SUMIFS(清洗后明细!G:G,清洗后明细!A:A,"2025-12",清洗后明细!E:E,"宿迁兆科",清洗后明细!D:D,"人机")>0,SUMIFS(清洗后明细!H:H,清洗后明细!A:A,"2025-12",清洗后明细!E:E,"宿迁兆科",清洗后明细!D:D,"人机")/SUMIFS(清洗后明细!G:G,清洗后明细!A:A,"2025-12",清洗后明细!E:E,"宿迁兆科",清洗后明细!D:D,"人机"),"")
A5: 宿迁兆科 | B5: 2026-01 | C5: =SUMIFS(清洗后明细!M:M,清洗后明细!A:A,"2026-01",清洗后明细!E:E,"宿迁兆科",清洗后明细!D:D,"人机") | D5: =SUMIFS(清洗后明细!N:N,清洗后明细!A:A,"2026-01",清洗后明细!E:E,"宿迁兆科",清洗后明细!D:D,"人机") | E5: =IF(SUMIFS(清洗后明细!M:M,清洗后明细!A:A,"2026-01",清洗后明细!E:E,"宿迁兆科",清洗后明细!D:D,"人机")>0,SUMIFS(清洗后明细!M:M,清洗后明细!A:A,"2026-01",清洗后明细!E:E,"宿迁兆科",清洗后明细!D:D,"人机")/SUMIFS(清洗后明细!N:N,清洗后明细!A:A,"2026-01",清洗后明细!E:E,"宿迁兆科",清洗后明细!D:D,"人机"),"") | F5: =IF(SUMIFS(清洗后明细!M:M,清洗后明细!A:A,"2026-01",清洗后明细!E:E,"宿迁兆科",清洗后明细!D:D,"人机")>0,SUMIFS(清洗后明细!M:M,清洗后明细!A:A,"2026-01",清洗后明细!E:E,"宿迁兆科",清洗后明细!D:D,"人机")/SUMIFS(清洗后明细!N:N,清洗后明细!A:A,"2026-01",清洗后明细!E:E,"宿迁兆科",清洗后明细!D:D,"人机")*0.7,"") | G5: =IF(SUMIFS(清洗后明细!L:L,清洗后明细!A:A,"2026-01",清洗后明细!E:E,"宿迁兆科",清洗后明细!D:D,"人机")>0,SUMIFS(清洗后明细!I:I,清洗后明细!A:A,"2026-01",清洗后明细!E:E,"宿迁兆科",清洗后明细!D:D,"人机")/SUMIFS(清洗后明细!L:L,清洗后明细!A:A,"2026-01",清洗后明细!E:E,"宿迁兆科",清洗后明细!D:D,"人机")*100,"") | H5: =IF(SUMIFS(清洗后明细!F:F,清洗后明细!A:A,"2026-01",清洗后明细!E:E,"宿迁兆科",清洗后明细!D:D,"人机")>0,SUMIFS(清洗后明细!G:G,清洗后明细!A:A,"2026-01",清洗后明细!E:E,"宿迁兆科",清洗后明细!D:D,"人机")/SUMIFS(清洗后明细!F:F,清洗后明细!A:A,"2026-01",清洗后明细!E:E,"宿迁兆科",清洗后明细!D:D,"人机")*100,"") | I5: =IF(SUMIFS(清洗后明细!G:G,清洗后明细!A:A,"2026-01",清洗后明细!E:E,"宿迁兆科",清洗后明细!D:D,"人机")>0,SUMIFS(清洗后明细!H:H,清洗后明细!A:A,"2026-01",清洗后明细!E:E,"宿迁兆科",清洗后明细!D:D,"人机")/SUMIFS(清洗后明细!G:G,清洗后明细!A:A,"2026-01",清洗后明细!E:E,"宿迁兆科",清洗后明细!D:D,"人机"),"")
A6: 宿迁兆科 | B6: 2026-02 | C6: =SUMIFS(清洗后明细!M:M,清洗后明细!A:A,"2026-02",清洗后明细!E:E,"宿迁兆科",清洗后明细!D:D,"人机") | D6: =SUMIFS(清洗后明细!N:N,清洗后明细!A:A,"2026-02",清洗后明细!E:E,"宿迁兆科",清洗后明细!D:D,"人机") | E6: =IF(SUMIFS(清洗后明细!M:M,清洗后明细!A:A,"2026-02",清洗后明细!E:E,"宿迁兆科",清洗后明细!D:D,"人机")>0,SUMIFS(清洗后明细!M:M,清洗后明细!A:A,"2026-02",清洗后明细!E:E,"宿迁兆科",清洗后明细!D:D,"人机")/SUMIFS(清洗后明细!N:N,清洗后明细!A:A,"2026-02",清洗后明细!E:E,"宿迁兆科",清洗后明细!D:D,"人机"),"") | F6: =IF(SUMIFS(清洗后明细!M:M,清洗后明细!A:A,"2026-02",清洗后明细!E:E,"宿迁兆科",清洗后明细!D:D,"人机")>0,SUMIFS(清洗后明细!M:M,清洗后明细!A:A,"2026-02",清洗后明细!E:E,"宿迁兆科",清洗后明细!D:D,"人机")/SUMIFS(清洗后明细!N:N,清洗后明细!A:A,"2026-02",清洗后明细!E:E,"宿迁兆科",清洗后明细!D:D,"人机")*0.7,"") | G6: =IF(SUMIFS(清洗后明细!L:L,清洗后明细!A:A,"2026-02",清洗后明细!E:E,"宿迁兆科",清洗后明细!D:D,"人机")>0,SUMIFS(清洗后明细!I:I,清洗后明细!A:A,"2026-02",清洗后明细!E:E,"宿迁兆科",清洗后明细!D:D,"人机")/SUMIFS(清洗后明细!L:L,清洗后明细!A:A,"2026-02",清洗后明细!E:E,"宿迁兆科",清洗后明细!D:D,"人机")*100,"") | H6: =IF(SUMIFS(清洗后明细!F:F,清洗后明细!A:A,"2026-02",清洗后明细!E:E,"宿迁兆科",清洗后明细!D:D,"人机")>0,SUMIFS(清洗后明细!G:G,清洗后明细!A:A,"2026-02",清洗后明细!E:E,"宿迁兆科",清洗后明细!D:D,"人机")/SUMIFS(清洗后明细!F:F,清洗后明细!A:A,"2026-02",清洗后明细!E:E,"宿迁兆科",清洗后明细!D:D,"人机")*100,"") | I6: =IF(SUMIFS(清洗后明细!G:G,清洗后明细!A:A,"2026-02",清洗后明细!E:E,"宿迁兆科",清洗后明细!D:D,"人机")>0,SUMIFS(清洗后明细!H:H,清洗后明细!A:A,"2026-02",清洗后明细!E:E,"宿迁兆科",清洗后明细!D:D,"人机")/SUMIFS(清洗后明细!G:G,清洗后明细!A:A,"2026-02",清洗后明细!E:E,"宿迁兆科",清洗后明细!D:D,"人机"),"")
A7: 宿迁兆科 | B7: 2026-03 | C7: =SUMIFS(清洗后明细!M:M,清洗后明细!A:A,"2026-03",清洗后明细!E:E,"宿迁兆科",清洗后明细!D:D,"人机") | D7: =SUMIFS(清洗后明细!N:N,清洗后明细!A:A,"2026-03",清洗后明细!E:E,"宿迁兆科",清洗后明细!D:D,"人机") | E7: =IF(SUMIFS(清洗后明细!M:M,清洗后明细!A:A,"2026-03",清洗后明细!E:E,"宿迁兆科",清洗后明细!D:D,"人机")>0,SUMIFS(清洗后明细!M:M,清洗后明细!A:A,"2026-03",清洗后明细!E:E,"宿迁兆科",清洗后明细!D:D,"人机")/SUMIFS(清洗后明细!N:N,清洗后明细!A:A,"2026-03",清洗后明细!E:E,"宿迁兆科",清洗后明细!D:D,"人机"),"") | F7: =IF(SUMIFS(清洗后明细!M:M,清洗后明细!A:A,"2026-03",清洗后明细!E:E,"宿迁兆科",清洗后明细!D:D,"人机")>0,SUMIFS(清洗后明细!M:M,清洗后明细!A:A,"2026-03",清洗后明细!E:E,"宿迁兆科",清洗后明细!D:D,"人机")/SUMIFS(清洗后明细!N:N,清洗后明细!A:A,"2026-03",清洗后明细!E:E,"宿迁兆科",清洗后明细!D:D,"人机")*0.7,"") | G7: =IF(SUMIFS(清洗后明细!L:L,清洗后明细!A:A,"2026-03",清洗后明细!E:E,"宿迁兆科",清洗后明细!D:D,"人机")>0,SUMIFS(清洗后明细!I:I,清洗后明细!A:A,"2026-03",清洗后明细!E:E,"宿迁兆科",清洗后明细!D:D,"人机")/SUMIFS(清洗后明细!L:L,清洗后明细!A:A,"2026-03",清洗后明细!E:E,"宿迁兆科",清洗后明细!D:D,"人机")*100,"") | H7: =IF(SUMIFS(清洗后明细!F:F,清洗后明细!A:A,"2026-03",清洗后明细!E:E,"宿迁兆科",清洗后明细!D:D,"人机")>0,SUMIFS(清洗后明细!G:G,清洗后明细!A:A,"2026-03",清洗后明细!E:E,"宿迁兆科",清洗后明细!D:D,"人机")/SUMIFS(清洗后明细!F:F,清洗后明细!A:A,"2026-03",清洗后明细!E:E,"宿迁兆科",清洗后明细!D:D,"人机")*100,"") | I7: =IF(SUMIFS(清洗后明细!G:G,清洗后明细!A:A,"2026-03",清洗后明细!E:E,"宿迁兆科",清洗后明细!D:D,"人机")>0,SUMIFS(清洗后明细!H:H,清洗后明细!A:A,"2026-03",清洗后明细!E:E,"宿迁兆科",清洗后明细!D:D,"人机")/SUMIFS(清洗后明细!G:G,清洗后明细!A:A,"2026-03",清洗后明细!E:E,"宿迁兆科",清洗后明细!D:D,"人机"),"")
A8: 宿迁兆科 | B8: 2026-04 | C8: =SUMIFS(清洗后明细!M:M,清洗后明细!A:A,"2026-04",清洗后明细!E:E,"宿迁兆科",清洗后明细!D:D,"人机") | D8: =SUMIFS(清洗后明细!N:N,清洗后明细!A:A,"2026-04",清洗后明细!E:E,"宿迁兆科",清洗后明细!D:D,"人机") | E8: =IF(SUMIFS(清洗后明细!M:M,清洗后明细!A:A,"2026-04",清洗后明细!E:E,"宿迁兆科",清洗后明细!D:D,"人机")>0,SUMIFS(清洗后明细!M:M,清洗后明细!A:A,"2026-04",清洗后明细!E:E,"宿迁兆科",清洗后明细!D:D,"人机")/SUMIFS(清洗后明细!N:N,清洗后明细!A:A,"2026-04",清洗后明细!E:E,"宿迁兆科",清洗后明细!D:D,"人机"),"") | F8: =IF(SUMIFS(清洗后明细!M:M,清洗后明细!A:A,"2026-04",清洗后明细!E:E,"宿迁兆科",清洗后明细!D:D,"人机")>0,SUMIFS(清洗后明细!M:M,清洗后明细!A:A,"2026-04",清洗后明细!E:E,"宿迁兆科",清洗后明细!D:D,"人机")/SUMIFS(清洗后明细!N:N,清洗后明细!A:A,"2026-04",清洗后明细!E:E,"宿迁兆科",清洗后明细!D:D,"人机")*0.7,"") | G8: =IF(SUMIFS(清洗后明细!L:L,清洗后明细!A:A,"2026-04",清洗后明细!E:E,"宿迁兆科",清洗后明细!D:D,"人机")>0,SUMIFS(清洗后明细!I:I,清洗后明细!A:A,"2026-04",清洗后明细!E:E,"宿迁兆科",清洗后明细!D:D,"人机")/SUMIFS(清洗后明细!L:L,清洗后明细!A:A,"2026-04",清洗后明细!E:E,"宿迁兆科",清洗后明细!D:D,"人机")*100,"") | H8: =IF(SUMIFS(清洗后明细!F:F,清洗后明细!A:A,"2026-04",清洗后明细!E:E,"宿迁兆科",清洗后明细!D:D,"人机")>0,SUMIFS(清洗后明细!G:G,清洗后明细!A:A,"2026-04",清洗后明细!E:E,"宿迁兆科",清洗后明细!D:D,"人机")/SUMIFS(清洗后明细!F:F,清洗后明细!A:A,"2026-04",清洗后明细!E:E,"宿迁兆科",清洗后明细!D:D,"人机")*100,"") | I8: =IF(SUMIFS(清洗后明细!G:G,清洗后明细!A:A,"2026-04",清洗后明细!E:E,"宿迁兆科",清洗后明细!D:D,"人机")>0,SUMIFS(清洗后明细!H:H,清洗后明细!A:A,"2026-04",清洗后明细!E:E,"宿迁兆科",清洗后明细!D:D,"人机")/SUMIFS(清洗后明细!G:G,清洗后明细!A:A,"2026-04",清洗后明细!E:E,"宿迁兆科",清洗后明细!D:D,"人机"),"")
A9: 宿迁兆科 | B9: 2026-05 | C9: =SUMIFS(清洗后明细!M:M,清洗后明细!A:A,"2026-05",清洗后明细!E:E,"宿迁兆科",清洗后明细!D:D,"人机") | D9: =SUMIFS(清洗后明细!N:N,清洗后明细!A:A,"2026-05",清洗后明细!E:E,"宿迁兆科",清洗后明细!D:D,"人机") | E9: =IF(SUMIFS(清洗后明细!M:M,清洗后明细!A:A,"2026-05",清洗后明细!E:E,"宿迁兆科",清洗后明细!D:D,"人机")>0,SUMIFS(清洗后明细!M:M,清洗后明细!A:A,"2026-05",清洗后明细!E:E,"宿迁兆科",清洗后明细!D:D,"人机")/SUMIFS(清洗后明细!N:N,清洗后明细!A:A,"2026-05",清洗后明细!E:E,"宿迁兆科",清洗后明细!D:D,"人机"),"") | F9: =IF(SUMIFS(清洗后明细!M:M,清洗后明细!A:A,"2026-05",清洗后明细!E:E,"宿迁兆科",清洗后明细!D:D,"人机")>0,SUMIFS(清洗后明细!M:M,清洗后明细!A:A,"2026-05",清洗后明细!E:E,"宿迁兆科",清洗后明细!D:D,"人机")/SUMIFS(清洗后明细!N:N,清洗后明细!A:A,"2026-05",清洗后明细!E:E,"宿迁兆科",清洗后明细!D:D,"人机")*0.7,"") | G9: =IF(SUMIFS(清洗后明细!L:L,清洗后明细!A:A,"2026-05",清洗后明细!E:E,"宿迁兆科",清洗后明细!D:D,"人机")>0,SUMIFS(清洗后明细!I:I,清洗后明细!A:A,"2026-05",清洗后明细!E:E,"宿迁兆科",清洗后明细!D:D,"人机")/SUMIFS(清洗后明细!L:L,清洗后明细!A:A,"2026-05",清洗后明细!E:E,"宿迁兆科",清洗后明细!D:D,"人机")*100,"") | H9: =IF(SUMIFS(清洗后明细!F:F,清洗后明细!A:A,"2026-05",清洗后明细!E:E,"宿迁兆科",清洗后明细!D:D,"人机")>0,SUMIFS(清洗后明细!G:G,清洗后明细!A:A,"2026-05",清洗后明细!E:E,"宿迁兆科",清洗后明细!D:D,"人机")/SUMIFS(清洗后明细!F:F,清洗后明细!A:A,"2026-05",清洗后明细!E:E,"宿迁兆科",清洗后明细!D:D,"人机")*100,"") | I9: =IF(SUMIFS(清洗后明细!G:G,清洗后明细!A:A,"2026-05",清洗后明细!E:E,"宿迁兆科",清洗后明细!D:D,"人机")>0,SUMIFS(清洗后明细!H:H,清洗后明细!A:A,"2026-05",清洗后明细!E:E,"宿迁兆科",清洗后明细!D:D,"人机")/SUMIFS(清洗后明细!G:G,清洗后明细!A:A,"2026-05",清洗后明细!E:E,"宿迁兆科",清洗后明细!D:D,"人机"),"")
A10: 宿迁兆科 | B10: 2026-06 | C10: =SUMIFS(清洗后明细!M:M,清洗后明细!A:A,"2026-06",清洗后明细!E:E,"宿迁兆科",清洗后明细!D:D,"人机") | D10: =SUMIFS(清洗后明细!N:N,清洗后明细!A:A,"2026-06",清洗后明细!E:E,"宿迁兆科",清洗后明细!D:D,"人机") | E10: =IF(SUMIFS(清洗后明细!M:M,清洗后明细!A:A,"2026-06",清洗后明细!E:E,"宿迁兆科",清洗后明细!D:D,"人机")>0,SUMIFS(清洗后明细!M:M,清洗后明细!A:A,"2026-06",清洗后明细!E:E,"宿迁兆科",清洗后明细!D:D,"人机")/SUMIFS(清洗后明细!N:N,清洗后明细!A:A,"2026-06",清洗后明细!E:E,"宿迁兆科",清洗后明细!D:D,"人机"),"") | F10: =IF(SUMIFS(清洗后明细!M:M,清洗后明细!A:A,"2026-06",清洗后明细!E:E,"宿迁兆科",清洗后明细!D:D,"人机")>0,SUMIFS(清洗后明细!M:M,清洗后明细!A:A,"2026-06",清洗后明细!E:E,"宿迁兆科",清洗后明细!D:D,"人机")/SUMIFS(清洗后明细!N:N,清洗后明细!A:A,"2026-06",清洗后明细!E:E,"宿迁兆科",清洗后明细!D:D,"人机")*0.7,"") | G10: =IF(SUMIFS(清洗后明细!L:L,清洗后明细!A:A,"2026-06",清洗后明细!E:E,"宿迁兆科",清洗后明细!D:D,"人机")>0,SUMIFS(清洗后明细!I:I,清洗后明细!A:A,"2026-06",清洗后明细!E:E,"宿迁兆科",清洗后明细!D:D,"人机")/SUMIFS(清洗后明细!L:L,清洗后明细!A:A,"2026-06",清洗后明细!E:E,"宿迁兆科",清洗后明细!D:D,"人机")*100,"") | H10: =IF(SUMIFS(清洗后明细!F:F,清洗后明细!A:A,"2026-06",清洗后明细!E:E,"宿迁兆科",清洗后明细!D:D,"人机")>0,SUMIFS(清洗后明细!G:G,清洗后明细!A:A,"2026-06",清洗后明细!E:E,"宿迁兆科",清洗后明细!D:D,"人机")/SUMIFS(清洗后明细!F:F,清洗后明细!A:A,"2026-06",清洗后明细!E:E,"宿迁兆科",清洗后明细!D:D,"人机")*100,"") | I10: =IF(SUMIFS(清洗后明细!G:G,清洗后明细!A:A,"2026-06",清洗后明细!E:E,"宿迁兆科",清洗后明细!D:D,"人机")>0,SUMIFS(清洗后明细!H:H,清洗后明细!A:A,"2026-06",清洗后明细!E:E,"宿迁兆科",清洗后明细!D:D,"人机")/SUMIFS(清洗后明细!G:G,清洗后明细!A:A,"2026-06",清洗后明细!E:E,"宿迁兆科",清洗后明细!D:D,"人机"),"")
A11: 赛维斯 | B11: 2025-12 | C11: =SUMIFS(清洗后明细!M:M,清洗后明细!A:A,"2025-12",清洗后明细!E:E,"赛维斯",清洗后明细!D:D,"人机") | D11: =SUMIFS(清洗后明细!N:N,清洗后明细!A:A,"2025-12",清洗后明细!E:E,"赛维斯",清洗后明细!D:D,"人机") | E11: =IF(SUMIFS(清洗后明细!M:M,清洗后明细!A:A,"2025-12",清洗后明细!E:E,"赛维斯",清洗后明细!D:D,"人机")>0,SUMIFS(清洗后明细!M:M,清洗后明细!A:A,"2025-12",清洗后明细!E:E,"赛维斯",清洗后明细!D:D,"人机")/SUMIFS(清洗后明细!N:N,清洗后明细!A:A,"2025-12",清洗后明细!E:E,"赛维斯",清洗后明细!D:D,"人机"),"") | F11: =IF(SUMIFS(清洗后明细!M:M,清洗后明细!A:A,"2025-12",清洗后明细!E:E,"赛维斯",清洗后明细!D:D,"人机")>0,SUMIFS(清洗后明细!M:M,清洗后明细!A:A,"2025-12",清洗后明细!E:E,"赛维斯",清洗后明细!D:D,"人机")/SUMIFS(清洗后明细!N:N,清洗后明细!A:A,"2025-12",清洗后明细!E:E,"赛维斯",清洗后明细!D:D,"人机")*0.7,"") | G11: =IF(SUMIFS(清洗后明细!L:L,清洗后明细!A:A,"2025-12",清洗后明细!E:E,"赛维斯",清洗后明细!D:D,"人机")>0,SUMIFS(清洗后明细!I:I,清洗后明细!A:A,"2025-12",清洗后明细!E:E,"赛维斯",清洗后明细!D:D,"人机")/SUMIFS(清洗后明细!L:L,清洗后明细!A:A,"2025-12",清洗后明细!E:E,"赛维斯",清洗后明细!D:D,"人机")*100,"") | H11: =IF(SUMIFS(清洗后明细!F:F,清洗后明细!A:A,"2025-12",清洗后明细!E:E,"赛维斯",清洗后明细!D:D,"人机")>0,SUMIFS(清洗后明细!G:G,清洗后明细!A:A,"2025-12",清洗后明细!E:E,"赛维斯",清洗后明细!D:D,"人机")/SUMIFS(清洗后明细!F:F,清洗后明细!A:A,"2025-12",清洗后明细!E:E,"赛维斯",清洗后明细!D:D,"人机")*100,"") | I11: =IF(SUMIFS(清洗后明细!G:G,清洗后明细!A:A,"2025-12",清洗后明细!E:E,"赛维斯",清洗后明细!D:D,"人机")>0,SUMIFS(清洗后明细!H:H,清洗后明细!A:A,"2025-12",清洗后明细!E:E,"赛维斯",清洗后明细!D:D,"人机")/SUMIFS(清洗后明细!G:G,清洗后明细!A:A,"2025-12",清洗后明细!E:E,"赛维斯",清洗后明细!D:D,"人机"),"")
A12: 赛维斯 | B12: 2026-01 | C12: =SUMIFS(清洗后明细!M:M,清洗后明细!A:A,"2026-01",清洗后明细!E:E,"赛维斯",清洗后明细!D:D,"人机") | D12: =SUMIFS(清洗后明细!N:N,清洗后明细!A:A,"2026-01",清洗后明细!E:E,"赛维斯",清洗后明细!D:D,"人机") | E12: =IF(SUMIFS(清洗后明细!M:M,清洗后明细!A:A,"2026-01",清洗后明细!E:E,"赛维斯",清洗后明细!D:D,"人机")>0,SUMIFS(清洗后明细!M:M,清洗后明细!A:A,"2026-01",清洗后明细!E:E,"赛维斯",清洗后明细!D:D,"人机")/SUMIFS(清洗后明细!N:N,清洗后明细!A:A,"2026-01",清洗后明细!E:E,"赛维斯",清洗后明细!D:D,"人机"),"") | F12: =IF(SUMIFS(清洗后明细!M:M,清洗后明细!A:A,"2026-01",清洗后明细!E:E,"赛维斯",清洗后明细!D:D,"人机")>0,SUMIFS(清洗后明细!M:M,清洗后明细!A:A,"2026-01",清洗后明细!E:E,"赛维斯",清洗后明细!D:D,"人机")/SUMIFS(清洗后明细!N:N,清洗后明细!A:A,"2026-01",清洗后明细!E:E,"赛维斯",清洗后明细!D:D,"人机")*0.7,"") | G12: =IF(SUMIFS(清洗后明细!L:L,清洗后明细!A:A,"2026-01",清洗后明细!E:E,"赛维斯",清洗后明细!D:D,"人机")>0,SUMIFS(清洗后明细!I:I,清洗后明细!A:A,"2026-01",清洗后明细!E:E,"赛维斯",清洗后明细!D:D,"人机")/SUMIFS(清洗后明细!L:L,清洗后明细!A:A,"2026-01",清洗后明细!E:E,"赛维斯",清洗后明细!D:D,"人机")*100,"") | H12: =IF(SUMIFS(清洗后明细!F:F,清洗后明细!A:A,"2026-01",清洗后明细!E:E,"赛维斯",清洗后明细!D:D,"人机")>0,SUMIFS(清洗后明细!G:G,清洗后明细!A:A,"2026-01",清洗后明细!E:E,"赛维斯",清洗后明细!D:D,"人机")/SUMIFS(清洗后明细!F:F,清洗后明细!A:A,"2026-01",清洗后明细!E:E,"赛维斯",清洗后明细!D:D,"人机")*100,"") | I12: =IF(SUMIFS(清洗后明细!G:G,清洗后明细!A:A,"2026-01",清洗后明细!E:E,"赛维斯",清洗后明细!D:D,"人机")>0,SUMIFS(清洗后明细!H:H,清洗后明细!A:A,"2026-01",清洗后明细!E:E,"赛维斯",清洗后明细!D:D,"人机")/SUMIFS(清洗后明细!G:G,清洗后明细!A:A,"2026-01",清洗后明细!E:E,"赛维斯",清洗后明细!D:D,"人机"),"")
A13: 赛维斯 | B13: 2026-02 | C13: =SUMIFS(清洗后明细!M:M,清洗后明细!A:A,"2026-02",清洗后明细!E:E,"赛维斯",清洗后明细!D:D,"人机") | D13: =SUMIFS(清洗后明细!N:N,清洗后明细!A:A,"2026-02",清洗后明细!E:E,"赛维斯",清洗后明细!D:D,"人机") | E13: =IF(SUMIFS(清洗后明细!M:M,清洗后明细!A:A,"2026-02",清洗后明细!E:E,"赛维斯",清洗后明细!D:D,"人机")>0,SUMIFS(清洗后明细!M:M,清洗后明细!A:A,"2026-02",清洗后明细!E:E,"赛维斯",清洗后明细!D:D,"人机")/SUMIFS(清洗后明细!N:N,清洗后明细!A:A,"2026-02",清洗后明细!E:E,"赛维斯",清洗后明细!D:D,"人机"),"") | F13: =IF(SUMIFS(清洗后明细!M:M,清洗后明细!A:A,"2026-02",清洗后明细!E:E,"赛维斯",清洗后明细!D:D,"人机")>0,SUMIFS(清洗后明细!M:M,清洗后明细!A:A,"2026-02",清洗后明细!E:E,"赛维斯",清洗后明细!D:D,"人机")/SUMIFS(清洗后明细!N:N,清洗后明细!A:A,"2026-02",清洗后明细!E:E,"赛维斯",清洗后明细!D:D,"人机")*0.7,"") | G13: =IF(SUMIFS(清洗后明细!L:L,清洗后明细!A:A,"2026-02",清洗后明细!E:E,"赛维斯",清洗后明细!D:D,"人机")>0,SUMIFS(清洗后明细!I:I,清洗后明细!A:A,"2026-02",清洗后明细!E:E,"赛维斯",清洗后明细!D:D,"人机")/SUMIFS(清洗后明细!L:L,清洗后明细!A:A,"2026-02",清洗后明细!E:E,"赛维斯",清洗后明细!D:D,"人机")*100,"") | H13: =IF(SUMIFS(清洗后明细!F:F,清洗后明细!A:A,"2026-02",清洗后明细!E:E,"赛维斯",清洗后明细!D:D,"人机")>0,SUMIFS(清洗后明细!G:G,清洗后明细!A:A,"2026-02",清洗后明细!E:E,"赛维斯",清洗后明细!D:D,"人机")/SUMIFS(清洗后明细!F:F,清洗后明细!A:A,"2026-02",清洗后明细!E:E,"赛维斯",清洗后明细!D:D,"人机")*100,"") | I13: =IF(SUMIFS(清洗后明细!G:G,清洗后明细!A:A,"2026-02",清洗后明细!E:E,"赛维斯",清洗后明细!D:D,"人机")>0,SUMIFS(清洗后明细!H:H,清洗后明细!A:A,"2026-02",清洗后明细!E:E,"赛维斯",清洗后明细!D:D,"人机")/SUMIFS(清洗后明细!G:G,清洗后明细!A:A,"2026-02",清洗后明细!E:E,"赛维斯",清洗后明细!D:D,"人机"),"")
A14: 赛维斯 | B14: 2026-03 | C14: =SUMIFS(清洗后明细!M:M,清洗后明细!A:A,"2026-03",清洗后明细!E:E,"赛维斯",清洗后明细!D:D,"人机") | D14: =SUMIFS(清洗后明细!N:N,清洗后明细!A:A,"2026-03",清洗后明细!E:E,"赛维斯",清洗后明细!D:D,"人机") | E14: =IF(SUMIFS(清洗后明细!M:M,清洗后明细!A:A,"2026-03",清洗后明细!E:E,"赛维斯",清洗后明细!D:D,"人机")>0,SUMIFS(清洗后明细!M:M,清洗后明细!A:A,"2026-03",清洗后明细!E:E,"赛维斯",清洗后明细!D:D,"人机")/SUMIFS(清洗后明细!N:N,清洗后明细!A:A,"2026-03",清洗后明细!E:E,"赛维斯",清洗后明细!D:D,"人机"),"") | F14: =IF(SUMIFS(清洗后明细!M:M,清洗后明细!A:A,"2026-03",清洗后明细!E:E,"赛维斯",清洗后明细!D:D,"人机")>0,SUMIFS(清洗后明细!M:M,清洗后明细!A:A,"2026-03",清洗后明细!E:E,"赛维斯",清洗后明细!D:D,"人机")/SUMIFS(清洗后明细!N:N,清洗后明细!A:A,"2026-03",清洗后明细!E:E,"赛维斯",清洗后明细!D:D,"人机")*0.7,"") | G14: =IF(SUMIFS(清洗后明细!L:L,清洗后明细!A:A,"2026-03",清洗后明细!E:E,"赛维斯",清洗后明细!D:D,"人机")>0,SUMIFS(清洗后明细!I:I,清洗后明细!A:A,"2026-03",清洗后明细!E:E,"赛维斯",清洗后明细!D:D,"人机")/SUMIFS(清洗后明细!L:L,清洗后明细!A:A,"2026-03",清洗后明细!E:E,"赛维斯",清洗后明细!D:D,"人机")*100,"") | H14: =IF(SUMIFS(清洗后明细!F:F,清洗后明细!A:A,"2026-03",清洗后明细!E:E,"赛维斯",清洗后明细!D:D,"人机")>0,SUMIFS(清洗后明细!G:G,清洗后明细!A:A,"2026-03",清洗后明细!E:E,"赛维斯",清洗后明细!D:D,"人机")/SUMIFS(清洗后明细!F:F,清洗后明细!A:A,"2026-03",清洗后明细!E:E,"赛维斯",清洗后明细!D:D,"人机")*100,"") | I14: =IF(SUMIFS(清洗后明细!G:G,清洗后明细!A:A,"2026-03",清洗后明细!E:E,"赛维斯",清洗后明细!D:D,"人机")>0,SUMIFS(清洗后明细!H:H,清洗后明细!A:A,"2026-03",清洗后明细!E:E,"赛维斯",清洗后明细!D:D,"人机")/SUMIFS(清洗后明细!G:G,清洗后明细!A:A,"2026-03",清洗后明细!E:E,"赛维斯",清洗后明细!D:D,"人机"),"")
A15: 赛维斯 | B15: 2026-04 | C15: =SUMIFS(清洗后明细!M:M,清洗后明细!A:A,"2026-04",清洗后明细!E:E,"赛维斯",清洗后明细!D:D,"人机") | D15: =SUMIFS(清洗后明细!N:N,清洗后明细!A:A,"2026-04",清洗后明细!E:E,"赛维斯",清洗后明细!D:D,"人机") | E15: =IF(SUMIFS(清洗后明细!M:M,清洗后明细!A:A,"2026-04",清洗后明细!E:E,"赛维斯",清洗后明细!D:D,"人机")>0,SUMIFS(清洗后明细!M:M,清洗后明细!A:A,"2026-04",清洗后明细!E:E,"赛维斯",清洗后明细!D:D,"人机")/SUMIFS(清洗后明细!N:N,清洗后明细!A:A,"2026-04",清洗后明细!E:E,"赛维斯",清洗后明细!D:D,"人机"),"") | F15: =IF(SUMIFS(清洗后明细!M:M,清洗后明细!A:A,"2026-04",清洗后明细!E:E,"赛维斯",清洗后明细!D:D,"人机")>0,SUMIFS(清洗后明细!M:M,清洗后明细!A:A,"2026-04",清洗后明细!E:E,"赛维斯",清洗后明细!D:D,"人机")/SUMIFS(清洗后明细!N:N,清洗后明细!A:A,"2026-04",清洗后明细!E:E,"赛维斯",清洗后明细!D:D,"人机")*0.7,"") | G15: =IF(SUMIFS(清洗后明细!L:L,清洗后明细!A:A,"2026-04",清洗后明细!E:E,"赛维斯",清洗后明细!D:D,"人机")>0,SUMIFS(清洗后明细!I:I,清洗后明细!A:A,"2026-04",清洗后明细!E:E,"赛维斯",清洗后明细!D:D,"人机")/SUMIFS(清洗后明细!L:L,清洗后明细!A:A,"2026-04",清洗后明细!E:E,"赛维斯",清洗后明细!D:D,"人机")*100,"") | H15: =IF(SUMIFS(清洗后明细!F:F,清洗后明细!A:A,"2026-04",清洗后明细!E:E,"赛维斯",清洗后明细!D:D,"人机")>0,SUMIFS(清洗后明细!G:G,清洗后明细!A:A,"2026-04",清洗后明细!E:E,"赛维斯",清洗后明细!D:D,"人机")/SUMIFS(清洗后明细!F:F,清洗后明细!A:A,"2026-04",清洗后明细!E:E,"赛维斯",清洗后明细!D:D,"人机")*100,"") | I15: =IF(SUMIFS(清洗后明细!G:G,清洗后明细!A:A,"2026-04",清洗后明细!E:E,"赛维斯",清洗后明细!D:D,"人机")>0,SUMIFS(清洗后明细!H:H,清洗后明细!A:A,"2026-04",清洗后明细!E:E,"赛维斯",清洗后明细!D:D,"人机")/SUMIFS(清洗后明细!G:G,清洗后明细!A:A,"2026-04",清洗后明细!E:E,"赛维斯",清洗后明细!D:D,"人机"),"")
A16: 赛维斯 | B16: 2026-05 | C16: =SUMIFS(清洗后明细!M:M,清洗后明细!A:A,"2026-05",清洗后明细!E:E,"赛维斯",清洗后明细!D:D,"人机") | D16: =SUMIFS(清洗后明细!N:N,清洗后明细!A:A,"2026-05",清洗后明细!E:E,"赛维斯",清洗后明细!D:D,"人机") | E16: =IF(SUMIFS(清洗后明细!M:M,清洗后明细!A:A,"2026-05",清洗后明细!E:E,"赛维斯",清洗后明细!D:D,"人机")>0,SUMIFS(清洗后明细!M:M,清洗后明细!A:A,"2026-05",清洗后明细!E:E,"赛维斯",清洗后明细!D:D,"人机")/SUMIFS(清洗后明细!N:N,清洗后明细!A:A,"2026-05",清洗后明细!E:E,"赛维斯",清洗后明细!D:D,"人机"),"") | F16: =IF(SUMIFS(清洗后明细!M:M,清洗后明细!A:A,"2026-05",清洗后明细!E:E,"赛维斯",清洗后明细!D:D,"人机")>0,SUMIFS(清洗后明细!M:M,清洗后明细!A:A,"2026-05",清洗后明细!E:E,"赛维斯",清洗后明细!D:D,"人机")/SUMIFS(清洗后明细!N:N,清洗后明细!A:A,"2026-05",清洗后明细!E:E,"赛维斯",清洗后明细!D:D,"人机")*0.7,"") | G16: =IF(SUMIFS(清洗后明细!L:L,清洗后明细!A:A,"2026-05",清洗后明细!E:E,"赛维斯",清洗后明细!D:D,"人机")>0,SUMIFS(清洗后明细!I:I,清洗后明细!A:A,"2026-05",清洗后明细!E:E,"赛维斯",清洗后明细!D:D,"人机")/SUMIFS(清洗后明细!L:L,清洗后明细!A:A,"2026-05",清洗后明细!E:E,"赛维斯",清洗后明细!D:D,"人机")*100,"") | H16: =IF(SUMIFS(清洗后明细!F:F,清洗后明细!A:A,"2026-05",清洗后明细!E:E,"赛维斯",清洗后明细!D:D,"人机")>0,SUMIFS(清洗后明细!G:G,清洗后明细!A:A,"2026-05",清洗后明细!E:E,"赛维斯",清洗后明细!D:D,"人机")/SUMIFS(清洗后明细!F:F,清洗后明细!A:A,"2026-05",清洗后明细!E:E,"赛维斯",清洗后明细!D:D,"人机")*100,"") | I16: =IF(SUMIFS(清洗后明细!G:G,清洗后明细!A:A,"2026-05",清洗后明细!E:E,"赛维斯",清洗后明细!D:D,"人机")>0,SUMIFS(清洗后明细!H:H,清洗后明细!A:A,"2026-05",清洗后明细!E:E,"赛维斯",清洗后明细!D:D,"人机")/SUMIFS(清洗后明细!G:G,清洗后明细!A:A,"2026-05",清洗后明细!E:E,"赛维斯",清洗后明细!D:D,"人机"),"")
A17: 赛维斯 | B17: 2026-06 | C17: =SUMIFS(清洗后明细!M:M,清洗后明细!A:A,"2026-06",清洗后明细!E:E,"赛维斯",清洗后明细!D:D,"人机") | D17: =SUMIFS(清洗后明细!N:N,清洗后明细!A:A,"2026-06",清洗后明细!E:E,"赛维斯",清洗后明细!D:D,"人机") | E17: =IF(SUMIFS(清洗后明细!M:M,清洗后明细!A:A,"2026-06",清洗后明细!E:E,"赛维斯",清洗后明细!D:D,"人机")>0,SUMIFS(清洗后明细!M:M,清洗后明细!A:A,"2026-06",清洗后明细!E:E,"赛维斯",清洗后明细!D:D,"人机")/SUMIFS(清洗后明细!N:N,清洗后明细!A:A,"2026-06",清洗后明细!E:E,"赛维斯",清洗后明细!D:D,"人机"),"") | F17: =IF(SUMIFS(清洗后明细!M:M,清洗后明细!A:A,"2026-06",清洗后明细!E:E,"赛维斯",清洗后明细!D:D,"人机")>0,SUMIFS(清洗后明细!M:M,清洗后明细!A:A,"2026-06",清洗后明细!E:E,"赛维斯",清洗后明细!D:D,"人机")/SUMIFS(清洗后明细!N:N,清洗后明细!A:A,"2026-06",清洗后明细!E:E,"赛维斯",清洗后明细!D:D,"人机")*0.7,"") | G17: =IF(SUMIFS(清洗后明细!L:L,清洗后明细!A:A,"2026-06",清洗后明细!E:E,"赛维斯",清洗后明细!D:D,"人机")>0,SUMIFS(清洗后明细!I:I,清洗后明细!A:A,"2026-06",清洗后明细!E:E,"赛维斯",清洗后明细!D:D,"人机")/SUMIFS(清洗后明细!L:L,清洗后明细!A:A,"2026-06",清洗后明细!E:E,"赛维斯",清洗后明细!D:D,"人机")*100,"") | H17: =IF(SUMIFS(清洗后明细!F:F,清洗后明细!A:A,"2026-06",清洗后明细!E:E,"赛维斯",清洗后明细!D:D,"人机")>0,SUMIFS(清洗后明细!G:G,清洗后明细!A:A,"2026-06",清洗后明细!E:E,"赛维斯",清洗后明细!D:D,"人机")/SUMIFS(清洗后明细!F:F,清洗后明细!A:A,"2026-06",清洗后明细!E:E,"赛维斯",清洗后明细!D:D,"人机")*100,"") | I17: =IF(SUMIFS(清洗后明细!G:G,清洗后明细!A:A,"2026-06",清洗后明细!E:E,"赛维斯",清洗后明细!D:D,"人机")>0,SUMIFS(清洗后明细!H:H,清洗后明细!A:A,"2026-06",清洗后明细!E:E,"赛维斯",清洗后明细!D:D,"人机")/SUMIFS(清洗后明细!G:G,清洗后明细!A:A,"2026-06",清洗后明细!E:E,"赛维斯",清洗后明细!D:D,"人机"),"")
A18: 零犀 | B18: 2025-12 | C18: =SUMIFS(清洗后明细!M:M,清洗后明细!A:A,"2025-12",清洗后明细!E:E,"零犀",清洗后明细!D:D,"人机") | D18: =SUMIFS(清洗后明细!N:N,清洗后明细!A:A,"2025-12",清洗后明细!E:E,"零犀",清洗后明细!D:D,"人机") | E18: =IF(SUMIFS(清洗后明细!M:M,清洗后明细!A:A,"2025-12",清洗后明细!E:E,"零犀",清洗后明细!D:D,"人机")>0,SUMIFS(清洗后明细!M:M,清洗后明细!A:A,"2025-12",清洗后明细!E:E,"零犀",清洗后明细!D:D,"人机")/SUMIFS(清洗后明细!N:N,清洗后明细!A:A,"2025-12",清洗后明细!E:E,"零犀",清洗后明细!D:D,"人机"),"") | F18: =IF(SUMIFS(清洗后明细!M:M,清洗后明细!A:A,"2025-12",清洗后明细!E:E,"零犀",清洗后明细!D:D,"人机")>0,SUMIFS(清洗后明细!M:M,清洗后明细!A:A,"2025-12",清洗后明细!E:E,"零犀",清洗后明细!D:D,"人机")/SUMIFS(清洗后明细!N:N,清洗后明细!A:A,"2025-12",清洗后明细!E:E,"零犀",清洗后明细!D:D,"人机")*0.7,"") | G18: =IF(SUMIFS(清洗后明细!L:L,清洗后明细!A:A,"2025-12",清洗后明细!E:E,"零犀",清洗后明细!D:D,"人机")>0,SUMIFS(清洗后明细!I:I,清洗后明细!A:A,"2025-12",清洗后明细!E:E,"零犀",清洗后明细!D:D,"人机")/SUMIFS(清洗后明细!L:L,清洗后明细!A:A,"2025-12",清洗后明细!E:E,"零犀",清洗后明细!D:D,"人机")*100,"") | H18: =IF(SUMIFS(清洗后明细!F:F,清洗后明细!A:A,"2025-12",清洗后明细!E:E,"零犀",清洗后明细!D:D,"人机")>0,SUMIFS(清洗后明细!G:G,清洗后明细!A:A,"2025-12",清洗后明细!E:E,"零犀",清洗后明细!D:D,"人机")/SUMIFS(清洗后明细!F:F,清洗后明细!A:A,"2025-12",清洗后明细!E:E,"零犀",清洗后明细!D:D,"人机")*100,"") | I18: =IF(SUMIFS(清洗后明细!G:G,清洗后明细!A:A,"2025-12",清洗后明细!E:E,"零犀",清洗后明细!D:D,"人机")>0,SUMIFS(清洗后明细!H:H,清洗后明细!A:A,"2025-12",清洗后明细!E:E,"零犀",清洗后明细!D:D,"人机")/SUMIFS(清洗后明细!G:G,清洗后明细!A:A,"2025-12",清洗后明细!E:E,"零犀",清洗后明细!D:D,"人机"),"")
A19: 零犀 | B19: 2026-01 | C19: =SUMIFS(清洗后明细!M:M,清洗后明细!A:A,"2026-01",清洗后明细!E:E,"零犀",清洗后明细!D:D,"人机") | D19: =SUMIFS(清洗后明细!N:N,清洗后明细!A:A,"2026-01",清洗后明细!E:E,"零犀",清洗后明细!D:D,"人机") | E19: =IF(SUMIFS(清洗后明细!M:M,清洗后明细!A:A,"2026-01",清洗后明细!E:E,"零犀",清洗后明细!D:D,"人机")>0,SUMIFS(清洗后明细!M:M,清洗后明细!A:A,"2026-01",清洗后明细!E:E,"零犀",清洗后明细!D:D,"人机")/SUMIFS(清洗后明细!N:N,清洗后明细!A:A,"2026-01",清洗后明细!E:E,"零犀",清洗后明细!D:D,"人机"),"") | F19: =IF(SUMIFS(清洗后明细!M:M,清洗后明细!A:A,"2026-01",清洗后明细!E:E,"零犀",清洗后明细!D:D,"人机")>0,SUMIFS(清洗后明细!M:M,清洗后明细!A:A,"2026-01",清洗后明细!E:E,"零犀",清洗后明细!D:D,"人机")/SUMIFS(清洗后明细!N:N,清洗后明细!A:A,"2026-01",清洗后明细!E:E,"零犀",清洗后明细!D:D,"人机")*0.7,"") | G19: =IF(SUMIFS(清洗后明细!L:L,清洗后明细!A:A,"2026-01",清洗后明细!E:E,"零犀",清洗后明细!D:D,"人机")>0,SUMIFS(清洗后明细!I:I,清洗后明细!A:A,"2026-01",清洗后明细!E:E,"零犀",清洗后明细!D:D,"人机")/SUMIFS(清洗后明细!L:L,清洗后明细!A:A,"2026-01",清洗后明细!E:E,"零犀",清洗后明细!D:D,"人机")*100,"") | H19: =IF(SUMIFS(清洗后明细!F:F,清洗后明细!A:A,"2026-01",清洗后明细!E:E,"零犀",清洗后明细!D:D,"人机")>0,SUMIFS(清洗后明细!G:G,清洗后明细!A:A,"2026-01",清洗后明细!E:E,"零犀",清洗后明细!D:D,"人机")/SUMIFS(清洗后明细!F:F,清洗后明细!A:A,"2026-01",清洗后明细!E:E,"零犀",清洗后明细!D:D,"人机")*100,"") | I19: =IF(SUMIFS(清洗后明细!G:G,清洗后明细!A:A,"2026-01",清洗后明细!E:E,"零犀",清洗后明细!D:D,"人机")>0,SUMIFS(清洗后明细!H:H,清洗后明细!A:A,"2026-01",清洗后明细!E:E,"零犀",清洗后明细!D:D,"人机")/SUMIFS(清洗后明细!G:G,清洗后明细!A:A,"2026-01",清洗后明细!E:E,"零犀",清洗后明细!D:D,"人机"),"")
A20: 零犀 | B20: 2026-02 | C20: =SUMIFS(清洗后明细!M:M,清洗后明细!A:A,"2026-02",清洗后明细!E:E,"零犀",清洗后明细!D:D,"人机") | D20: =SUMIFS(清洗后明细!N:N,清洗后明细!A:A,"2026-02",清洗后明细!E:E,"零犀",清洗后明细!D:D,"人机") | E20: =IF(SUMIFS(清洗后明细!M:M,清洗后明细!A:A,"2026-02",清洗后明细!E:E,"零犀",清洗后明细!D:D,"人机")>0,SUMIFS(清洗后明细!M:M,清洗后明细!A:A,"2026-02",清洗后明细!E:E,"零犀",清洗后明细!D:D,"人机")/SUMIFS(清洗后明细!N:N,清洗后明细!A:A,"2026-02",清洗后明细!E:E,"零犀",清洗后明细!D:D,"人机"),"") | F20: =IF(SUMIFS(清洗后明细!M:M,清洗后明细!A:A,"2026-02",清洗后明细!E:E,"零犀",清洗后明细!D:D,"人机")>0,SUMIFS(清洗后明细!M:M,清洗后明细!A:A,"2026-02",清洗后明细!E:E,"零犀",清洗后明细!D:D,"人机")/SUMIFS(清洗后明细!N:N,清洗后明细!A:A,"2026-02",清洗后明细!E:E,"零犀",清洗后明细!D:D,"人机")*0.7,"") | G20: =IF(SUMIFS(清洗后明细!L:L,清洗后明细!A:A,"2026-02",清洗后明细!E:E,"零犀",清洗后明细!D:D,"人机")>0,SUMIFS(清洗后明细!I:I,清洗后明细!A:A,"2026-02",清洗后明细!E:E,"零犀",清洗后明细!D:D,"人机")/SUMIFS(清洗后明细!L:L,清洗后明细!A:A,"2026-02",清洗后明细!E:E,"零犀",清洗后明细!D:D,"人机")*100,"") | H20: =IF(SUMIFS(清洗后明细!F:F,清洗后明细!A:A,"2026-02",清洗后明细!E:E,"零犀",清洗后明细!D:D,"人机")>0,SUMIFS(清洗后明细!G:G,清洗后明细!A:A,"2026-02",清洗后明细!E:E,"零犀",清洗后明细!D:D,"人机")/SUMIFS(清洗后明细!F:F,清洗后明细!A:A,"2026-02",清洗后明细!E:E,"零犀",清洗后明细!D:D,"人机")*100,"") | I20: =IF(SUMIFS(清洗后明细!G:G,清洗后明细!A:A,"2026-02",清洗后明细!E:E,"零犀",清洗后明细!D:D,"人机")>0,SUMIFS(清洗后明细!H:H,清洗后明细!A:A,"2026-02",清洗后明细!E:E,"零犀",清洗后明细!D:D,"人机")/SUMIFS(清洗后明细!G:G,清洗后明细!A:A,"2026-02",清洗后明细!E:E,"零犀",清洗后明细!D:D,"人机"),"")
A21: 零犀 | B21: 2026-03 | C21: =SUMIFS(清洗后明细!M:M,清洗后明细!A:A,"2026-03",清洗后明细!E:E,"零犀",清洗后明细!D:D,"人机") | D21: =SUMIFS(清洗后明细!N:N,清洗后明细!A:A,"2026-03",清洗后明细!E:E,"零犀",清洗后明细!D:D,"人机") | E21: =IF(SUMIFS(清洗后明细!M:M,清洗后明细!A:A,"2026-03",清洗后明细!E:E,"零犀",清洗后明细!D:D,"人机")>0,SUMIFS(清洗后明细!M:M,清洗后明细!A:A,"2026-03",清洗后明细!E:E,"零犀",清洗后明细!D:D,"人机")/SUMIFS(清洗后明细!N:N,清洗后明细!A:A,"2026-03",清洗后明细!E:E,"零犀",清洗后明细!D:D,"人机"),"") | F21: =IF(SUMIFS(清洗后明细!M:M,清洗后明细!A:A,"2026-03",清洗后明细!E:E,"零犀",清洗后明细!D:D,"人机")>0,SUMIFS(清洗后明细!M:M,清洗后明细!A:A,"2026-03",清洗后明细!E:E,"零犀",清洗后明细!D:D,"人机")/SUMIFS(清洗后明细!N:N,清洗后明细!A:A,"2026-03",清洗后明细!E:E,"零犀",清洗后明细!D:D,"人机")*0.7,"") | G21: =IF(SUMIFS(清洗后明细!L:L,清洗后明细!A:A,"2026-03",清洗后明细!E:E,"零犀",清洗后明细!D:D,"人机")>0,SUMIFS(清洗后明细!I:I,清洗后明细!A:A,"2026-03",清洗后明细!E:E,"零犀",清洗后明细!D:D,"人机")/SUMIFS(清洗后明细!L:L,清洗后明细!A:A,"2026-03",清洗后明细!E:E,"零犀",清洗后明细!D:D,"人机")*100,"") | H21: =IF(SUMIFS(清洗后明细!F:F,清洗后明细!A:A,"2026-03",清洗后明细!E:E,"零犀",清洗后明细!D:D,"人机")>0,SUMIFS(清洗后明细!G:G,清洗后明细!A:A,"2026-03",清洗后明细!E:E,"零犀",清洗后明细!D:D,"人机")/SUMIFS(清洗后明细!F:F,清洗后明细!A:A,"2026-03",清洗后明细!E:E,"零犀",清洗后明细!D:D,"人机")*100,"") | I21: =IF(SUMIFS(清洗后明细!G:G,清洗后明细!A:A,"2026-03",清洗后明细!E:E,"零犀",清洗后明细!D:D,"人机")>0,SUMIFS(清洗后明细!H:H,清洗后明细!A:A,"2026-03",清洗后明细!E:E,"零犀",清洗后明细!D:D,"人机")/SUMIFS(清洗后明细!G:G,清洗后明细!A:A,"2026-03",清洗后明细!E:E,"零犀",清洗后明细!D:D,"人机"),"")
A22: 零犀 | B22: 2026-04 | C22: =SUMIFS(清洗后明细!M:M,清洗后明细!A:A,"2026-04",清洗后明细!E:E,"零犀",清洗后明细!D:D,"人机") | D22: =SUMIFS(清洗后明细!N:N,清洗后明细!A:A,"2026-04",清洗后明细!E:E,"零犀",清洗后明细!D:D,"人机") | E22: =IF(SUMIFS(清洗后明细!M:M,清洗后明细!A:A,"2026-04",清洗后明细!E:E,"零犀",清洗后明细!D:D,"人机")>0,SUMIFS(清洗后明细!M:M,清洗后明细!A:A,"2026-04",清洗后明细!E:E,"零犀",清洗后明细!D:D,"人机")/SUMIFS(清洗后明细!N:N,清洗后明细!A:A,"2026-04",清洗后明细!E:E,"零犀",清洗后明细!D:D,"人机"),"") | F22: =IF(SUMIFS(清洗后明细!M:M,清洗后明细!A:A,"2026-04",清洗后明细!E:E,"零犀",清洗后明细!D:D,"人机")>0,SUMIFS(清洗后明细!M:M,清洗后明细!A:A,"2026-04",清洗后明细!E:E,"零犀",清洗后明细!D:D,"人机")/SUMIFS(清洗后明细!N:N,清洗后明细!A:A,"2026-04",清洗后明细!E:E,"零犀",清洗后明细!D:D,"人机")*0.7,"") | G22: =IF(SUMIFS(清洗后明细!L:L,清洗后明细!A:A,"2026-04",清洗后明细!E:E,"零犀",清洗后明细!D:D,"人机")>0,SUMIFS(清洗后明细!I:I,清洗后明细!A:A,"2026-04",清洗后明细!E:E,"零犀",清洗后明细!D:D,"人机")/SUMIFS(清洗后明细!L:L,清洗后明细!A:A,"2026-04",清洗后明细!E:E,"零犀",清洗后明细!D:D,"人机")*100,"") | H22: =IF(SUMIFS(清洗后明细!F:F,清洗后明细!A:A,"2026-04",清洗后明细!E:E,"零犀",清洗后明细!D:D,"人机")>0,SUMIFS(清洗后明细!G:G,清洗后明细!A:A,"2026-04",清洗后明细!E:E,"零犀",清洗后明细!D:D,"人机")/SUMIFS(清洗后明细!F:F,清洗后明细!A:A,"2026-04",清洗后明细!E:E,"零犀",清洗后明细!D:D,"人机")*100,"") | I22: =IF(SUMIFS(清洗后明细!G:G,清洗后明细!A:A,"2026-04",清洗后明细!E:E,"零犀",清洗后明细!D:D,"人机")>0,SUMIFS(清洗后明细!H:H,清洗后明细!A:A,"2026-04",清洗后明细!E:E,"零犀",清洗后明细!D:D,"人机")/SUMIFS(清洗后明细!G:G,清洗后明细!A:A,"2026-04",清洗后明细!E:E,"零犀",清洗后明细!D:D,"人机"),"")
A23: 零犀 | B23: 2026-05 | C23: =SUMIFS(清洗后明细!M:M,清洗后明细!A:A,"2026-05",清洗后明细!E:E,"零犀",清洗后明细!D:D,"人机") | D23: =SUMIFS(清洗后明细!N:N,清洗后明细!A:A,"2026-05",清洗后明细!E:E,"零犀",清洗后明细!D:D,"人机") | E23: =IF(SUMIFS(清洗后明细!M:M,清洗后明细!A:A,"2026-05",清洗后明细!E:E,"零犀",清洗后明细!D:D,"人机")>0,SUMIFS(清洗后明细!M:M,清洗后明细!A:A,"2026-05",清洗后明细!E:E,"零犀",清洗后明细!D:D,"人机")/SUMIFS(清洗后明细!N:N,清洗后明细!A:A,"2026-05",清洗后明细!E:E,"零犀",清洗后明细!D:D,"人机"),"") | F23: =IF(SUMIFS(清洗后明细!M:M,清洗后明细!A:A,"2026-05",清洗后明细!E:E,"零犀",清洗后明细!D:D,"人机")>0,SUMIFS(清洗后明细!M:M,清洗后明细!A:A,"2026-05",清洗后明细!E:E,"零犀",清洗后明细!D:D,"人机")/SUMIFS(清洗后明细!N:N,清洗后明细!A:A,"2026-05",清洗后明细!E:E,"零犀",清洗后明细!D:D,"人机")*0.7,"") | G23: =IF(SUMIFS(清洗后明细!L:L,清洗后明细!A:A,"2026-05",清洗后明细!E:E,"零犀",清洗后明细!D:D,"人机")>0,SUMIFS(清洗后明细!I:I,清洗后明细!A:A,"2026-05",清洗后明细!E:E,"零犀",清洗后明细!D:D,"人机")/SUMIFS(清洗后明细!L:L,清洗后明细!A:A,"2026-05",清洗后明细!E:E,"零犀",清洗后明细!D:D,"人机")*100,"") | H23: =IF(SUMIFS(清洗后明细!F:F,清洗后明细!A:A,"2026-05",清洗后明细!E:E,"零犀",清洗后明细!D:D,"人机")>0,SUMIFS(清洗后明细!G:G,清洗后明细!A:A,"2026-05",清洗后明细!E:E,"零犀",清洗后明细!D:D,"人机")/SUMIFS(清洗后明细!F:F,清洗后明细!A:A,"2026-05",清洗后明细!E:E,"零犀",清洗后明细!D:D,"人机")*100,"") | I23: =IF(SUMIFS(清洗后明细!G:G,清洗后明细!A:A,"2026-05",清洗后明细!E:E,"零犀",清洗后明细!D:D,"人机")>0,SUMIFS(清洗后明细!H:H,清洗后明细!A:A,"2026-05",清洗后明细!E:E,"零犀",清洗后明细!D:D,"人机")/SUMIFS(清洗后明细!G:G,清洗后明细!A:A,"2026-05",清洗后明细!E:E,"零犀",清洗后明细!D:D,"人机"),"")
A24: 零犀 | B24: 2026-06 | C24: =SUMIFS(清洗后明细!M:M,清洗后明细!A:A,"2026-06",清洗后明细!E:E,"零犀",清洗后明细!D:D,"人机") | D24: =SUMIFS(清洗后明细!N:N,清洗后明细!A:A,"2026-06",清洗后明细!E:E,"零犀",清洗后明细!D:D,"人机") | E24: =IF(SUMIFS(清洗后明细!M:M,清洗后明细!A:A,"2026-06",清洗后明细!E:E,"零犀",清洗后明细!D:D,"人机")>0,SUMIFS(清洗后明细!M:M,清洗后明细!A:A,"2026-06",清洗后明细!E:E,"零犀",清洗后明细!D:D,"人机")/SUMIFS(清洗后明细!N:N,清洗后明细!A:A,"2026-06",清洗后明细!E:E,"零犀",清洗后明细!D:D,"人机"),"") | F24: =IF(SUMIFS(清洗后明细!M:M,清洗后明细!A:A,"2026-06",清洗后明细!E:E,"零犀",清洗后明细!D:D,"人机")>0,SUMIFS(清洗后明细!M:M,清洗后明细!A:A,"2026-06",清洗后明细!E:E,"零犀",清洗后明细!D:D,"人机")/SUMIFS(清洗后明细!N:N,清洗后明细!A:A,"2026-06",清洗后明细!E:E,"零犀",清洗后明细!D:D,"人机")*0.7,"") | G24: =IF(SUMIFS(清洗后明细!L:L,清洗后明细!A:A,"2026-06",清洗后明细!E:E,"零犀",清洗后明细!D:D,"人机")>0,SUMIFS(清洗后明细!I:I,清洗后明细!A:A,"2026-06",清洗后明细!E:E,"零犀",清洗后明细!D:D,"人机")/SUMIFS(清洗后明细!L:L,清洗后明细!A:A,"2026-06",清洗后明细!E:E,"零犀",清洗后明细!D:D,"人机")*100,"") | H24: =IF(SUMIFS(清洗后明细!F:F,清洗后明细!A:A,"2026-06",清洗后明细!E:E,"零犀",清洗后明细!D:D,"人机")>0,SUMIFS(清洗后明细!G:G,清洗后明细!A:A,"2026-06",清洗后明细!E:E,"零犀",清洗后明细!D:D,"人机")/SUMIFS(清洗后明细!F:F,清洗后明细!A:A,"2026-06",清洗后明细!E:E,"零犀",清洗后明细!D:D,"人机")*100,"") | I24: =IF(SUMIFS(清洗后明细!G:G,清洗后明细!A:A,"2026-06",清洗后明细!E:E,"零犀",清洗后明细!D:D,"人机")>0,SUMIFS(清洗后明细!H:H,清洗后明细!A:A,"2026-06",清洗后明细!E:E,"零犀",清洗后明细!D:D,"人机")/SUMIFS(清洗后明细!G:G,清洗后明细!A:A,"2026-06",清洗后明细!E:E,"零犀",清洗后明细!D:D,"人机"),"")
A25: 零犀伽玛 | B25: 2025-12 | C25: =SUMIFS(清洗后明细!M:M,清洗后明细!A:A,"2025-12",清洗后明细!E:E,"零犀伽玛",清洗后明细!D:D,"人机") | D25: =SUMIFS(清洗后明细!N:N,清洗后明细!A:A,"2025-12",清洗后明细!E:E,"零犀伽玛",清洗后明细!D:D,"人机") | E25: =IF(SUMIFS(清洗后明细!M:M,清洗后明细!A:A,"2025-12",清洗后明细!E:E,"零犀伽玛",清洗后明细!D:D,"人机")>0,SUMIFS(清洗后明细!M:M,清洗后明细!A:A,"2025-12",清洗后明细!E:E,"零犀伽玛",清洗后明细!D:D,"人机")/SUMIFS(清洗后明细!N:N,清洗后明细!A:A,"2025-12",清洗后明细!E:E,"零犀伽玛",清洗后明细!D:D,"人机"),"") | F25: =IF(SUMIFS(清洗后明细!M:M,清洗后明细!A:A,"2025-12",清洗后明细!E:E,"零犀伽玛",清洗后明细!D:D,"人机")>0,SUMIFS(清洗后明细!M:M,清洗后明细!A:A,"2025-12",清洗后明细!E:E,"零犀伽玛",清洗后明细!D:D,"人机")/SUMIFS(清洗后明细!N:N,清洗后明细!A:A,"2025-12",清洗后明细!E:E,"零犀伽玛",清洗后明细!D:D,"人机")*0.7,"") | G25: =IF(SUMIFS(清洗后明细!L:L,清洗后明细!A:A,"2025-12",清洗后明细!E:E,"零犀伽玛",清洗后明细!D:D,"人机")>0,SUMIFS(清洗后明细!I:I,清洗后明细!A:A,"2025-12",清洗后明细!E:E,"零犀伽玛",清洗后明细!D:D,"人机")/SUMIFS(清洗后明细!L:L,清洗后明细!A:A,"2025-12",清洗后明细!E:E,"零犀伽玛",清洗后明细!D:D,"人机")*100,"") | H25: =IF(SUMIFS(清洗后明细!F:F,清洗后明细!A:A,"2025-12",清洗后明细!E:E,"零犀伽玛",清洗后明细!D:D,"人机")>0,SUMIFS(清洗后明细!G:G,清洗后明细!A:A,"2025-12",清洗后明细!E:E,"零犀伽玛",清洗后明细!D:D,"人机")/SUMIFS(清洗后明细!F:F,清洗后明细!A:A,"2025-12",清洗后明细!E:E,"零犀伽玛",清洗后明细!D:D,"人机")*100,"") | I25: =IF(SUMIFS(清洗后明细!G:G,清洗后明细!A:A,"2025-12",清洗后明细!E:E,"零犀伽玛",清洗后明细!D:D,"人机")>0,SUMIFS(清洗后明细!H:H,清洗后明细!A:A,"2025-12",清洗后明细!E:E,"零犀伽玛",清洗后明细!D:D,"人机")/SUMIFS(清洗后明细!G:G,清洗后明细!A:A,"2025-12",清洗后明细!E:E,"零犀伽玛",清洗后明细!D:D,"人机"),"")
A26: 零犀伽玛 | B26: 2026-01 | C26: =SUMIFS(清洗后明细!M:M,清洗后明细!A:A,"2026-01",清洗后明细!E:E,"零犀伽玛",清洗后明细!D:D,"人机") | D26: =SUMIFS(清洗后明细!N:N,清洗后明细!A:A,"2026-01",清洗后明细!E:E,"零犀伽玛",清洗后明细!D:D,"人机") | E26: =IF(SUMIFS(清洗后明细!M:M,清洗后明细!A:A,"2026-01",清洗后明细!E:E,"零犀伽玛",清洗后明细!D:D,"人机")>0,SUMIFS(清洗后明细!M:M,清洗后明细!A:A,"2026-01",清洗后明细!E:E,"零犀伽玛",清洗后明细!D:D,"人机")/SUMIFS(清洗后明细!N:N,清洗后明细!A:A,"2026-01",清洗后明细!E:E,"零犀伽玛",清洗后明细!D:D,"人机"),"") | F26: =IF(SUMIFS(清洗后明细!M:M,清洗后明细!A:A,"2026-01",清洗后明细!E:E,"零犀伽玛",清洗后明细!D:D,"人机")>0,SUMIFS(清洗后明细!M:M,清洗后明细!A:A,"2026-01",清洗后明细!E:E,"零犀伽玛",清洗后明细!D:D,"人机")/SUMIFS(清洗后明细!N:N,清洗后明细!A:A,"2026-01",清洗后明细!E:E,"零犀伽玛",清洗后明细!D:D,"人机")*0.7,"") | G26: =IF(SUMIFS(清洗后明细!L:L,清洗后明细!A:A,"2026-01",清洗后明细!E:E,"零犀伽玛",清洗后明细!D:D,"人机")>0,SUMIFS(清洗后明细!I:I,清洗后明细!A:A,"2026-01",清洗后明细!E:E,"零犀伽玛",清洗后明细!D:D,"人机")/SUMIFS(清洗后明细!L:L,清洗后明细!A:A,"2026-01",清洗后明细!E:E,"零犀伽玛",清洗后明细!D:D,"人机")*100,"") | H26: =IF(SUMIFS(清洗后明细!F:F,清洗后明细!A:A,"2026-01",清洗后明细!E:E,"零犀伽玛",清洗后明细!D:D,"人机")>0,SUMIFS(清洗后明细!G:G,清洗后明细!A:A,"2026-01",清洗后明细!E:E,"零犀伽玛",清洗后明细!D:D,"人机")/SUMIFS(清洗后明细!F:F,清洗后明细!A:A,"2026-01",清洗后明细!E:E,"零犀伽玛",清洗后明细!D:D,"人机")*100,"") | I26: =IF(SUMIFS(清洗后明细!G:G,清洗后明细!A:A,"2026-01",清洗后明细!E:E,"零犀伽玛",清洗后明细!D:D,"人机")>0,SUMIFS(清洗后明细!H:H,清洗后明细!A:A,"2026-01",清洗后明细!E:E,"零犀伽玛",清洗后明细!D:D,"人机")/SUMIFS(清洗后明细!G:G,清洗后明细!A:A,"2026-01",清洗后明细!E:E,"零犀伽玛",清洗后明细!D:D,"人机"),"")
A27: 零犀伽玛 | B27: 2026-02 | C27: =SUMIFS(清洗后明细!M:M,清洗后明细!A:A,"2026-02",清洗后明细!E:E,"零犀伽玛",清洗后明细!D:D,"人机") | D27: =SUMIFS(清洗后明细!N:N,清洗后明细!A:A,"2026-02",清洗后明细!E:E,"零犀伽玛",清洗后明细!D:D,"人机") | E27: =IF(SUMIFS(清洗后明细!M:M,清洗后明细!A:A,"2026-02",清洗后明细!E:E,"零犀伽玛",清洗后明细!D:D,"人机")>0,SUMIFS(清洗后明细!M:M,清洗后明细!A:A,"2026-02",清洗后明细!E:E,"零犀伽玛",清洗后明细!D:D,"人机")/SUMIFS(清洗后明细!N:N,清洗后明细!A:A,"2026-02",清洗后明细!E:E,"零犀伽玛",清洗后明细!D:D,"人机"),"") | F27: =IF(SUMIFS(清洗后明细!M:M,清洗后明细!A:A,"2026-02",清洗后明细!E:E,"零犀伽玛",清洗后明细!D:D,"人机")>0,SUMIFS(清洗后明细!M:M,清洗后明细!A:A,"2026-02",清洗后明细!E:E,"零犀伽玛",清洗后明细!D:D,"人机")/SUMIFS(清洗后明细!N:N,清洗后明细!A:A,"2026-02",清洗后明细!E:E,"零犀伽玛",清洗后明细!D:D,"人机")*0.7,"") | G27: =IF(SUMIFS(清洗后明细!L:L,清洗后明细!A:A,"2026-02",清洗后明细!E:E,"零犀伽玛",清洗后明细!D:D,"人机")>0,SUMIFS(清洗后明细!I:I,清洗后明细!A:A,"2026-02",清洗后明细!E:E,"零犀伽玛",清洗后明细!D:D,"人机")/SUMIFS(清洗后明细!L:L,清洗后明细!A:A,"2026-02",清洗后明细!E:E,"零犀伽玛",清洗后明细!D:D,"人机")*100,"") | H27: =IF(SUMIFS(清洗后明细!F:F,清洗后明细!A:A,"2026-02",清洗后明细!E:E,"零犀伽玛",清洗后明细!D:D,"人机")>0,SUMIFS(清洗后明细!G:G,清洗后明细!A:A,"2026-02",清洗后明细!E:E,"零犀伽玛",清洗后明细!D:D,"人机")/SUMIFS(清洗后明细!F:F,清洗后明细!A:A,"2026-02",清洗后明细!E:E,"零犀伽玛",清洗后明细!D:D,"人机")*100,"") | I27: =IF(SUMIFS(清洗后明细!G:G,清洗后明细!A:A,"2026-02",清洗后明细!E:E,"零犀伽玛",清洗后明细!D:D,"人机")>0,SUMIFS(清洗后明细!H:H,清洗后明细!A:A,"2026-02",清洗后明细!E:E,"零犀伽玛",清洗后明细!D:D,"人机")/SUMIFS(清洗后明细!G:G,清洗后明细!A:A,"2026-02",清洗后明细!E:E,"零犀伽玛",清洗后明细!D:D,"人机"),"")
A28: 零犀伽玛 | B28: 2026-03 | C28: =SUMIFS(清洗后明细!M:M,清洗后明细!A:A,"2026-03",清洗后明细!E:E,"零犀伽玛",清洗后明细!D:D,"人机") | D28: =SUMIFS(清洗后明细!N:N,清洗后明细!A:A,"2026-03",清洗后明细!E:E,"零犀伽玛",清洗后明细!D:D,"人机") | E28: =IF(SUMIFS(清洗后明细!M:M,清洗后明细!A:A,"2026-03",清洗后明细!E:E,"零犀伽玛",清洗后明细!D:D,"人机")>0,SUMIFS(清洗后明细!M:M,清洗后明细!A:A,"2026-03",清洗后明细!E:E,"零犀伽玛",清洗后明细!D:D,"人机")/SUMIFS(清洗后明细!N:N,清洗后明细!A:A,"2026-03",清洗后明细!E:E,"零犀伽玛",清洗后明细!D:D,"人机"),"") | F28: =IF(SUMIFS(清洗后明细!M:M,清洗后明细!A:A,"2026-03",清洗后明细!E:E,"零犀伽玛",清洗后明细!D:D,"人机")>0,SUMIFS(清洗后明细!M:M,清洗后明细!A:A,"2026-03",清洗后明细!E:E,"零犀伽玛",清洗后明细!D:D,"人机")/SUMIFS(清洗后明细!N:N,清洗后明细!A:A,"2026-03",清洗后明细!E:E,"零犀伽玛",清洗后明细!D:D,"人机")*0.7,"") | G28: =IF(SUMIFS(清洗后明细!L:L,清洗后明细!A:A,"2026-03",清洗后明细!E:E,"零犀伽玛",清洗后明细!D:D,"人机")>0,SUMIFS(清洗后明细!I:I,清洗后明细!A:A,"2026-03",清洗后明细!E:E,"零犀伽玛",清洗后明细!D:D,"人机")/SUMIFS(清洗后明细!L:L,清洗后明细!A:A,"2026-03",清洗后明细!E:E,"零犀伽玛",清洗后明细!D:D,"人机")*100,"") | H28: =IF(SUMIFS(清洗后明细!F:F,清洗后明细!A:A,"2026-03",清洗后明细!E:E,"零犀伽玛",清洗后明细!D:D,"人机")>0,SUMIFS(清洗后明细!G:G,清洗后明细!A:A,"2026-03",清洗后明细!E:E,"零犀伽玛",清洗后明细!D:D,"人机")/SUMIFS(清洗后明细!F:F,清洗后明细!A:A,"2026-03",清洗后明细!E:E,"零犀伽玛",清洗后明细!D:D,"人机")*100,"") | I28: =IF(SUMIFS(清洗后明细!G:G,清洗后明细!A:A,"2026-03",清洗后明细!E:E,"零犀伽玛",清洗后明细!D:D,"人机")>0,SUMIFS(清洗后明细!H:H,清洗后明细!A:A,"2026-03",清洗后明细!E:E,"零犀伽玛",清洗后明细!D:D,"人机")/SUMIFS(清洗后明细!G:G,清洗后明细!A:A,"2026-03",清洗后明细!E:E,"零犀伽玛",清洗后明细!D:D,"人机"),"")
A29: 零犀伽玛 | B29: 2026-04 | C29: =SUMIFS(清洗后明细!M:M,清洗后明细!A:A,"2026-04",清洗后明细!E:E,"零犀伽玛",清洗后明细!D:D,"人机") | D29: =SUMIFS(清洗后明细!N:N,清洗后明细!A:A,"2026-04",清洗后明细!E:E,"零犀伽玛",清洗后明细!D:D,"人机") | E29: =IF(SUMIFS(清洗后明细!M:M,清洗后明细!A:A,"2026-04",清洗后明细!E:E,"零犀伽玛",清洗后明细!D:D,"人机")>0,SUMIFS(清洗后明细!M:M,清洗后明细!A:A,"2026-04",清洗后明细!E:E,"零犀伽玛",清洗后明细!D:D,"人机")/SUMIFS(清洗后明细!N:N,清洗后明细!A:A,"2026-04",清洗后明细!E:E,"零犀伽玛",清洗后明细!D:D,"人机"),"") | F29: =IF(SUMIFS(清洗后明细!M:M,清洗后明细!A:A,"2026-04",清洗后明细!E:E,"零犀伽玛",清洗后明细!D:D,"人机")>0,SUMIFS(清洗后明细!M:M,清洗后明细!A:A,"2026-04",清洗后明细!E:E,"零犀伽玛",清洗后明细!D:D,"人机")/SUMIFS(清洗后明细!N:N,清洗后明细!A:A,"2026-04",清洗后明细!E:E,"零犀伽玛",清洗后明细!D:D,"人机")*0.7,"") | G29: =IF(SUMIFS(清洗后明细!L:L,清洗后明细!A:A,"2026-04",清洗后明细!E:E,"零犀伽玛",清洗后明细!D:D,"人机")>0,SUMIFS(清洗后明细!I:I,清洗后明细!A:A,"2026-04",清洗后明细!E:E,"零犀伽玛",清洗后明细!D:D,"人机")/SUMIFS(清洗后明细!L:L,清洗后明细!A:A,"2026-04",清洗后明细!E:E,"零犀伽玛",清洗后明细!D:D,"人机")*100,"") | H29: =IF(SUMIFS(清洗后明细!F:F,清洗后明细!A:A,"2026-04",清洗后明细!E:E,"零犀伽玛",清洗后明细!D:D,"人机")>0,SUMIFS(清洗后明细!G:G,清洗后明细!A:A,"2026-04",清洗后明细!E:E,"零犀伽玛",清洗后明细!D:D,"人机")/SUMIFS(清洗后明细!F:F,清洗后明细!A:A,"2026-04",清洗后明细!E:E,"零犀伽玛",清洗后明细!D:D,"人机")*100,"") | I29: =IF(SUMIFS(清洗后明细!G:G,清洗后明细!A:A,"2026-04",清洗后明细!E:E,"零犀伽玛",清洗后明细!D:D,"人机")>0,SUMIFS(清洗后明细!H:H,清洗后明细!A:A,"2026-04",清洗后明细!E:E,"零犀伽玛",清洗后明细!D:D,"人机")/SUMIFS(清洗后明细!G:G,清洗后明细!A:A,"2026-04",清洗后明细!E:E,"零犀伽玛",清洗后明细!D:D,"人机"),"")
A30: 零犀伽玛 | B30: 2026-05 | C30: =SUMIFS(清洗后明细!M:M,清洗后明细!A:A,"2026-05",清洗后明细!E:E,"零犀伽玛",清洗后明细!D:D,"人机") | D30: =SUMIFS(清洗后明细!N:N,清洗后明细!A:A,"2026-05",清洗后明细!E:E,"零犀伽玛",清洗后明细!D:D,"人机") | E30: =IF(SUMIFS(清洗后明细!M:M,清洗后明细!A:A,"2026-05",清洗后明细!E:E,"零犀伽玛",清洗后明细!D:D,"人机")>0,SUMIFS(清洗后明细!M:M,清洗后明细!A:A,"2026-05",清洗后明细!E:E,"零犀伽玛",清洗后明细!D:D,"人机")/SUMIFS(清洗后明细!N:N,清洗后明细!A:A,"2026-05",清洗后明细!E:E,"零犀伽玛",清洗后明细!D:D,"人机"),"") | F30: =IF(SUMIFS(清洗后明细!M:M,清洗后明细!A:A,"2026-05",清洗后明细!E:E,"零犀伽玛",清洗后明细!D:D,"人机")>0,SUMIFS(清洗后明细!M:M,清洗后明细!A:A,"2026-05",清洗后明细!E:E,"零犀伽玛",清洗后明细!D:D,"人机")/SUMIFS(清洗后明细!N:N,清洗后明细!A:A,"2026-05",清洗后明细!E:E,"零犀伽玛",清洗后明细!D:D,"人机")*0.7,"") | G30: =IF(SUMIFS(清洗后明细!L:L,清洗后明细!A:A,"2026-05",清洗后明细!E:E,"零犀伽玛",清洗后明细!D:D,"人机")>0,SUMIFS(清洗后明细!I:I,清洗后明细!A:A,"2026-05",清洗后明细!E:E,"零犀伽玛",清洗后明细!D:D,"人机")/SUMIFS(清洗后明细!L:L,清洗后明细!A:A,"2026-05",清洗后明细!E:E,"零犀伽玛",清洗后明细!D:D,"人机")*100,"") | H30: =IF(SUMIFS(清洗后明细!F:F,清洗后明细!A:A,"2026-05",清洗后明细!E:E,"零犀伽玛",清洗后明细!D:D,"人机")>0,SUMIFS(清洗后明细!G:G,清洗后明细!A:A,"2026-05",清洗后明细!E:E,"零犀伽玛",清洗后明细!D:D,"人机")/SUMIFS(清洗后明细!F:F,清洗后明细!A:A,"2026-05",清洗后明细!E:E,"零犀伽玛",清洗后明细!D:D,"人机")*100,"") | I30: =IF(SUMIFS(清洗后明细!G:G,清洗后明细!A:A,"2026-05",清洗后明细!E:E,"零犀伽玛",清洗后明细!D:D,"人机")>0,SUMIFS(清洗后明细!H:H,清洗后明细!A:A,"2026-05",清洗后明细!E:E,"零犀伽玛",清洗后明细!D:D,"人机")/SUMIFS(清洗后明细!G:G,清洗后明细!A:A,"2026-05",清洗后明细!E:E,"零犀伽玛",清洗后明细!D:D,"人机"),"")
A31: 零犀伽玛 | B31: 2026-06 | C31: =SUMIFS(清洗后明细!M:M,清洗后明细!A:A,"2026-06",清洗后明细!E:E,"零犀伽玛",清洗后明细!D:D,"人机") | D31: =SUMIFS(清洗后明细!N:N,清洗后明细!A:A,"2026-06",清洗后明细!E:E,"零犀伽玛",清洗后明细!D:D,"人机") | E31: =IF(SUMIFS(清洗后明细!M:M,清洗后明细!A:A,"2026-06",清洗后明细!E:E,"零犀伽玛",清洗后明细!D:D,"人机")>0,SUMIFS(清洗后明细!M:M,清洗后明细!A:A,"2026-06",清洗后明细!E:E,"零犀伽玛",清洗后明细!D:D,"人机")/SUMIFS(清洗后明细!N:N,清洗后明细!A:A,"2026-06",清洗后明细!E:E,"零犀伽玛",清洗后明细!D:D,"人机"),"") | F31: =IF(SUMIFS(清洗后明细!M:M,清洗后明细!A:A,"2026-06",清洗后明细!E:E,"零犀伽玛",清洗后明细!D:D,"人机")>0,SUMIFS(清洗后明细!M:M,清洗后明细!A:A,"2026-06",清洗后明细!E:E,"零犀伽玛",清洗后明细!D:D,"人机")/SUMIFS(清洗后明细!N:N,清洗后明细!A:A,"2026-06",清洗后明细!E:E,"零犀伽玛",清洗后明细!D:D,"人机")*0.7,"") | G31: =IF(SUMIFS(清洗后明细!L:L,清洗后明细!A:A,"2026-06",清洗后明细!E:E,"零犀伽玛",清洗后明细!D:D,"人机")>0,SUMIFS(清洗后明细!I:I,清洗后明细!A:A,"2026-06",清洗后明细!E:E,"零犀伽玛",清洗后明细!D:D,"人机")/SUMIFS(清洗后明细!L:L,清洗后明细!A:A,"2026-06",清洗后明细!E:E,"零犀伽玛",清洗后明细!D:D,"人机")*100,"") | H31: =IF(SUMIFS(清洗后明细!F:F,清洗后明细!A:A,"2026-06",清洗后明细!E:E,"零犀伽玛",清洗后明细!D:D,"人机")>0,SUMIFS(清洗后明细!G:G,清洗后明细!A:A,"2026-06",清洗后明细!E:E,"零犀伽玛",清洗后明细!D:D,"人机")/SUMIFS(清洗后明细!F:F,清洗后明细!A:A,"2026-06",清洗后明细!E:E,"零犀伽玛",清洗后明细!D:D,"人机")*100,"") | I31: =IF(SUMIFS(清洗后明细!G:G,清洗后明细!A:A,"2026-06",清洗后明细!E:E,"零犀伽玛",清洗后明细!D:D,"人机")>0,SUMIFS(清洗后明细!H:H,清洗后明细!A:A,"2026-06",清洗后明细!E:E,"零犀伽玛",清洗后明细!D:D,"人机")/SUMIFS(清洗后明细!G:G,清洗后明细!A:A,"2026-06",清洗后明细!E:E,"零犀伽玛",清洗后明细!D:D,"人机"),"")
